Workbook

Sheet About
A1: ELCCAfR Effective Load Carrying Capability Adjustment for Reliability | B1: Arizona | C1: 46265 | F1: Alabama | G1: AL
A2: Active state: B1 (full name). B2 derives the code used by every tab. | B2: =VLOOKUP($B$1,$F$1:$G$48,2,FALSE) -> AZ | F2: Arkansas | G2: AR
A3: Sources: | B3: Firm-tech availability targets (nuclear 0.975; thermal derate relocated to MCF) | F3: Arizona | G3: AZ
B4: NERC / ISO-NE | F4: California | G4: CA
B5: GADS EFORd class averages 2020-2024, all units reporting (ISO-NE compilation, updated 2026-03-12) | F5: Colorado | G5: CO
B6: 2026 | F6: Connecticut | G6: CT
B7: https://www.iso-ne.com/static-assets/documents/genrtion_resrcs/gads/class_ave_2010.pdf | F7: Delaware | G7: DE
B8: Basis for nuclear target 0.975 (1 - EFORd, PWR classes) and the NGCC 0.95 that now lives in MCF.csv (not this file). NOT re-verified against the current NERC brochure or PJM Manual 21 / MISO filings — do that before external use. EFORd excludes planned outages by design; do not use these values for energy (annual CF) purposes. | F8: Florida | G8: FL
F9: Georgia | G9: GA
B10: Hydro peak-credit values (5 researched states) and targets (10 high-MCF states) | F10: Iowa | G10: IA
B11: EIA | F11: Idaho | G11: ID
B12: Open Data API v2: electric-power-operational-data (fueltypeid HYC, sectorid 98) / operating-generator-capacity (WAT, OP, net-summer-capacity-mw) | F12: Illinois | G12: IL
B13: 2026 | F13: Indiana | G13: IN
B14: https://www.eia.gov/opendata/ | F14: Kansas | G14: KS
B15: August 2020-24 generation over net-summer capacity x 744 h. NET SUMMER basis, not nameplate (model capacity is net summer; ND model 510.0 MW = EIA net summer exactly). Values embedded on Keys with rejected raw values recorded. OR and VT are calibration floors, NOT their raw EIA CFs — a monthly energy CF understates reservoir peak capability. The 10 target-state values arrived as constants from the colleague 2026-08-31 and are PENDING independent EIA re-derivation (plan D1); do not treat them as verified. Do not use any of these as energy CFs. | F15: Kentucky | G15: KY
F16: Louisiana | G16: LA
B17: VRE passthrough grids, and all layouts/labels | F17: Massachusetts | G17: MA
B18: Energy Innovation | F18: Maryland | G18: MD
B19: state-eps-data-repository, deployed per-state ELCCAfR/SYSHECF/HYECFCA/MCF/BHRaSYC CSVs | F19: Maine | G19: ME
B20: 2026 | F20: Michigan | G20: MI
B21: https://github.com/EnergyInnovation | F21: Minnesota | G21: MN
B22: Read 2026-08-31 from state-eps-data-repository @ 3599b4df1a + uncommitted working-tree edits (the recalibration itself). VRE tabs are Robbie's P30 pinned-peak-day builder output, passed through verbatim (Src_VRE tab) — this workbook does not re-derive them. SYSHECF/HYECFCA/MCF/BHRaSYC rows embedded verbatim on the Src_ tabs. These are model inputs, not primary data; their own provenance lives in their generating workbooks/builders. | F22: Missouri | G22: MO
F23: Mississippi | G23: MS
F24: Montana | G24: MT
A25: Notes: | F25: North Carolina | G25: NC
A26: Filename | B26: Folder/file named per eps-us InputData convention. NOTE: the state tree currently carries a DIFFERENTLY NAMED workbook per state ("ELCCAfR ELCC Adjustment for Reliability.xlsx", Robbie's builder, Parameters!B4 = 0.90) which is SUPERSEDED by this methodology and must not be used to regenerate CSVs. | F26: North Dakota | G26: ND
A27: Deploy state | B27: CSVs in state-eps-data-repository were edited 2026-08-31 by qc/firm-credit/_apply_firm_credit_elccafr.py; this workbook documents/derives the same values. Run tree NOT yet updated. | F27: Nebraska | G27: NE
F28: New Hampshire | G28: NH
F29: New Jersey | G29: NJ
F30: New Mexico | G30: NM
F31: Nevada | G31: NV
F32: New York | G32: NY
F33: Ohio | G33: OH
F34: Oklahoma | G34: OK
F35: Oregon | G35: OR
F36: Pennsylvania | G36: PA
F37: Rhode Island | G37: RI
F38: South Carolina | G38: SC
F39: South Dakota | G39: SD
... F48: Wyoming | G48: WY

Sheet Keys
A1: category | B1: key | C1: value | D1: description
A2: const | B2: nuclear_target | C2: 0.975 | D2: Peak-hour availability credit for nuclear: 1 - EFORd, GADS PWR classes 2020-24. Robbie/colleague decision 2026-08-31.
A3: const | B3: thermal_elccafr | C3: 1 | D3: ELCCAfR for the 12 MCF-path thermal techs. The 0.9 availability derate moved into MCF.csv (Olivia edit 2026-08-31), so ELCCAfR = 1.0 here; net credit 0.9 (0.95 for NGCC, whose MCF is 0.95).
A4: const | B4: unchanged_elccafr | C4: 0.9 | D4: Value kept for deferred techs (biomass, biomass-CCS, geothermal, MSW, SMR, crude oil), for nuclear in the 20 states with no nuclear fleet, and for demand-altering techs. As committed 2026-08-19 (state-eps-data 3462ef1608).
A5: const | B5: round_dp | C5: 4 | D5: Decimal places in the deployed CSVs.
A6: const | B6: tol_credit | C6: 0.0002 | D6: Tolerance on recomputed credits vs their target (covers 4-dp rounding).
A7: const | B7: tol_mcf_vary | C7: 1e-06 | D7: Threshold above which a hydro MCF row counts as varying across years.
A9: hydro_fixed | D9: Group 5b: the five states whose hydro MCF is 1.0, so ELCCAfR carries the whole peak derate. Rejected raw EIA values recorded in the description.
A10: hydro_fixed | B10: FL | C10: 0.5004 | D10: EIA 2020-24 avg August CF, net-summer basis
A11: hydro_fixed | B11: ND | C11: 0.4727 | D11: EIA 2020-24 avg August CF, net-summer basis
A12: hydro_fixed | B12: OR | C12: 0.75 | D12: calibration floor for reservoir hydro; raw EIA Aug CF 0.4041 REJECTED (fails 2025 no-fake-shortfall gate by ~2,600 MW); absorbs unmodeled BPA-region import support — Robbie sign-off pending
A13: hydro_fixed | B13: VT | C13: 0.36 | D13: EIA Aug CF 0.3042 raised to calibration floor 0.3481, rounded up; thin margin, dry-year fragility documented
A14: hydro_fixed | B14: WY | C14: 0.4854 | D14: EIA 2020-24 avg August CF, net-summer basis
A16: hydro_target | D16: Group 5c: high-MCF states whose hydro MCF is an energy CF, not peak availability. The CREDIT target below is divided by the state MCF on Calcs to get the ELCCAfR. Values from the colleague 2026-08-31; EIA re-derivation pending (plan decision D1).
A17: hydro_target | B17: AZ | C17: 0.55 | D17: target peak-hour CREDIT (not the ELCCAfR itself)
A18: hydro_target | B18: CO | C18: 0.7 | D18: target peak-hour CREDIT (not the ELCCAfR itself)
A19: hydro_target | B19: IA | C19: 0.75 | D19: target peak-hour CREDIT (not the ELCCAfR itself)
A20: hydro_target | B20: MN | C20: 0.75 | D20: target peak-hour CREDIT (not the ELCCAfR itself)
A21: hydro_target | B21: NV | C21: 0.4 | D21: target peak-hour CREDIT (not the ELCCAfR itself)
A22: hydro_target | B22: NY | C22: 0.9 | D22: target peak-hour CREDIT (not the ELCCAfR itself)
A23: hydro_target | B23: OK | C23: 0.75 | D23: target peak-hour CREDIT (not the ELCCAfR itself)
A24: hydro_target | B24: SD | C24: 0.75 | D24: target peak-hour CREDIT (not the ELCCAfR itself)
A25: hydro_target | B25: TN | C25: 0.75 | D25: target peak-hour CREDIT (not the ELCCAfR itself)
A26: hydro_target | B26: WI | C26: 0.75 | D26: target peak-hour CREDIT (not the ELCCAfR itself)

Sheet Src_HYECFCA_nuclear
A1: Src_HYECFCA_nuclear
A2: The nuclear row of each state's HYECFCA.csv, verbatim. Column 2 (2025) is the only year the recalibration divides by; 2026+ are 1.0 by construction.
A3: Provenance: state-eps-data-repository @ 3599b4df1a + uncommitted working-tree edits (the recalibration itself), read 2026-08-31. Helper: none needed — 2025 is column B.
A4: state | B4: %)" | C4: 2025.0 | D4: 2026.0 | E4: 2027.0 | F4: 2028.0 | G4: 2029.0 | H4: 2030.0 | I4: 2031.0 | J4: 2032.0 | K4: 2033.0 | L4: 2034.0 | M4: 2035.0 | N4: 2036.0 | O4: 2037.0 | P4: 2038.0 | Q4: 2039.0 | R4: 2040.0 | S4: 2041.0 | T4: 2042.0 | U4: 2043.0 | V4: 2044.0 | W4: 2045.0 | X4: 2046.0 | Y4: 2047.0 | Z4: 2048.0 | AA4: 2049.0 | AB4: 2050.0
A5: AL | B5: 0.97915 | C5: 1 | D5: 1 | E5: 1 | F5: 1 | G5: 1 | H5: 1 | I5: 1 | J5: 1 | K5: 1 | L5: 1 | M5: 1 | N5: 1 | O5: 1 | P5: 1 | Q5: 1 | R5: 1 | S5: 1 | T5: 1 | U5: 1 | V5: 1 | W5: 1 | X5: 1 | Y5: 1 | Z5: 1 | AA5: 1
A6: AR | B6: 1.01825 | C6: 1 | D6: 1 | E6: 1 | F6: 1 | G6: 1 | H6: 1 | I6: 1 | J6: 1 | K6: 1 | L6: 1 | M6: 1 | N6: 1 | O6: 1 | P6: 1 | Q6: 1 | R6: 1 | S6: 1 | T6: 1 | U6: 1 | V6: 1 | W6: 1 | X6: 1 | Y6: 1 | Z6: 1 | AA6: 1
A7: AZ | B7: 0.98321 | C7: 1 | D7: 1 | E7: 1 | F7: 1 | G7: 1 | H7: 1 | I7: 1 | J7: 1 | K7: 1 | L7: 1 | M7: 1 | N7: 1 | O7: 1 | P7: 1 | Q7: 1 | R7: 1 | S7: 1 | T7: 1 | U7: 1 | V7: 1 | W7: 1 | X7: 1 | Y7: 1 | Z7: 1 | AA7: 1
A8: CA | B8: 0.977191 | C8: 1 | D8: 1 | E8: 1 | F8: 1 | G8: 1 | H8: 1 | I8: 1 | J8: 1 | K8: 1 | L8: 1 | M8: 1 | N8: 1 | O8: 1 | P8: 1 | Q8: 1 | R8: 1 | S8: 1 | T8: 1 | U8: 1 | V8: 1 | W8: 1 | X8: 1 | Y8: 1 | Z8: 1 | AA8: 1
A9: CO | B9: 1 | C9: 1 | D9: 1 | E9: 1 | F9: 1 | G9: 1 | H9: 1 | I9: 1 | J9: 1 | K9: 1 | L9: 1 | M9: 1 | N9: 1 | O9: 1 | P9: 1 | Q9: 1 | R9: 1 | S9: 1 | T9: 1 | U9: 1 | V9: 1 | W9: 1 | X9: 1 | Y9: 1 | Z9: 1 | AA9: 1
A10: CT | B10: 0.994241 | C10: 1 | D10: 1 | E10: 1 | F10: 1 | G10: 1 | H10: 1 | I10: 1 | J10: 1 | K10: 1 | L10: 1 | M10: 1 | N10: 1 | O10: 1 | P10: 1 | Q10: 1 | R10: 1 | S10: 1 | T10: 1 | U10: 1 | V10: 1 | W10: 1 | X10: 1 | Y10: 1 | Z10: 1 | AA10: 1
A11: DE | B11: 1 | C11: 1 | D11: 1 | E11: 1 | F11: 1 | G11: 1 | H11: 1 | I11: 1 | J11: 1 | K11: 1 | L11: 1 | M11: 1 | N11: 1 | O11: 1 | P11: 1 | Q11: 1 | R11: 1 | S11: 1 | T11: 1 | U11: 1 | V11: 1 | W11: 1 | X11: 1 | Y11: 1 | Z11: 1 | AA11: 1
A12: FL | B12: 1.02804 | C12: 1 | D12: 1 | E12: 1 | F12: 1 | G12: 1 | H12: 1 | I12: 1 | J12: 1 | K12: 1 | L12: 1 | M12: 1 | N12: 1 | O12: 1 | P12: 1 | Q12: 1 | R12: 1 | S12: 1 | T12: 1 | U12: 1 | V12: 1 | W12: 1 | X12: 1 | Y12: 1 | Z12: 1 | AA12: 1
A13: GA | B13: 1.03278 | C13: 1 | D13: 1 | E13: 1 | F13: 1 | G13: 1 | H13: 1 | I13: 1 | J13: 1 | K13: 1 | L13: 1 | M13: 1 | N13: 1 | O13: 1 | P13: 1 | Q13: 1 | R13: 1 | S13: 1 | T13: 1 | U13: 1 | V13: 1 | W13: 1 | X13: 1 | Y13: 1 | Z13: 1 | AA13: 1
A14: IA | B14: 1 | C14: 1 | D14: 1 | E14: 1 | F14: 1 | G14: 1 | H14: 1 | I14: 1 | J14: 1 | K14: 1 | L14: 1 | M14: 1 | N14: 1 | O14: 1 | P14: 1 | Q14: 1 | R14: 1 | S14: 1 | T14: 1 | U14: 1 | V14: 1 | W14: 1 | X14: 1 | Y14: 1 | Z14: 1 | AA14: 1
A15: ID | B15: 1 | C15: 1 | D15: 1 | E15: 1 | F15: 1 | G15: 1 | H15: 1 | I15: 1 | J15: 1 | K15: 1 | L15: 1 | M15: 1 | N15: 1 | O15: 1 | P15: 1 | Q15: 1 | R15: 1 | S15: 1 | T15: 1 | U15: 1 | V15: 1 | W15: 1 | X15: 1 | Y15: 1 | Z15: 1 | AA15: 1
A16: IL | B16: 0.991989 | C16: 1 | D16: 1 | E16: 1 | F16: 1 | G16: 1 | H16: 1 | I16: 1 | J16: 1 | K16: 1 | L16: 1 | M16: 1 | N16: 1 | O16: 1 | P16: 1 | Q16: 1 | R16: 1 | S16: 1 | T16: 1 | U16: 1 | V16: 1 | W16: 1 | X16: 1 | Y16: 1 | Z16: 1 | AA16: 1
... A52: WY | B52: 1 | C52: 1 | D52: 1 | E52: 1 | F52: 1 | G52: 1 | H52: 1 | I52: 1 | J52: 1 | K52: 1 | L52: 1 | M52: 1 | N52: 1 | O52: 1 | P52: 1 | Q52: 1 | R52: 1 | S52: 1 | T52: 1 | U52: 1 | V52: 1 | W52: 1 | X52: 1 | Y52: 1 | Z52: 1 | AA52: 1

Sheet Src_MCF_hydro
A1: Src_MCF_hydro
A2: The hydro row of each state's MCF.csv, verbatim (post Olivia's 2026-08-31 MCF edit, which left hydro untouched). Helpers at right: the 2025 value the target states divide by, and a constancy check across the 26 years.
A3: Provenance: state-eps-data-repository @ 3599b4df1a + uncommitted working-tree edits (the recalibration itself), read 2026-08-31. Helpers in columns AB-AC.
A4: state | B4: 2025.0 | C4: 2026.0 | D4: 2027.0 | E4: 2028.0 | F4: 2029.0 | G4: 2030.0 | H4: 2031.0 | I4: 2032.0 | J4: 2033.0 | K4: 2034.0 | L4: 2035.0 | M4: 2036.0 | N4: 2037.0 | O4: 2038.0 | P4: 2039.0 | Q4: 2040.0 | R4: 2041.0 | S4: 2042.0 | T4: 2043.0 | U4: 2044.0 | V4: 2045.0 | W4: 2046.0 | X4: 2047.0 | Y4: 2048.0 | Z4: 2049.0 | AA4: 2050.0 | AC4: MCF used in the division (= 2025 column) | AD4: CHECK: does MCF vary across years? 1 = problem
A5: AL | B5: 0.788569 | C5: 0.788569 | D5: 0.788569 | E5: 0.788569 | F5: 0.788569 | G5: 0.788569 | H5: 0.788569 | I5: 0.788569 | J5: 0.788569 | K5: 0.788569 | L5: 0.788569 | M5: 0.788569 | N5: 0.788569 | O5: 0.788569 | P5: 0.788569 | Q5: 0.788569 | R5: 0.788569 | S5: 0.788569 | T5: 0.788569 | U5: 0.788569 | V5: 0.788569 | W5: 0.788569 | X5: 0.788569 | Y5: 0.788569 | Z5: 0.788569 | AA5: 0.788569 | AC5: =$B5 -> 0.788569 | AD5: =IF(MAX(B5:AA5)-MIN(B5:AA5)>Keys!$C$7,1,0) -> 0
A6: AR | B6: 0.709971 | C6: 0.709971 | D6: 0.709971 | E6: 0.709971 | F6: 0.709971 | G6: 0.709971 | H6: 0.709971 | I6: 0.709971 | J6: 0.709971 | K6: 0.709971 | L6: 0.709971 | M6: 0.709971 | N6: 0.709971 | O6: 0.709971 | P6: 0.709971 | Q6: 0.709971 | R6: 0.709971 | S6: 0.709971 | T6: 0.709971 | U6: 0.709971 | V6: 0.709971 | W6: 0.709971 | X6: 0.709971 | Y6: 0.709971 | Z6: 0.709971 | AA6: 0.709971 | AC6: =$B6 -> 0.709971 | AD6: =IF(MAX(B6:AA6)-MIN(B6:AA6)>Keys!$C$7,1,0) -> 0
A7: AZ | B7: 0.86868 | C7: 0.86868 | D7: 0.86868 | E7: 0.86868 | F7: 0.86868 | G7: 0.86868 | H7: 0.86868 | I7: 0.86868 | J7: 0.86868 | K7: 0.86868 | L7: 0.86868 | M7: 0.86868 | N7: 0.86868 | O7: 0.86868 | P7: 0.86868 | Q7: 0.86868 | R7: 0.86868 | S7: 0.86868 | T7: 0.86868 | U7: 0.86868 | V7: 0.86868 | W7: 0.86868 | X7: 0.86868 | Y7: 0.86868 | Z7: 0.86868 | AA7: 0.86868 | AC7: =$B7 -> 0.86868 | AD7: =IF(MAX(B7:AA7)-MIN(B7:AA7)>Keys!$C$7,1,0) -> 0
A8: CA | B8: 0.779854 | C8: 0.779854 | D8: 0.779854 | E8: 0.779854 | F8: 0.779854 | G8: 0.779854 | H8: 0.779854 | I8: 0.779854 | J8: 0.779854 | K8: 0.779854 | L8: 0.779854 | M8: 0.779854 | N8: 0.779854 | O8: 0.779854 | P8: 0.779854 | Q8: 0.779854 | R8: 0.779854 | S8: 0.779854 | T8: 0.779854 | U8: 0.779854 | V8: 0.779854 | W8: 0.779854 | X8: 0.779854 | Y8: 0.779854 | Z8: 0.779854 | AA8: 0.779854 | AC8: =$B8 -> 0.779854 | AD8: =IF(MAX(B8:AA8)-MIN(B8:AA8)>Keys!$C$7,1,0) -> 0
A9: CO | B9: 0.915666 | C9: 0.915666 | D9: 0.915666 | E9: 0.915666 | F9: 0.915666 | G9: 0.915666 | H9: 0.915666 | I9: 0.915666 | J9: 0.915666 | K9: 0.915666 | L9: 0.915666 | M9: 0.915666 | N9: 0.915666 | O9: 0.915666 | P9: 0.915666 | Q9: 0.915666 | R9: 0.915666 | S9: 0.915666 | T9: 0.915666 | U9: 0.915666 | V9: 0.915666 | W9: 0.915666 | X9: 0.915666 | Y9: 0.915666 | Z9: 0.915666 | AA9: 0.915666 | AC9: =$B9 -> 0.915666 | AD9: =IF(MAX(B9:AA9)-MIN(B9:AA9)>Keys!$C$7,1,0) -> 0
A10: CT | B10: 0.75283 | C10: 0.75283 | D10: 0.75283 | E10: 0.75283 | F10: 0.75283 | G10: 0.75283 | H10: 0.75283 | I10: 0.75283 | J10: 0.75283 | K10: 0.75283 | L10: 0.75283 | M10: 0.75283 | N10: 0.75283 | O10: 0.75283 | P10: 0.75283 | Q10: 0.75283 | R10: 0.75283 | S10: 0.75283 | T10: 0.75283 | U10: 0.75283 | V10: 0.75283 | W10: 0.75283 | X10: 0.75283 | Y10: 0.75283 | Z10: 0.75283 | AA10: 0.75283 | AC10: =$B10 -> 0.75283 | AD10: =IF(MAX(B10:AA10)-MIN(B10:AA10)>Keys!$C$7,1,0) -> 0
A11: DE | B11: 0.736084 | C11: 0.736084 | D11: 0.736084 | E11: 0.736084 | F11: 0.736084 | G11: 0.736084 | H11: 0.736084 | I11: 0.736084 | J11: 0.736084 | K11: 0.736084 | L11: 0.736084 | M11: 0.736084 | N11: 0.736084 | O11: 0.736084 | P11: 0.736084 | Q11: 0.736084 | R11: 0.736084 | S11: 0.736084 | T11: 0.736084 | U11: 0.736084 | V11: 0.736084 | W11: 0.736084 | X11: 0.736084 | Y11: 0.736084 | Z11: 0.736084 | AA11: 0.736084 | AC11: =$B11 -> 0.736084 | AD11: =IF(MAX(B11:AA11)-MIN(B11:AA11)>Keys!$C$7,1,0) -> 0
A12: FL | B12: 1 | C12: 1 | D12: 1 | E12: 1 | F12: 1 | G12: 1 | H12: 1 | I12: 1 | J12: 1 | K12: 1 | L12: 1 | M12: 1 | N12: 1 | O12: 1 | P12: 1 | Q12: 1 | R12: 1 | S12: 1 | T12: 1 | U12: 1 | V12: 1 | W12: 1 | X12: 1 | Y12: 1 | Z12: 1 | AA12: 1 | AC12: =$B12 -> 1 | AD12: =IF(MAX(B12:AA12)-MIN(B12:AA12)>Keys!$C$7,1,0) -> 0
A13: GA | B13: 0.812898 | C13: 0.812898 | D13: 0.812898 | E13: 0.812898 | F13: 0.812898 | G13: 0.812898 | H13: 0.812898 | I13: 0.812898 | J13: 0.812898 | K13: 0.812898 | L13: 0.812898 | M13: 0.812898 | N13: 0.812898 | O13: 0.812898 | P13: 0.812898 | Q13: 0.812898 | R13: 0.812898 | S13: 0.812898 | T13: 0.812898 | U13: 0.812898 | V13: 0.812898 | W13: 0.812898 | X13: 0.812898 | Y13: 0.812898 | Z13: 0.812898 | AA13: 0.812898 | AC13: =$B13 -> 0.812898 | AD13: =IF(MAX(B13:AA13)-MIN(B13:AA13)>Keys!$C$7,1,0) -> 0
A14: IA | B14: 0.865797 | C14: 0.865797 | D14: 0.865797 | E14: 0.865797 | F14: 0.865797 | G14: 0.865797 | H14: 0.865797 | I14: 0.865797 | J14: 0.865797 | K14: 0.865797 | L14: 0.865797 | M14: 0.865797 | N14: 0.865797 | O14: 0.865797 | P14: 0.865797 | Q14: 0.865797 | R14: 0.865797 | S14: 0.865797 | T14: 0.865797 | U14: 0.865797 | V14: 0.865797 | W14: 0.865797 | X14: 0.865797 | Y14: 0.865797 | Z14: 0.865797 | AA14: 0.865797 | AC14: =$B14 -> 0.865797 | AD14: =IF(MAX(B14:AA14)-MIN(B14:AA14)>Keys!$C$7,1,0) -> 0
A15: ID | B15: 0.83619 | C15: 0.83619 | D15: 0.83619 | E15: 0.83619 | F15: 0.83619 | G15: 0.83619 | H15: 0.83619 | I15: 0.83619 | J15: 0.83619 | K15: 0.83619 | L15: 0.83619 | M15: 0.83619 | N15: 0.83619 | O15: 0.83619 | P15: 0.83619 | Q15: 0.83619 | R15: 0.83619 | S15: 0.83619 | T15: 0.83619 | U15: 0.83619 | V15: 0.83619 | W15: 0.83619 | X15: 0.83619 | Y15: 0.83619 | Z15: 0.83619 | AA15: 0.83619 | AC15: =$B15 -> 0.83619 | AD15: =IF(MAX(B15:AA15)-MIN(B15:AA15)>Keys!$C$7,1,0) -> 0
A16: IL | B16: 0.430594 | C16: 0.430594 | D16: 0.430594 | E16: 0.430594 | F16: 0.430594 | G16: 0.430594 | H16: 0.430594 | I16: 0.430594 | J16: 0.430594 | K16: 0.430594 | L16: 0.430594 | M16: 0.430594 | N16: 0.430594 | O16: 0.430594 | P16: 0.430594 | Q16: 0.430594 | R16: 0.430594 | S16: 0.430594 | T16: 0.430594 | U16: 0.430594 | V16: 0.430594 | W16: 0.430594 | X16: 0.430594 | Y16: 0.430594 | Z16: 0.430594 | AA16: 0.430594 | AC16: =$B16 -> 0.430594 | AD16: =IF(MAX(B16:AA16)-MIN(B16:AA16)>Keys!$C$7,1,0) -> 0
... A52: WY | B52: 1 | C52: 1 | D52: 1 | E52: 1 | F52: 1 | G52: 1 | H52: 1 | I52: 1 | J52: 1 | K52: 1 | L52: 1 | M52: 1 | N52: 1 | O52: 1 | P52: 1 | Q52: 1 | R52: 1 | S52: 1 | T52: 1 | U52: 1 | V52: 1 | W52: 1 | X52: 1 | Y52: 1 | Z52: 1 | AA52: 1 | AC52: =$B52 -> 1 | AD52: =IF(MAX(B52:AA52)-MIN(B52:AA52)>Keys!$C$7,1,0) -> 0

Sheet Src_BHRaSYC_nuclear
A1: Src_BHRaSYC_nuclear
A2: The nuclear row of each state's BHRaSYC-StartYearCapacities.csv, verbatim across all vintage columns. The SUM column gates which states get the nuclear ratio treatment.
A3: Provenance: state-eps-data-repository @ 3599b4df1a + uncommitted working-tree edits (the recalibration itself), read 2026-08-31. Vintage headers as upstream.
A4: state | B4: Vintage1891 | C4: Vintage1892 | D4: Vintage1893 | E4: Vintage1894 | F4: Vintage1895 | G4: Vintage1896 | H4: Vintage1897 | I4: Vintage1898 | J4: Vintage1899 | K4: Vintage1900 | L4: Vintage1901 | M4: Vintage1902 | N4: Vintage1903 | O4: Vintage1904 | P4: Vintage1905 | Q4: Vintage1906 | R4: Vintage1907 | S4: Vintage1908 | T4: Vintage1909 | U4: Vintage1910 | V4: Vintage1911 | W4: Vintage1912 | X4: Vintage1913 | Y4: Vintage1914 | Z4: Vintage1915 | AA4: Vintage1916 | AB4: Vintage1917 | AC4: Vintage1918 | AD4: Vintage1919 | AE4: Vintage1920 | AF4: Vintage1921 | AG4: Vintage1922 | AH4: Vintage1923 | AI4: Vintage1924 | AJ4: Vintage1925 | AK4: Vintage1926 | AL4: Vintage1927 | AM4: Vintage1928 | AN4: Vintage1929 | AO4: Vintage1930 | AP4: Vintage1931 | AQ4: Vintage1932 | AR4: Vintage1933 | AS4: Vintage1934 | AT4: Vintage1935 | AU4: Vintage1936 | AV4: Vintage1937 | AW4: Vintage1938 | AX4: Vintage1939 | AY4: Vintage1940 | AZ4: Vintage1941 | BA4: Vintage1942 | BB4: Vintage1943 | BC4: Vintage1944 | BD4: Vintage1945 | BE4: Vintage1946 | BF4: Vintage1947 | BG4: Vintage1948 | BH4: Vintage1949 | BI4: Vintage1950 | BJ4: Vintage1951 | BK4: Vintage1952 | BL4: Vintage1953 | BM4: Vintage1954 | BN4: Vintage1955 | BO4: Vintage1956 | BP4: Vintage1957 | BQ4: Vintage1958 | BR4: Vintage1959 | BS4: Vintage1960 | BT4: Vintage1961 | BU4: Vintage1962 | BV4: Vintage1963 | BW4: Vintage1964 | BX4: Vintage1965 | BY4: Vintage1966 | BZ4: Vintage1967 | CA4: Vintage1968 | CB4: Vintage1969 | CC4: Vintage1970 | CD4: Vintage1971 | CE4: Vintage1972 | CF4: Vintage1973 | CG4: Vintage1974 | CH4: Vintage1975 | CI4: Vintage1976 | CJ4: Vintage1977 | CK4: Vintage1978 | CL4: Vintage1979 | CM4: Vintage1980 | CN4: Vintage1981 | CO4: Vintage1982 | CP4: Vintage1983 | CQ4: Vintage1984 | CR4: Vintage1985 | CS4: Vintage1986 | CT4: Vintage1987 | CU4: Vintage1988 | CV4: Vintage1989 | CW4: Vintage1990 | CX4: Vintage1991 | CY4: Vintage1992 | CZ4: Vintage1993 | DA4: Vintage1994 | DB4: Vintage1995 | DC4: Vintage1996 | DD4: Vintage1997 | DE4: Vintage1998 | DF4: Vintage1999 | DG4: Vintage2000 | DH4: Vintage2001 | DI4: Vintage2002 | DJ4: Vintage2003 | DK4: Vintage2004 | DL4: Vintage2005 | DM4: Vintage2006 | DN4: Vintage2007 | DO4: Vintage2008 | DP4: Vintage2009 | DQ4: Vintage2010 | DR4: Vintage2011 | DS4: Vintage2012 | DT4: Vintage2013 | DU4: Vintage2014 | DV4: Vintage2015 | DW4: Vintage2016 | DX4: Vintage2017 | DY4: Vintage2018 | DZ4: Vintage2019 | EA4: Vintage2020 | EB4: Vintage2021 | EC4: Vintage2022 | ED4: Vintage2023 | EE4: Vintage2024 | EF4: Vintage2025 | EG4: Vintage2026 | EH4: Vintage2027 | EI4: Vintage2028 | EJ4: Vintage2029 | EK4: Vintage2030 | EL4: Vintage2031 | EM4: Vintage2032 | EN4: Vintage2033 | EO4: Vintage2034 | EP4: Vintage2035 | EQ4: Vintage2036 | ER4: Vintage2037 | ES4: Vintage2038 | ET4: Vintage2039 | EU4: Vintage2040 | EV4: Vintage2041 | EW4: Vintage2042 | EX4: Vintage2043 | EY4: Vintage2044 | EZ4: Vintage2045 | FA4: Vintage2046 | FB4: Vintage2047 | FC4: Vintage2048 | FD4: Vintage2049 | FE4: Vintage2050 | FF4: Vintage2051 | FG4: Vintage2052 | FH4: Vintage2053 | FI4: Vintage2054 | FJ4: Vintage2055 | FK4: Vintage2056 | FL4: Vintage2057 | FM4: Vintage2058 | FN4: Vintage2059 | FO4: Vintage2060 | FP4: Vintage2061 | FQ4: Vintage2062 | FR4: Vintage2063 | FS4: Vintage2064 | FT4: Vintage2065 | FU4: Vintage2066 | FV4: Vintage2067 | FW4: Vintage2068 | FX4: Vintage2069 | FY4: Vintage2070 | FZ4: Vintage2071 | GA4: Vintage2072 | GB4: Vintage2073 | GC4: Vintage2074 | GD4: Vintage2075 | GE4: Vintage2076 | GF4: Vintage2077 | GG4: Vintage2078 | GH4: Vintage2079 | GI4: Vintage2080 | GJ4: Vintage2081 | GK4: Vintage2082 | GL4: Vintage2083 | GM4: Vintage2084 | GN4: Vintage2085 | GO4: Vintage2086 | GP4: Vintage2087 | GQ4: Vintage2088 | GR4: Vintage2089 | GS4: Vintage2090 | GT4: Vintage2091 | GU4: Vintage2092 | GV4: Vintage2093 | GW4: Vintage2094 | GX4: Vintage2095 | GY4: Vintage2096 | GZ4: Vintage2097 | HA4: Vintage2098 | HB4: Vintage2099 | HC4: Vintage2100 | HE4: Nuclear start-year capacity, MW (sum across vintages) | HF4: HAS NUCLEAR FLEET? 1 = gets the ratio ELCCAfR
A5: AL | B5: 0 | C5: 0 | D5: 0 | E5: 0 | F5: 0 | G5: 0 | H5: 0 | I5: 0 | J5: 0 | K5: 0 | L5: 0 | M5: 0 | N5: 0 | O5: 0 | P5: 0 | Q5: 0 | R5: 0 | S5: 0 | T5: 0 | U5: 0 | V5: 0 | W5: 0 | X5: 0 | Y5: 0 | Z5: 0 | AA5: 0 | AB5: 0 | AC5: 0 | AD5: 0 | AE5: 0 | AF5: 0 | AG5: 0 | AH5: 0 | AI5: 0 | AJ5: 0 | AK5: 0 | AL5: 0 | AM5: 0 | AN5: 0 | AO5: 0 | AP5: 0 | AQ5: 0 | AR5: 0 | AS5: 0 | AT5: 0 | AU5: 0 | AV5: 0 | AW5: 0 | AX5: 0 | AY5: 0 | AZ5: 0 | BA5: 0 | BB5: 0 | BC5: 0 | BD5: 0 | BE5: 0 | BF5: 0 | BG5: 0 | BH5: 0 | BI5: 0 | BJ5: 0 | BK5: 0 | BL5: 0 | BM5: 0 | BN5: 0 | BO5: 0 | BP5: 0 | BQ5: 0 | BR5: 0 | BS5: 0 | BT5: 0 | BU5: 0 | BV5: 0 | BW5: 0 | BX5: 0 | BY5: 0 | BZ5: 0 | CA5: 0 | CB5: 0 | CC5: 0 | CD5: 0 | CE5: 0 | CF5: 0 | CG5: 1227.4 | CH5: 1207.7 | CI5: 0 | CJ5: 2121.6 | CK5: 0 | CL5: 0 | CM5: 0 | CN5: 896 | CO5: 0 | CP5: 0 | CQ5: 0 | CR5: 0 | CS5: 0 | CT5: 0 | CU5: 0 | CV5: 0 | CW5: 0 | CX5: 0 | CY5: 0 | CZ5: 0 | DA5: 0 | DB5: 0 | DC5: 0 | DD5: 0 | DE5: 0 | DF5: 0 | DG5: 0 | DH5: 0 | DI5: 0 | DJ5: 0 | DK5: 0 | DL5: 0 | DM5: 0 | DN5: 0 | DO5: 0 | DP5: 0 | DQ5: 0 | DR5: 0 | DS5: 0 | DT5: 0 | DU5: 0 | DV5: 0 | DW5: 0 | DX5: 0 | DY5: 0 | DZ5: 0 | EA5: 0 | EB5: 0 | EC5: 0 | ED5: 0 | EE5: 0 | EF5: 0 | EG5: 0 | EH5: 0 | EI5: 0 | EJ5: 0 | EK5: 0 | EL5: 0 | EM5: 0 | EN5: 0 | EO5: 0 | EP5: 0 | EQ5: 0 | ER5: 0 | ES5: 0 | ET5: 0 | EU5: 0 | EV5: 0 | EW5: 0 | EX5: 0 | EY5: 0 | EZ5: 0 | FA5: 0 | FB5: 0 | FC5: 0 | FD5: 0 | FE5: 0 | FF5: 0 | FG5: 0 | FH5: 0 | FI5: 0 | FJ5: 0 | FK5: 0 | FL5: 0 | FM5: 0 | FN5: 0 | FO5: 0 | FP5: 0 | FQ5: 0 | FR5: 0 | FS5: 0 | FT5: 0 | FU5: 0 | FV5: 0 | FW5: 0 | FX5: 0 | FY5: 0 | FZ5: 0 | GA5: 0 | GB5: 0 | GC5: 0 | GD5: 0 | GE5: 0 | GF5: 0 | GG5: 0 | GH5: 0 | GI5: 0 | GJ5: 0 | GK5: 0 | GL5: 0 | GM5: 0 | GN5: 0 | GO5: 0 | GP5: 0 | GQ5: 0 | GR5: 0 | GS5: 0 | GT5: 0 | GU5: 0 | GV5: 0 | GW5: 0 | GX5: 0 | GY5: 0 | GZ5: 0 | HA5: 0 | HB5: 0 | HC5: 0 | HE5: =SUM(B5:HC5) -> 5452.7 | HF5: =IF(HE5>0,1,0) -> 1
A6: AR | B6: 0 | C6: 0 | D6: 0 | E6: 0 | F6: 0 | G6: 0 | H6: 0 | I6: 0 | J6: 0 | K6: 0 | L6: 0 | M6: 0 | N6: 0 | O6: 0 | P6: 0 | Q6: 0 | R6: 0 | S6: 0 | T6: 0 | U6: 0 | V6: 0 | W6: 0 | X6: 0 | Y6: 0 | Z6: 0 | AA6: 0 | AB6: 0 | AC6: 0 | AD6: 0 | AE6: 0 | AF6: 0 | AG6: 0 | AH6: 0 | AI6: 0 | AJ6: 0 | AK6: 0 | AL6: 0 | AM6: 0 | AN6: 0 | AO6: 0 | AP6: 0 | AQ6: 0 | AR6: 0 | AS6: 0 | AT6: 0 | AU6: 0 | AV6: 0 | AW6: 0 | AX6: 0 | AY6: 0 | AZ6: 0 | BA6: 0 | BB6: 0 | BC6: 0 | BD6: 0 | BE6: 0 | BF6: 0 | BG6: 0 | BH6: 0 | BI6: 0 | BJ6: 0 | BK6: 0 | BL6: 0 | BM6: 0 | BN6: 0 | BO6: 0 | BP6: 0 | BQ6: 0 | BR6: 0 | BS6: 0 | BT6: 0 | BU6: 0 | BV6: 0 | BW6: 0 | BX6: 0 | BY6: 0 | BZ6: 0 | CA6: 0 | CB6: 0 | CC6: 0 | CD6: 0 | CE6: 0 | CF6: 0 | CG6: 833.8 | CH6: 0 | CI6: 0 | CJ6: 0 | CK6: 0 | CL6: 0 | CM6: 987.2 | CN6: 0 | CO6: 0 | CP6: 0 | CQ6: 0 | CR6: 0 | CS6: 0 | CT6: 0 | CU6: 0 | CV6: 0 | CW6: 0 | CX6: 0 | CY6: 0 | CZ6: 0 | DA6: 0 | DB6: 0 | DC6: 0 | DD6: 0 | DE6: 0 | DF6: 0 | DG6: 0 | DH6: 0 | DI6: 0 | DJ6: 0 | DK6: 0 | DL6: 0 | DM6: 0 | DN6: 0 | DO6: 0 | DP6: 0 | DQ6: 0 | DR6: 0 | DS6: 0 | DT6: 0 | DU6: 0 | DV6: 0 | DW6: 0 | DX6: 0 | DY6: 0 | DZ6: 0 | EA6: 0 | EB6: 0 | EC6: 0 | ED6: 0 | EE6: 0 | EF6: 0 | EG6: 0 | EH6: 0 | EI6: 0 | EJ6: 0 | EK6: 0 | EL6: 0 | EM6: 0 | EN6: 0 | EO6: 0 | EP6: 0 | EQ6: 0 | ER6: 0 | ES6: 0 | ET6: 0 | EU6: 0 | EV6: 0 | EW6: 0 | EX6: 0 | EY6: 0 | EZ6: 0 | FA6: 0 | FB6: 0 | FC6: 0 | FD6: 0 | FE6: 0 | FF6: 0 | FG6: 0 | FH6: 0 | FI6: 0 | FJ6: 0 | FK6: 0 | FL6: 0 | FM6: 0 | FN6: 0 | FO6: 0 | FP6: 0 | FQ6: 0 | FR6: 0 | FS6: 0 | FT6: 0 | FU6: 0 | FV6: 0 | FW6: 0 | FX6: 0 | FY6: 0 | FZ6: 0 | GA6: 0 | GB6: 0 | GC6: 0 | GD6: 0 | GE6: 0 | GF6: 0 | GG6: 0 | GH6: 0 | GI6: 0 | GJ6: 0 | GK6: 0 | GL6: 0 | GM6: 0 | GN6: 0 | GO6: 0 | GP6: 0 | GQ6: 0 | GR6: 0 | GS6: 0 | GT6: 0 | GU6: 0 | GV6: 0 | GW6: 0 | GX6: 0 | GY6: 0 | GZ6: 0 | HA6: 0 | HB6: 0 | HC6: 0 | HE6: =SUM(B6:HC6) -> 1821 | HF6: =IF(HE6>0,1,0) -> 1
A7: AZ | B7: 0 | C7: 0 | D7: 0 | E7: 0 | F7: 0 | G7: 0 | H7: 0 | I7: 0 | J7: 0 | K7: 0 | L7: 0 | M7: 0 | N7: 0 | O7: 0 | P7: 0 | Q7: 0 | R7: 0 | S7: 0 | T7: 0 | U7: 0 | V7: 0 | W7: 0 | X7: 0 | Y7: 0 | Z7: 0 | AA7: 0 | AB7: 0 | AC7: 0 | AD7: 0 | AE7: 0 | AF7: 0 | AG7: 0 | AH7: 0 | AI7: 0 | AJ7: 0 | AK7: 0 | AL7: 0 | AM7: 0 | AN7: 0 | AO7: 0 | AP7: 0 | AQ7: 0 | AR7: 0 | AS7: 0 | AT7: 0 | AU7: 0 | AV7: 0 | AW7: 0 | AX7: 0 | AY7: 0 | AZ7: 0 | BA7: 0 | BB7: 0 | BC7: 0 | BD7: 0 | BE7: 0 | BF7: 0 | BG7: 0 | BH7: 0 | BI7: 0 | BJ7: 0 | BK7: 0 | BL7: 0 | BM7: 0 | BN7: 0 | BO7: 0 | BP7: 0 | BQ7: 0 | BR7: 0 | BS7: 0 | BT7: 0 | BU7: 0 | BV7: 0 | BW7: 0 | BX7: 0 | BY7: 0 | BZ7: 0 | CA7: 0 | CB7: 0 | CC7: 0 | CD7: 0 | CE7: 0 | CF7: 0 | CG7: 0 | CH7: 0 | CI7: 0 | CJ7: 0 | CK7: 0 | CL7: 0 | CM7: 0 | CN7: 0 | CO7: 0 | CP7: 0 | CQ7: 0 | CR7: 0 | CS7: 2625 | CT7: 0 | CU7: 1312 | CV7: 0 | CW7: 0 | CX7: 0 | CY7: 0 | CZ7: 0 | DA7: 0 | DB7: 0 | DC7: 0 | DD7: 0 | DE7: 0 | DF7: 0 | DG7: 0 | DH7: 0 | DI7: 0 | DJ7: 0 | DK7: 0 | DL7: 0 | DM7: 0 | DN7: 0 | DO7: 0 | DP7: 0 | DQ7: 0 | DR7: 0 | DS7: 0 | DT7: 0 | DU7: 0 | DV7: 0 | DW7: 0 | DX7: 0 | DY7: 0 | DZ7: 0 | EA7: 0 | EB7: 0 | EC7: 0 | ED7: 0 | EE7: 0 | EF7: 0 | EG7: 0 | EH7: 0 | EI7: 0 | EJ7: 0 | EK7: 0 | EL7: 0 | EM7: 0 | EN7: 0 | EO7: 0 | EP7: 0 | EQ7: 0 | ER7: 0 | ES7: 0 | ET7: 0 | EU7: 0 | EV7: 0 | EW7: 0 | EX7: 0 | EY7: 0 | EZ7: 0 | FA7: 0 | FB7: 0 | FC7: 0 | FD7: 0 | FE7: 0 | FF7: 0 | FG7: 0 | FH7: 0 | FI7: 0 | FJ7: 0 | FK7: 0 | FL7: 0 | FM7: 0 | FN7: 0 | FO7: 0 | FP7: 0 | FQ7: 0 | FR7: 0 | FS7: 0 | FT7: 0 | FU7: 0 | FV7: 0 | FW7: 0 | FX7: 0 | FY7: 0 | FZ7: 0 | GA7: 0 | GB7: 0 | GC7: 0 | GD7: 0 | GE7: 0 | GF7: 0 | GG7: 0 | GH7: 0 | GI7: 0 | GJ7: 0 | GK7: 0 | GL7: 0 | GM7: 0 | GN7: 0 | GO7: 0 | GP7: 0 | GQ7: 0 | GR7: 0 | GS7: 0 | GT7: 0 | GU7: 0 | GV7: 0 | GW7: 0 | GX7: 0 | GY7: 0 | GZ7: 0 | HA7: 0 | HB7: 0 | HC7: 0 | HE7: =SUM(B7:HC7) -> 3937 | HF7: =IF(HE7>0,1,0) -> 1
A8: CA | B8: 0 | C8: 0 | D8: 0 | E8: 0 | F8: 0 | G8: 0 | H8: 0 | I8: 0 | J8: 0 | K8: 0 | L8: 0 | M8: 0 | N8: 0 | O8: 0 | P8: 0 | Q8: 0 | R8: 0 | S8: 0 | T8: 0 | U8: 0 | V8: 0 | W8: 0 | X8: 0 | Y8: 0 | Z8: 0 | AA8: 0 | AB8: 0 | AC8: 0 | AD8: 0 | AE8: 0 | AF8: 0 | AG8: 0 | AH8: 0 | AI8: 0 | AJ8: 0 | AK8: 0 | AL8: 0 | AM8: 0 | AN8: 0 | AO8: 0 | AP8: 0 | AQ8: 0 | AR8: 0 | AS8: 0 | AT8: 0 | AU8: 0 | AV8: 0 | AW8: 0 | AX8: 0 | AY8: 0 | AZ8: 0 | BA8: 0 | BB8: 0 | BC8: 0 | BD8: 0 | BE8: 0 | BF8: 0 | BG8: 0 | BH8: 0 | BI8: 0 | BJ8: 0 | BK8: 0 | BL8: 0 | BM8: 0 | BN8: 0 | BO8: 0 | BP8: 0 | BQ8: 0 | BR8: 0 | BS8: 0 | BT8: 0 | BU8: 0 | BV8: 0 | BW8: 0 | BX8: 0 | BY8: 0 | BZ8: 0 | CA8: 0 | CB8: 0 | CC8: 0 | CD8: 0 | CE8: 0 | CF8: 0 | CG8: 0 | CH8: 0 | CI8: 0 | CJ8: 0 | CK8: 0 | CL8: 0 | CM8: 0 | CN8: 0 | CO8: 0 | CP8: 0 | CQ8: 0 | CR8: 1122 | CS8: 1118 | CT8: 0 | CU8: 0 | CV8: 0 | CW8: 0 | CX8: 0 | CY8: 0 | CZ8: 0 | DA8: 0 | DB8: 0 | DC8: 0 | DD8: 0 | DE8: 0 | DF8: 0 | DG8: 0 | DH8: 0 | DI8: 0 | DJ8: 0 | DK8: 0 | DL8: 0 | DM8: 0 | DN8: 0 | DO8: 0 | DP8: 0 | DQ8: 0 | DR8: 0 | DS8: 0 | DT8: 0 | DU8: 0 | DV8: 0 | DW8: 0 | DX8: 0 | DY8: 0 | DZ8: 0 | EA8: 0 | EB8: 0 | EC8: 0 | ED8: 0 | EE8: 0 | EF8: 0 | EG8: 0 | EH8: 0 | EI8: 0 | EJ8: 0 | EK8: 0 | EL8: 0 | EM8: 0 | EN8: 0 | EO8: 0 | EP8: 0 | EQ8: 0 | ER8: 0 | ES8: 0 | ET8: 0 | EU8: 0 | EV8: 0 | EW8: 0 | EX8: 0 | EY8: 0 | EZ8: 0 | FA8: 0 | FB8: 0 | FC8: 0 | FD8: 0 | FE8: 0 | FF8: 0 | FG8: 0 | FH8: 0 | FI8: 0 | FJ8: 0 | FK8: 0 | FL8: 0 | FM8: 0 | FN8: 0 | FO8: 0 | FP8: 0 | FQ8: 0 | FR8: 0 | FS8: 0 | FT8: 0 | FU8: 0 | FV8: 0 | FW8: 0 | FX8: 0 | FY8: 0 | FZ8: 0 | GA8: 0 | GB8: 0 | GC8: 0 | GD8: 0 | GE8: 0 | GF8: 0 | GG8: 0 | GH8: 0 | GI8: 0 | GJ8: 0 | GK8: 0 | GL8: 0 | GM8: 0 | GN8: 0 | GO8: 0 | GP8: 0 | GQ8: 0 | GR8: 0 | GS8: 0 | GT8: 0 | GU8: 0 | GV8: 0 | GW8: 0 | GX8: 0 | GY8: 0 | GZ8: 0 | HA8: 0 | HB8: 0 | HC8: 0 | HE8: =SUM(B8:HC8) -> 2240 | HF8: =IF(HE8>0,1,0) -> 1
A9: CO | B9: 0 | C9: 0 | D9: 0 | E9: 0 | F9: 0 | G9: 0 | H9: 0 | I9: 0 | J9: 0 | K9: 0 | L9: 0 | M9: 0 | N9: 0 | O9: 0 | P9: 0 | Q9: 0 | R9: 0 | S9: 0 | T9: 0 | U9: 0 | V9: 0 | W9: 0 | X9: 0 | Y9: 0 | Z9: 0 | AA9: 0 | AB9: 0 | AC9: 0 | AD9: 0 | AE9: 0 | AF9: 0 | AG9: 0 | AH9: 0 | AI9: 0 | AJ9: 0 | AK9: 0 | AL9: 0 | AM9: 0 | AN9: 0 | AO9: 0 | AP9: 0 | AQ9: 0 | AR9: 0 | AS9: 0 | AT9: 0 | AU9: 0 | AV9: 0 | AW9: 0 | AX9: 0 | AY9: 0 | AZ9: 0 | BA9: 0 | BB9: 0 | BC9: 0 | BD9: 0 | BE9: 0 | BF9: 0 | BG9: 0 | BH9: 0 | BI9: 0 | BJ9: 0 | BK9: 0 | BL9: 0 | BM9: 0 | BN9: 0 | BO9: 0 | BP9: 0 | BQ9: 0 | BR9: 0 | BS9: 0 | BT9: 0 | BU9: 0 | BV9: 0 | BW9: 0 | BX9: 0 | BY9: 0 | BZ9: 0 | CA9: 0 | CB9: 0 | CC9: 0 | CD9: 0 | CE9: 0 | CF9: 0 | CG9: 0 | CH9: 0 | CI9: 0 | CJ9: 0 | CK9: 0 | CL9: 0 | CM9: 0 | CN9: 0 | CO9: 0 | CP9: 0 | CQ9: 0 | CR9: 0 | CS9: 0 | CT9: 0 | CU9: 0 | CV9: 0 | CW9: 0 | CX9: 0 | CY9: 0 | CZ9: 0 | DA9: 0 | DB9: 0 | DC9: 0 | DD9: 0 | DE9: 0 | DF9: 0 | DG9: 0 | DH9: 0 | DI9: 0 | DJ9: 0 | DK9: 0 | DL9: 0 | DM9: 0 | DN9: 0 | DO9: 0 | DP9: 0 | DQ9: 0 | DR9: 0 | DS9: 0 | DT9: 0 | DU9: 0 | DV9: 0 | DW9: 0 | DX9: 0 | DY9: 0 | DZ9: 0 | EA9: 0 | EB9: 0 | EC9: 0 | ED9: 0 | EE9: 0 | EF9: 0 | EG9: 0 | EH9: 0 | EI9: 0 | EJ9: 0 | EK9: 0 | EL9: 0 | EM9: 0 | EN9: 0 | EO9: 0 | EP9: 0 | EQ9: 0 | ER9: 0 | ES9: 0 | ET9: 0 | EU9: 0 | EV9: 0 | EW9: 0 | EX9: 0 | EY9: 0 | EZ9: 0 | FA9: 0 | FB9: 0 | FC9: 0 | FD9: 0 | FE9: 0 | FF9: 0 | FG9: 0 | FH9: 0 | FI9: 0 | FJ9: 0 | FK9: 0 | FL9: 0 | FM9: 0 | FN9: 0 | FO9: 0 | FP9: 0 | FQ9: 0 | FR9: 0 | FS9: 0 | FT9: 0 | FU9: 0 | FV9: 0 | FW9: 0 | FX9: 0 | FY9: 0 | FZ9: 0 | GA9: 0 | GB9: 0 | GC9: 0 | GD9: 0 | GE9: 0 | GF9: 0 | GG9: 0 | GH9: 0 | GI9: 0 | GJ9: 0 | GK9: 0 | GL9: 0 | GM9: 0 | GN9: 0 | GO9: 0 | GP9: 0 | GQ9: 0 | GR9: 0 | GS9: 0 | GT9: 0 | GU9: 0 | GV9: 0 | GW9: 0 | GX9: 0 | GY9: 0 | GZ9: 0 | HA9: 0 | HB9: 0 | HC9: 0 | HE9: =SUM(B9:HC9) -> 0 | HF9: =IF(HE9>0,1,0) -> 0
A10: CT | B10: 0 | C10: 0 | D10: 0 | E10: 0 | F10: 0 | G10: 0 | H10: 0 | I10: 0 | J10: 0 | K10: 0 | L10: 0 | M10: 0 | N10: 0 | O10: 0 | P10: 0 | Q10: 0 | R10: 0 | S10: 0 | T10: 0 | U10: 0 | V10: 0 | W10: 0 | X10: 0 | Y10: 0 | Z10: 0 | AA10: 0 | AB10: 0 | AC10: 0 | AD10: 0 | AE10: 0 | AF10: 0 | AG10: 0 | AH10: 0 | AI10: 0 | AJ10: 0 | AK10: 0 | AL10: 0 | AM10: 0 | AN10: 0 | AO10: 0 | AP10: 0 | AQ10: 0 | AR10: 0 | AS10: 0 | AT10: 0 | AU10: 0 | AV10: 0 | AW10: 0 | AX10: 0 | AY10: 0 | AZ10: 0 | BA10: 0 | BB10: 0 | BC10: 0 | BD10: 0 | BE10: 0 | BF10: 0 | BG10: 0 | BH10: 0 | BI10: 0 | BJ10: 0 | BK10: 0 | BL10: 0 | BM10: 0 | BN10: 0 | BO10: 0 | BP10: 0 | BQ10: 0 | BR10: 0 | BS10: 0 | BT10: 0 | BU10: 0 | BV10: 0 | BW10: 0 | BX10: 0 | BY10: 0 | BZ10: 0 | CA10: 0 | CB10: 0 | CC10: 0 | CD10: 0 | CE10: 0 | CF10: 0 | CG10: 0 | CH10: 861 | CI10: 0 | CJ10: 0 | CK10: 0 | CL10: 0 | CM10: 0 | CN10: 0 | CO10: 0 | CP10: 0 | CQ10: 0 | CR10: 0 | CS10: 1243.2 | CT10: 0 | CU10: 0 | CV10: 0 | CW10: 0 | CX10: 0 | CY10: 0 | CZ10: 0 | DA10: 0 | DB10: 0 | DC10: 0 | DD10: 0 | DE10: 0 | DF10: 0 | DG10: 0 | DH10: 0 | DI10: 0 | DJ10: 0 | DK10: 0 | DL10: 0 | DM10: 0 | DN10: 0 | DO10: 0 | DP10: 0 | DQ10: 0 | DR10: 0 | DS10: 0 | DT10: 0 | DU10: 0 | DV10: 0 | DW10: 0 | DX10: 0 | DY10: 0 | DZ10: 0 | EA10: 0 | EB10: 0 | EC10: 0 | ED10: 0 | EE10: 0 | EF10: 0 | EG10: 0 | EH10: 0 | EI10: 0 | EJ10: 0 | EK10: 0 | EL10: 0 | EM10: 0 | EN10: 0 | EO10: 0 | EP10: 0 | EQ10: 0 | ER10: 0 | ES10: 0 | ET10: 0 | EU10: 0 | EV10: 0 | EW10: 0 | EX10: 0 | EY10: 0 | EZ10: 0 | FA10: 0 | FB10: 0 | FC10: 0 | FD10: 0 | FE10: 0 | FF10: 0 | FG10: 0 | FH10: 0 | FI10: 0 | FJ10: 0 | FK10: 0 | FL10: 0 | FM10: 0 | FN10: 0 | FO10: 0 | FP10: 0 | FQ10: 0 | FR10: 0 | FS10: 0 | FT10: 0 | FU10: 0 | FV10: 0 | FW10: 0 | FX10: 0 | FY10: 0 | FZ10: 0 | GA10: 0 | GB10: 0 | GC10: 0 | GD10: 0 | GE10: 0 | GF10: 0 | GG10: 0 | GH10: 0 | GI10: 0 | GJ10: 0 | GK10: 0 | GL10: 0 | GM10: 0 | GN10: 0 | GO10: 0 | GP10: 0 | GQ10: 0 | GR10: 0 | GS10: 0 | GT10: 0 | GU10: 0 | GV10: 0 | GW10: 0 | GX10: 0 | GY10: 0 | GZ10: 0 | HA10: 0 | HB10: 0 | HC10: 0 | HE10: =SUM(B10:HC10) -> 2104.2 | HF10: =IF(HE10>0,1,0) -> 1
A11: DE | B11: 0 | C11: 0 | D11: 0 | E11: 0 | F11: 0 | G11: 0 | H11: 0 | I11: 0 | J11: 0 | K11: 0 | L11: 0 | M11: 0 | N11: 0 | O11: 0 | P11: 0 | Q11: 0 | R11: 0 | S11: 0 | T11: 0 | U11: 0 | V11: 0 | W11: 0 | X11: 0 | Y11: 0 | Z11: 0 | AA11: 0 | AB11: 0 | AC11: 0 | AD11: 0 | AE11: 0 | AF11: 0 | AG11: 0 | AH11: 0 | AI11: 0 | AJ11: 0 | AK11: 0 | AL11: 0 | AM11: 0 | AN11: 0 | AO11: 0 | AP11: 0 | AQ11: 0 | AR11: 0 | AS11: 0 | AT11: 0 | AU11: 0 | AV11: 0 | AW11: 0 | AX11: 0 | AY11: 0 | AZ11: 0 | BA11: 0 | BB11: 0 | BC11: 0 | BD11: 0 | BE11: 0 | BF11: 0 | BG11: 0 | BH11: 0 | BI11: 0 | BJ11: 0 | BK11: 0 | BL11: 0 | BM11: 0 | BN11: 0 | BO11: 0 | BP11: 0 | BQ11: 0 | BR11: 0 | BS11: 0 | BT11: 0 | BU11: 0 | BV11: 0 | BW11: 0 | BX11: 0 | BY11: 0 | BZ11: 0 | CA11: 0 | CB11: 0 | CC11: 0 | CD11: 0 | CE11: 0 | CF11: 0 | CG11: 0 | CH11: 0 | CI11: 0 | CJ11: 0 | CK11: 0 | CL11: 0 | CM11: 0 | CN11: 0 | CO11: 0 | CP11: 0 | CQ11: 0 | CR11: 0 | CS11: 0 | CT11: 0 | CU11: 0 | CV11: 0 | CW11: 0 | CX11: 0 | CY11: 0 | CZ11: 0 | DA11: 0 | DB11: 0 | DC11: 0 | DD11: 0 | DE11: 0 | DF11: 0 | DG11: 0 | DH11: 0 | DI11: 0 | DJ11: 0 | DK11: 0 | DL11: 0 | DM11: 0 | DN11: 0 | DO11: 0 | DP11: 0 | DQ11: 0 | DR11: 0 | DS11: 0 | DT11: 0 | DU11: 0 | DV11: 0 | DW11: 0 | DX11: 0 | DY11: 0 | DZ11: 0 | EA11: 0 | EB11: 0 | EC11: 0 | ED11: 0 | EE11: 0 | EF11: 0 | EG11: 0 | EH11: 0 | EI11: 0 | EJ11: 0 | EK11: 0 | EL11: 0 | EM11: 0 | EN11: 0 | EO11: 0 | EP11: 0 | EQ11: 0 | ER11: 0 | ES11: 0 | ET11: 0 | EU11: 0 | EV11: 0 | EW11: 0 | EX11: 0 | EY11: 0 | EZ11: 0 | FA11: 0 | FB11: 0 | FC11: 0 | FD11: 0 | FE11: 0 | FF11: 0 | FG11: 0 | FH11: 0 | FI11: 0 | FJ11: 0 | FK11: 0 | FL11: 0 | FM11: 0 | FN11: 0 | FO11: 0 | FP11: 0 | FQ11: 0 | FR11: 0 | FS11: 0 | FT11: 0 | FU11: 0 | FV11: 0 | FW11: 0 | FX11: 0 | FY11: 0 | FZ11: 0 | GA11: 0 | GB11: 0 | GC11: 0 | GD11: 0 | GE11: 0 | GF11: 0 | GG11: 0 | GH11: 0 | GI11: 0 | GJ11: 0 | GK11: 0 | GL11: 0 | GM11: 0 | GN11: 0 | GO11: 0 | GP11: 0 | GQ11: 0 | GR11: 0 | GS11: 0 | GT11: 0 | GU11: 0 | GV11: 0 | GW11: 0 | GX11: 0 | GY11: 0 | GZ11: 0 | HA11: 0 | HB11: 0 | HC11: 0 | HE11: =SUM(B11:HC11) -> 0 | HF11: =IF(HE11>0,1,0) -> 0
A12: FL | B12: 0 | C12: 0 | D12: 0 | E12: 0 | F12: 0 | G12: 0 | H12: 0 | I12: 0 | J12: 0 | K12: 0 | L12: 0 | M12: 0 | N12: 0 | O12: 0 | P12: 0 | Q12: 0 | R12: 0 | S12: 0 | T12: 0 | U12: 0 | V12: 0 | W12: 0 | X12: 0 | Y12: 0 | Z12: 0 | AA12: 0 | AB12: 0 | AC12: 0 | AD12: 0 | AE12: 0 | AF12: 0 | AG12: 0 | AH12: 0 | AI12: 0 | AJ12: 0 | AK12: 0 | AL12: 0 | AM12: 0 | AN12: 0 | AO12: 0 | AP12: 0 | AQ12: 0 | AR12: 0 | AS12: 0 | AT12: 0 | AU12: 0 | AV12: 0 | AW12: 0 | AX12: 0 | AY12: 0 | AZ12: 0 | BA12: 0 | BB12: 0 | BC12: 0 | BD12: 0 | BE12: 0 | BF12: 0 | BG12: 0 | BH12: 0 | BI12: 0 | BJ12: 0 | BK12: 0 | BL12: 0 | BM12: 0 | BN12: 0 | BO12: 0 | BP12: 0 | BQ12: 0 | BR12: 0 | BS12: 0 | BT12: 0 | BU12: 0 | BV12: 0 | BW12: 0 | BX12: 0 | BY12: 0 | BZ12: 0 | CA12: 0 | CB12: 0 | CC12: 0 | CD12: 0 | CE12: 837 | CF12: 861 | CG12: 0 | CH12: 0 | CI12: 981 | CJ12: 0 | CK12: 0 | CL12: 0 | CM12: 0 | CN12: 0 | CO12: 0 | CP12: 987 | CQ12: 0 | CR12: 0 | CS12: 0 | CT12: 0 | CU12: 0 | CV12: 0 | CW12: 0 | CX12: 0 | CY12: 0 | CZ12: 0 | DA12: 0 | DB12: 0 | DC12: 0 | DD12: 0 | DE12: 0 | DF12: 0 | DG12: 0 | DH12: 0 | DI12: 0 | DJ12: 0 | DK12: 0 | DL12: 0 | DM12: 0 | DN12: 0 | DO12: 0 | DP12: 0 | DQ12: 0 | DR12: 0 | DS12: 0 | DT12: 0 | DU12: 0 | DV12: 0 | DW12: 0 | DX12: 0 | DY12: 0 | DZ12: 0 | EA12: 0 | EB12: 0 | EC12: 0 | ED12: 0 | EE12: 0 | EF12: 0 | EG12: 0 | EH12: 0 | EI12: 0 | EJ12: 0 | EK12: 0 | EL12: 0 | EM12: 0 | EN12: 0 | EO12: 0 | EP12: 0 | EQ12: 0 | ER12: 0 | ES12: 0 | ET12: 0 | EU12: 0 | EV12: 0 | EW12: 0 | EX12: 0 | EY12: 0 | EZ12: 0 | FA12: 0 | FB12: 0 | FC12: 0 | FD12: 0 | FE12: 0 | FF12: 0 | FG12: 0 | FH12: 0 | FI12: 0 | FJ12: 0 | FK12: 0 | FL12: 0 | FM12: 0 | FN12: 0 | FO12: 0 | FP12: 0 | FQ12: 0 | FR12: 0 | FS12: 0 | FT12: 0 | FU12: 0 | FV12: 0 | FW12: 0 | FX12: 0 | FY12: 0 | FZ12: 0 | GA12: 0 | GB12: 0 | GC12: 0 | GD12: 0 | GE12: 0 | GF12: 0 | GG12: 0 | GH12: 0 | GI12: 0 | GJ12: 0 | GK12: 0 | GL12: 0 | GM12: 0 | GN12: 0 | GO12: 0 | GP12: 0 | GQ12: 0 | GR12: 0 | GS12: 0 | GT12: 0 | GU12: 0 | GV12: 0 | GW12: 0 | GX12: 0 | GY12: 0 | GZ12: 0 | HA12: 0 | HB12: 0 | HC12: 0 | HE12: =SUM(B12:HC12) -> 3666 | HF12: =IF(HE12>0,1,0) -> 1
A13: GA | B13: 0 | C13: 0 | D13: 0 | E13: 0 | F13: 0 | G13: 0 | H13: 0 | I13: 0 | J13: 0 | K13: 0 | L13: 0 | M13: 0 | N13: 0 | O13: 0 | P13: 0 | Q13: 0 | R13: 0 | S13: 0 | T13: 0 | U13: 0 | V13: 0 | W13: 0 | X13: 0 | Y13: 0 | Z13: 0 | AA13: 0 | AB13: 0 | AC13: 0 | AD13: 0 | AE13: 0 | AF13: 0 | AG13: 0 | AH13: 0 | AI13: 0 | AJ13: 0 | AK13: 0 | AL13: 0 | AM13: 0 | AN13: 0 | AO13: 0 | AP13: 0 | AQ13: 0 | AR13: 0 | AS13: 0 | AT13: 0 | AU13: 0 | AV13: 0 | AW13: 0 | AX13: 0 | AY13: 0 | AZ13: 0 | BA13: 0 | BB13: 0 | BC13: 0 | BD13: 0 | BE13: 0 | BF13: 0 | BG13: 0 | BH13: 0 | BI13: 0 | BJ13: 0 | BK13: 0 | BL13: 0 | BM13: 0 | BN13: 0 | BO13: 0 | BP13: 0 | BQ13: 0 | BR13: 0 | BS13: 0 | BT13: 0 | BU13: 0 | BV13: 0 | BW13: 0 | BX13: 0 | BY13: 0 | BZ13: 0 | CA13: 0 | CB13: 0 | CC13: 0 | CD13: 0 | CE13: 0 | CF13: 0 | CG13: 0 | CH13: 876 | CI13: 0 | CJ13: 0 | CK13: 0 | CL13: 883 | CM13: 0 | CN13: 0 | CO13: 0 | CP13: 0 | CQ13: 0 | CR13: 0 | CS13: 0 | CT13: 1150 | CU13: 0 | CV13: 1152 | CW13: 0 | CX13: 0 | CY13: 0 | CZ13: 0 | DA13: 0 | DB13: 0 | DC13: 0 | DD13: 0 | DE13: 0 | DF13: 0 | DG13: 0 | DH13: 0 | DI13: 0 | DJ13: 0 | DK13: 0 | DL13: 0 | DM13: 0 | DN13: 0 | DO13: 0 | DP13: 0 | DQ13: 0 | DR13: 0 | DS13: 0 | DT13: 0 | DU13: 0 | DV13: 0 | DW13: 0 | DX13: 0 | DY13: 0 | DZ13: 0 | EA13: 0 | EB13: 0 | EC13: 0 | ED13: 1114 | EE13: 1114 | EF13: 0 | EG13: 0 | EH13: 0 | EI13: 0 | EJ13: 0 | EK13: 0 | EL13: 0 | EM13: 0 | EN13: 0 | EO13: 0 | EP13: 0 | EQ13: 0 | ER13: 0 | ES13: 0 | ET13: 0 | EU13: 0 | EV13: 0 | EW13: 0 | EX13: 0 | EY13: 0 | EZ13: 0 | FA13: 0 | FB13: 0 | FC13: 0 | FD13: 0 | FE13: 0 | FF13: 0 | FG13: 0 | FH13: 0 | FI13: 0 | FJ13: 0 | FK13: 0 | FL13: 0 | FM13: 0 | FN13: 0 | FO13: 0 | FP13: 0 | FQ13: 0 | FR13: 0 | FS13: 0 | FT13: 0 | FU13: 0 | FV13: 0 | FW13: 0 | FX13: 0 | FY13: 0 | FZ13: 0 | GA13: 0 | GB13: 0 | GC13: 0 | GD13: 0 | GE13: 0 | GF13: 0 | GG13: 0 | GH13: 0 | GI13: 0 | GJ13: 0 | GK13: 0 | GL13: 0 | GM13: 0 | GN13: 0 | GO13: 0 | GP13: 0 | GQ13: 0 | GR13: 0 | GS13: 0 | GT13: 0 | GU13: 0 | GV13: 0 | GW13: 0 | GX13: 0 | GY13: 0 | GZ13: 0 | HA13: 0 | HB13: 0 | HC13: 0 | HE13: =SUM(B13:HC13) -> 6289 | HF13: =IF(HE13>0,1,0) -> 1
A14: IA | B14: 0 | C14: 0 | D14: 0 | E14: 0 | F14: 0 | G14: 0 | H14: 0 | I14: 0 | J14: 0 | K14: 0 | L14: 0 | M14: 0 | N14: 0 | O14: 0 | P14: 0 | Q14: 0 | R14: 0 | S14: 0 | T14: 0 | U14: 0 | V14: 0 | W14: 0 | X14: 0 | Y14: 0 | Z14: 0 | AA14: 0 | AB14: 0 | AC14: 0 | AD14: 0 | AE14: 0 | AF14: 0 | AG14: 0 | AH14: 0 | AI14: 0 | AJ14: 0 | AK14: 0 | AL14: 0 | AM14: 0 | AN14: 0 | AO14: 0 | AP14: 0 | AQ14: 0 | AR14: 0 | AS14: 0 | AT14: 0 | AU14: 0 | AV14: 0 | AW14: 0 | AX14: 0 | AY14: 0 | AZ14: 0 | BA14: 0 | BB14: 0 | BC14: 0 | BD14: 0 | BE14: 0 | BF14: 0 | BG14: 0 | BH14: 0 | BI14: 0 | BJ14: 0 | BK14: 0 | BL14: 0 | BM14: 0 | BN14: 0 | BO14: 0 | BP14: 0 | BQ14: 0 | BR14: 0 | BS14: 0 | BT14: 0 | BU14: 0 | BV14: 0 | BW14: 0 | BX14: 0 | BY14: 0 | BZ14: 0 | CA14: 0 | CB14: 0 | CC14: 0 | CD14: 0 | CE14: 0 | CF14: 0 | CG14: 0 | CH14: 0 | CI14: 0 | CJ14: 0 | CK14: 0 | CL14: 0 | CM14: 0 | CN14: 0 | CO14: 0 | CP14: 0 | CQ14: 0 | CR14: 0 | CS14: 0 | CT14: 0 | CU14: 0 | CV14: 0 | CW14: 0 | CX14: 0 | CY14: 0 | CZ14: 0 | DA14: 0 | DB14: 0 | DC14: 0 | DD14: 0 | DE14: 0 | DF14: 0 | DG14: 0 | DH14: 0 | DI14: 0 | DJ14: 0 | DK14: 0 | DL14: 0 | DM14: 0 | DN14: 0 | DO14: 0 | DP14: 0 | DQ14: 0 | DR14: 0 | DS14: 0 | DT14: 0 | DU14: 0 | DV14: 0 | DW14: 0 | DX14: 0 | DY14: 0 | DZ14: 0 | EA14: 0 | EB14: 0 | EC14: 0 | ED14: 0 | EE14: 0 | EF14: 0 | EG14: 0 | EH14: 0 | EI14: 0 | EJ14: 0 | EK14: 0 | EL14: 0 | EM14: 0 | EN14: 0 | EO14: 0 | EP14: 0 | EQ14: 0 | ER14: 0 | ES14: 0 | ET14: 0 | EU14: 0 | EV14: 0 | EW14: 0 | EX14: 0 | EY14: 0 | EZ14: 0 | FA14: 0 | FB14: 0 | FC14: 0 | FD14: 0 | FE14: 0 | FF14: 0 | FG14: 0 | FH14: 0 | FI14: 0 | FJ14: 0 | FK14: 0 | FL14: 0 | FM14: 0 | FN14: 0 | FO14: 0 | FP14: 0 | FQ14: 0 | FR14: 0 | FS14: 0 | FT14: 0 | FU14: 0 | FV14: 0 | FW14: 0 | FX14: 0 | FY14: 0 | FZ14: 0 | GA14: 0 | GB14: 0 | GC14: 0 | GD14: 0 | GE14: 0 | GF14: 0 | GG14: 0 | GH14: 0 | GI14: 0 | GJ14: 0 | GK14: 0 | GL14: 0 | GM14: 0 | GN14: 0 | GO14: 0 | GP14: 0 | GQ14: 0 | GR14: 0 | GS14: 0 | GT14: 0 | GU14: 0 | GV14: 0 | GW14: 0 | GX14: 0 | GY14: 0 | GZ14: 0 | HA14: 0 | HB14: 0 | HC14: 0 | HE14: =SUM(B14:HC14) -> 0 | HF14: =IF(HE14>0,1,0) -> 0
A15: ID | B15: 0 | C15: 0 | D15: 0 | E15: 0 | F15: 0 | G15: 0 | H15: 0 | I15: 0 | J15: 0 | K15: 0 | L15: 0 | M15: 0 | N15: 0 | O15: 0 | P15: 0 | Q15: 0 | R15: 0 | S15: 0 | T15: 0 | U15: 0 | V15: 0 | W15: 0 | X15: 0 | Y15: 0 | Z15: 0 | AA15: 0 | AB15: 0 | AC15: 0 | AD15: 0 | AE15: 0 | AF15: 0 | AG15: 0 | AH15: 0 | AI15: 0 | AJ15: 0 | AK15: 0 | AL15: 0 | AM15: 0 | AN15: 0 | AO15: 0 | AP15: 0 | AQ15: 0 | AR15: 0 | AS15: 0 | AT15: 0 | AU15: 0 | AV15: 0 | AW15: 0 | AX15: 0 | AY15: 0 | AZ15: 0 | BA15: 0 | BB15: 0 | BC15: 0 | BD15: 0 | BE15: 0 | BF15: 0 | BG15: 0 | BH15: 0 | BI15: 0 | BJ15: 0 | BK15: 0 | BL15: 0 | BM15: 0 | BN15: 0 | BO15: 0 | BP15: 0 | BQ15: 0 | BR15: 0 | BS15: 0 | BT15: 0 | BU15: 0 | BV15: 0 | BW15: 0 | BX15: 0 | BY15: 0 | BZ15: 0 | CA15: 0 | CB15: 0 | CC15: 0 | CD15: 0 | CE15: 0 | CF15: 0 | CG15: 0 | CH15: 0 | CI15: 0 | CJ15: 0 | CK15: 0 | CL15: 0 | CM15: 0 | CN15: 0 | CO15: 0 | CP15: 0 | CQ15: 0 | CR15: 0 | CS15: 0 | CT15: 0 | CU15: 0 | CV15: 0 | CW15: 0 | CX15: 0 | CY15: 0 | CZ15: 0 | DA15: 0 | DB15: 0 | DC15: 0 | DD15: 0 | DE15: 0 | DF15: 0 | DG15: 0 | DH15: 0 | DI15: 0 | DJ15: 0 | DK15: 0 | DL15: 0 | DM15: 0 | DN15: 0 | DO15: 0 | DP15: 0 | DQ15: 0 | DR15: 0 | DS15: 0 | DT15: 0 | DU15: 0 | DV15: 0 | DW15: 0 | DX15: 0 | DY15: 0 | DZ15: 0 | EA15: 0 | EB15: 0 | EC15: 0 | ED15: 0 | EE15: 0 | EF15: 0 | EG15: 0 | EH15: 0 | EI15: 0 | EJ15: 0 | EK15: 0 | EL15: 0 | EM15: 0 | EN15: 0 | EO15: 0 | EP15: 0 | EQ15: 0 | ER15: 0 | ES15: 0 | ET15: 0 | EU15: 0 | EV15: 0 | EW15: 0 | EX15: 0 | EY15: 0 | EZ15: 0 | FA15: 0 | FB15: 0 | FC15: 0 | FD15: 0 | FE15: 0 | FF15: 0 | FG15: 0 | FH15: 0 | FI15: 0 | FJ15: 0 | FK15: 0 | FL15: 0 | FM15: 0 | FN15: 0 | FO15: 0 | FP15: 0 | FQ15: 0 | FR15: 0 | FS15: 0 | FT15: 0 | FU15: 0 | FV15: 0 | FW15: 0 | FX15: 0 | FY15: 0 | FZ15: 0 | GA15: 0 | GB15: 0 | GC15: 0 | GD15: 0 | GE15: 0 | GF15: 0 | GG15: 0 | GH15: 0 | GI15: 0 | GJ15: 0 | GK15: 0 | GL15: 0 | GM15: 0 | GN15: 0 | GO15: 0 | GP15: 0 | GQ15: 0 | GR15: 0 | GS15: 0 | GT15: 0 | GU15: 0 | GV15: 0 | GW15: 0 | GX15: 0 | GY15: 0 | GZ15: 0 | HA15: 0 | HB15: 0 | HC15: 0 | HE15: =SUM(B15:HC15) -> 0 | HF15: =IF(HE15>0,1,0) -> 0
A16: IL | B16: 0 | C16: 0 | D16: 0 | E16: 0 | F16: 0 | G16: 0 | H16: 0 | I16: 0 | J16: 0 | K16: 0 | L16: 0 | M16: 0 | N16: 0 | O16: 0 | P16: 0 | Q16: 0 | R16: 0 | S16: 0 | T16: 0 | U16: 0 | V16: 0 | W16: 0 | X16: 0 | Y16: 0 | Z16: 0 | AA16: 0 | AB16: 0 | AC16: 0 | AD16: 0 | AE16: 0 | AF16: 0 | AG16: 0 | AH16: 0 | AI16: 0 | AJ16: 0 | AK16: 0 | AL16: 0 | AM16: 0 | AN16: 0 | AO16: 0 | AP16: 0 | AQ16: 0 | AR16: 0 | AS16: 0 | AT16: 0 | AU16: 0 | AV16: 0 | AW16: 0 | AX16: 0 | AY16: 0 | AZ16: 0 | BA16: 0 | BB16: 0 | BC16: 0 | BD16: 0 | BE16: 0 | BF16: 0 | BG16: 0 | BH16: 0 | BI16: 0 | BJ16: 0 | BK16: 0 | BL16: 0 | BM16: 0 | BN16: 0 | BO16: 0 | BP16: 0 | BQ16: 0 | BR16: 0 | BS16: 0 | BT16: 0 | BU16: 0 | BV16: 0 | BW16: 0 | BX16: 0 | BY16: 0 | BZ16: 0 | CA16: 0 | CB16: 0 | CC16: 902 | CD16: 895 | CE16: 1819 | CF16: 0 | CG16: 0 | CH16: 0 | CI16: 0 | CJ16: 0 | CK16: 0 | CL16: 0 | CM16: 0 | CN16: 0 | CO16: 0 | CP16: 0 | CQ16: 2264.4 | CR16: 1164 | CS16: 0 | CT16: 2214.9 | CU16: 2332.3 | CV16: 0 | CW16: 0 | CX16: 0 | CY16: 0 | CZ16: 0 | DA16: 0 | DB16: 0 | DC16: 0 | DD16: 0 | DE16: 0 | DF16: 0 | DG16: 0 | DH16: 0 | DI16: 0 | DJ16: 0 | DK16: 0 | DL16: 0 | DM16: 0 | DN16: 0 | DO16: 0 | DP16: 0 | DQ16: 0 | DR16: 0 | DS16: 0 | DT16: 0 | DU16: 0 | DV16: 0 | DW16: 0 | DX16: 0 | DY16: 0 | DZ16: 0 | EA16: 0 | EB16: 0 | EC16: 0 | ED16: 0 | EE16: 0 | EF16: 0 | EG16: 0 | EH16: 0 | EI16: 0 | EJ16: 0 | EK16: 0 | EL16: 0 | EM16: 0 | EN16: 0 | EO16: 0 | EP16: 0 | EQ16: 0 | ER16: 0 | ES16: 0 | ET16: 0 | EU16: 0 | EV16: 0 | EW16: 0 | EX16: 0 | EY16: 0 | EZ16: 0 | FA16: 0 | FB16: 0 | FC16: 0 | FD16: 0 | FE16: 0 | FF16: 0 | FG16: 0 | FH16: 0 | FI16: 0 | FJ16: 0 | FK16: 0 | FL16: 0 | FM16: 0 | FN16: 0 | FO16: 0 | FP16: 0 | FQ16: 0 | FR16: 0 | FS16: 0 | FT16: 0 | FU16: 0 | FV16: 0 | FW16: 0 | FX16: 0 | FY16: 0 | FZ16: 0 | GA16: 0 | GB16: 0 | GC16: 0 | GD16: 0 | GE16: 0 | GF16: 0 | GG16: 0 | GH16: 0 | GI16: 0 | GJ16: 0 | GK16: 0 | GL16: 0 | GM16: 0 | GN16: 0 | GO16: 0 | GP16: 0 | GQ16: 0 | GR16: 0 | GS16: 0 | GT16: 0 | GU16: 0 | GV16: 0 | GW16: 0 | GX16: 0 | GY16: 0 | GZ16: 0 | HA16: 0 | HB16: 0 | HC16: 0 | HE16: =SUM(B16:HC16) -> 11591.6 | HF16: =IF(HE16>0,1,0) -> 1
... A52: WY | B52: 0 | C52: 0 | D52: 0 | E52: 0 | F52: 0 | G52: 0 | H52: 0 | I52: 0 | J52: 0 | K52: 0 | L52: 0 | M52: 0 | N52: 0 | O52: 0 | P52: 0 | Q52: 0 | R52: 0 | S52: 0 | T52: 0 | U52: 0 | V52: 0 | W52: 0 | X52: 0 | Y52: 0 | Z52: 0 | AA52: 0 | AB52: 0 | AC52: 0 | AD52: 0 | AE52: 0 | AF52: 0 | AG52: 0 | AH52: 0 | AI52: 0 | AJ52: 0 | AK52: 0 | AL52: 0 | AM52: 0 | AN52: 0 | AO52: 0 | AP52: 0 | AQ52: 0 | AR52: 0 | AS52: 0 | AT52: 0 | AU52: 0 | AV52: 0 | AW52: 0 | AX52: 0 | AY52: 0 | AZ52: 0 | BA52: 0 | BB52: 0 | BC52: 0 | BD52: 0 | BE52: 0 | BF52: 0 | BG52: 0 | BH52: 0 | BI52: 0 | BJ52: 0 | BK52: 0 | BL52: 0 | BM52: 0 | BN52: 0 | BO52: 0 | BP52: 0 | BQ52: 0 | BR52: 0 | BS52: 0 | BT52: 0 | BU52: 0 | BV52: 0 | BW52: 0 | BX52: 0 | BY52: 0 | BZ52: 0 | CA52: 0 | CB52: 0 | CC52: 0 | CD52: 0 | CE52: 0 | CF52: 0 | CG52: 0 | CH52: 0 | CI52: 0 | CJ52: 0 | CK52: 0 | CL52: 0 | CM52: 0 | CN52: 0 | CO52: 0 | CP52: 0 | CQ52: 0 | CR52: 0 | CS52: 0 | CT52: 0 | CU52: 0 | CV52: 0 | CW52: 0 | CX52: 0 | CY52: 0 | CZ52: 0 | DA52: 0 | DB52: 0 | DC52: 0 | DD52: 0 | DE52: 0 | DF52: 0 | DG52: 0 | DH52: 0 | DI52: 0 | DJ52: 0 | DK52: 0 | DL52: 0 | DM52: 0 | DN52: 0 | DO52: 0 | DP52: 0 | DQ52: 0 | DR52: 0 | DS52: 0 | DT52: 0 | DU52: 0 | DV52: 0 | DW52: 0 | DX52: 0 | DY52: 0 | DZ52: 0 | EA52: 0 | EB52: 0 | EC52: 0 | ED52: 0 | EE52: 0 | EF52: 0 | EG52: 0 | EH52: 0 | EI52: 0 | EJ52: 0 | EK52: 0 | EL52: 0 | EM52: 0 | EN52: 0 | EO52: 0 | EP52: 0 | EQ52: 0 | ER52: 0 | ES52: 0 | ET52: 0 | EU52: 0 | EV52: 0 | EW52: 0 | EX52: 0 | EY52: 0 | EZ52: 0 | FA52: 0 | FB52: 0 | FC52: 0 | FD52: 0 | FE52: 0 | FF52: 0 | FG52: 0 | FH52: 0 | FI52: 0 | FJ52: 0 | FK52: 0 | FL52: 0 | FM52: 0 | FN52: 0 | FO52: 0 | FP52: 0 | FQ52: 0 | FR52: 0 | FS52: 0 | FT52: 0 | FU52: 0 | FV52: 0 | FW52: 0 | FX52: 0 | FY52: 0 | FZ52: 0 | GA52: 0 | GB52: 0 | GC52: 0 | GD52: 0 | GE52: 0 | GF52: 0 | GG52: 0 | GH52: 0 | GI52: 0 | GJ52: 0 | GK52: 0 | GL52: 0 | GM52: 0 | GN52: 0 | GO52: 0 | GP52: 0 | GQ52: 0 | GR52: 0 | GS52: 0 | GT52: 0 | GU52: 0 | GV52: 0 | GW52: 0 | GX52: 0 | GY52: 0 | GZ52: 0 | HA52: 0 | HB52: 0 | HC52: 0 | HE52: =SUM(B52:HC52) -> 0 | HF52: =IF(HE52>0,1,0) -> 0

Sheet Src_SYSHECF_nuclear
A1: Src_SYSHECF_nuclear
A2: Every state's SYSHECF-nuclear.csv, verbatim, tall (48 states x 6 slices). Only the gated states' rows are consumed by Calcs; the rest are embedded for completeness (the file exists in every state folder).
A3: Provenance: state-eps-data-repository @ 3599b4df1a + uncommitted working-tree edits (the recalibration itself), read 2026-08-31.
A4: state | B4: slice | C4: key state|slice | D4: Hour0 | E4: Hour1 | F4: Hour2 | G4: Hour3 | H4: Hour4 | I4: Hour5 | J4: Hour6 | K4: Hour7 | L4: Hour8 | M4: Hour9 | N4: Hour10 | O4: Hour11 | P4: Hour12 | Q4: Hour13 | R4: Hour14 | S4: Hour15 | T4: Hour16 | U4: Hour17 | V4: Hour18 | W4: Hour19 | X4: Hour20 | Y4: Hour21 | Z4: Hour22 | AA4: Hour23
A5: AL | B5: Winter | C5: =A5&"|"&B5 -> AL|Winter | D5: 0.91246672 | E5: 0.91246672 | F5: 0.91246672 | G5: 0.91246672 | H5: 0.91246672 | I5: 0.91246672 | J5: 0.91246672 | K5: 0.91246672 | L5: 0.91246672 | M5: 0.91246672 | N5: 0.91246672 | O5: 0.91246672 | P5: 0.91246672 | Q5: 0.91246672 | R5: 0.91246672 | S5: 0.91246672 | T5: 0.91246672 | U5: 0.91246672 | V5: 0.91246672 | W5: 0.91246672 | X5: 0.91246672 | Y5: 0.91246672 | Z5: 0.91246672 | AA5: 0.91246672
A6: AL | B6: Spring | C6: =A6&"|"&B6 -> AL|Spring | D6: 0.91246672 | E6: 0.91246672 | F6: 0.91246672 | G6: 0.91246672 | H6: 0.91246672 | I6: 0.91246672 | J6: 0.91246672 | K6: 0.91246672 | L6: 0.91246672 | M6: 0.91246672 | N6: 0.91246672 | O6: 0.91246672 | P6: 0.91246672 | Q6: 0.91246672 | R6: 0.91246672 | S6: 0.91246672 | T6: 0.91246672 | U6: 0.91246672 | V6: 0.91246672 | W6: 0.91246672 | X6: 0.91246672 | Y6: 0.91246672 | Z6: 0.91246672 | AA6: 0.91246672
A7: AL | B7: Summer | C7: =A7&"|"&B7 -> AL|Summer | D7: 0.91246672 | E7: 0.91246672 | F7: 0.91246672 | G7: 0.91246672 | H7: 0.91246672 | I7: 0.91246672 | J7: 0.91228855 | K7: 0.91246672 | L7: 0.91246672 | M7: 0.91246672 | N7: 0.91246672 | O7: 0.91246672 | P7: 0.91246672 | Q7: 0.91246672 | R7: 0.91246672 | S7: 0.91246672 | T7: 0.91246672 | U7: 0.91246672 | V7: 0.91246672 | W7: 0.91246672 | X7: 0.91246672 | Y7: 0.91246672 | Z7: 0.91246672 | AA7: 0.91246672
A8: AL | B8: Fall | C8: =A8&"|"&B8 -> AL|Fall | D8: 0.91246672 | E8: 0.91246672 | F8: 0.91246672 | G8: 0.91246672 | H8: 0.91246672 | I8: 0.9080654 | J8: 0.91090943 | K8: 0.91246672 | L8: 0.91246672 | M8: 0.91246672 | N8: 0.91246672 | O8: 0.91246672 | P8: 0.91246672 | Q8: 0.91246672 | R8: 0.91246672 | S8: 0.91246672 | T8: 0.91246672 | U8: 0.91246672 | V8: 0.91246672 | W8: 0.91246672 | X8: 0.91246672 | Y8: 0.91246672 | Z8: 0.91246672 | AA8: 0.91246672
A9: AL | B9: Summer Peak | C9: =A9&"|"&B9 -> AL|Summer Peak | D9: 0.91246672 | E9: 0.91246672 | F9: 0.91246672 | G9: 0.91246672 | H9: 0.91246672 | I9: 0.91246672 | J9: 0.91246672 | K9: 0.91246672 | L9: 0.91246672 | M9: 0.91246672 | N9: 0.91246672 | O9: 0.91246672 | P9: 0.91246672 | Q9: 0.91246672 | R9: 0.91246672 | S9: 0.91246672 | T9: 0.91246672 | U9: 0.91246672 | V9: 0.91246672 | W9: 0.91246672 | X9: 0.91246672 | Y9: 0.91246672 | Z9: 0.91246672 | AA9: 0.91246672
A10: AL | B10: Winter Peak | C10: =A10&"|"&B10 -> AL|Winter Peak | D10: 0.91246672 | E10: 0.91246672 | F10: 0.91246672 | G10: 0.91246672 | H10: 0.91246672 | I10: 0.91246672 | J10: 0.91246672 | K10: 0.91246672 | L10: 0.91246672 | M10: 0.91246672 | N10: 0.91246672 | O10: 0.91246672 | P10: 0.91246672 | Q10: 0.91246672 | R10: 0.91246672 | S10: 0.91246672 | T10: 0.91246672 | U10: 0.91246672 | V10: 0.91246672 | W10: 0.91246672 | X10: 0.91246672 | Y10: 0.91246672 | Z10: 0.91246672 | AA10: 0.91246672
A11: AR | B11: Winter | C11: =A11&"|"&B11 -> AR|Winter | D11: 0.94288092 | E11: 0.94288092 | F11: 0.94288092 | G11: 0.94288092 | H11: 0.94288092 | I11: 0.94288092 | J11: 0.94288092 | K11: 0.94288092 | L11: 0.94288092 | M11: 0.94288092 | N11: 0.94288092 | O11: 0.94288092 | P11: 0.94288092 | Q11: 0.94288092 | R11: 0.94288092 | S11: 0.94288092 | T11: 0.94288092 | U11: 0.94288092 | V11: 0.94288092 | W11: 0.94288092 | X11: 0.94288092 | Y11: 0.94288092 | Z11: 0.94288092 | AA11: 0.94288092
A12: AR | B12: Spring | C12: =A12&"|"&B12 -> AR|Spring | D12: 0.94288092 | E12: 0.94288092 | F12: 0.94288092 | G12: 0.94288092 | H12: 0.94288092 | I12: 0.93673108 | J12: 0.93673108 | K12: 0.94288092 | L12: 0.94288092 | M12: 0.94288092 | N12: 0.94288092 | O12: 0.94288092 | P12: 0.94288092 | Q12: 0.94288092 | R12: 0.94288092 | S12: 0.94288092 | T12: 0.94288092 | U12: 0.94288092 | V12: 0.94288092 | W12: 0.94288092 | X12: 0.94288092 | Y12: 0.94288092 | Z12: 0.94288092 | AA12: 0.94288092
A13: AR | B13: Summer | C13: =A13&"|"&B13 -> AR|Summer | D13: 0.94288092 | E13: 0.94288092 | F13: 0.94288092 | G13: 0.94288092 | H13: 0.94288092 | I13: 0.93782927 | J13: 0.93782927 | K13: 0.94288092 | L13: 0.94288092 | M13: 0.94288092 | N13: 0.94288092 | O13: 0.94288092 | P13: 0.94288092 | Q13: 0.94288092 | R13: 0.94288092 | S13: 0.94288092 | T13: 0.94288092 | U13: 0.94288092 | V13: 0.94288092 | W13: 0.94288092 | X13: 0.94288092 | Y13: 0.94288092 | Z13: 0.94288092 | AA13: 0.94288092
A14: AR | B14: Fall | C14: =A14&"|"&B14 -> AR|Fall | D14: 0.94288092 | E14: 0.94288092 | F14: 0.94288092 | G14: 0.94288092 | H14: 0.94288092 | I14: 0.93900568 | J14: 0.94152657 | K14: 0.94288092 | L14: 0.94288092 | M14: 0.94288092 | N14: 0.94288092 | O14: 0.94288092 | P14: 0.94288092 | Q14: 0.94288092 | R14: 0.94288092 | S14: 0.94288092 | T14: 0.94288092 | U14: 0.94288092 | V14: 0.94288092 | W14: 0.94288092 | X14: 0.94288092 | Y14: 0.94288092 | Z14: 0.94288092 | AA14: 0.94288092
A15: AR | B15: Summer Peak | C15: =A15&"|"&B15 -> AR|Summer Peak | D15: 0.94288092 | E15: 0.94288092 | F15: 0.94288092 | G15: 0.94288092 | H15: 0.94288092 | I15: 0.94288092 | J15: 0.94288092 | K15: 0.94288092 | L15: 0.94288092 | M15: 0.94288092 | N15: 0.94288092 | O15: 0.94288092 | P15: 0.94288092 | Q15: 0.94288092 | R15: 0.94288092 | S15: 0.94288092 | T15: 0.94288092 | U15: 0.94288092 | V15: 0.94288092 | W15: 0.94288092 | X15: 0.94288092 | Y15: 0.94288092 | Z15: 0.94288092 | AA15: 0.94288092
A16: AR | B16: Winter Peak | C16: =A16&"|"&B16 -> AR|Winter Peak | D16: 0.94288092 | E16: 0.94288092 | F16: 0.94288092 | G16: 0.94288092 | H16: 0.94288092 | I16: 0.94288092 | J16: 0.94288092 | K16: 0.94288092 | L16: 0.94288092 | M16: 0.94288092 | N16: 0.94288092 | O16: 0.94288092 | P16: 0.94288092 | Q16: 0.94288092 | R16: 0.94288092 | S16: 0.94288092 | T16: 0.94288092 | U16: 0.94288092 | V16: 0.94288092 | W16: 0.94288092 | X16: 0.94288092 | Y16: 0.94288092 | Z16: 0.94288092 | AA16: 0.94288092
... A292: WY | B292: Winter Peak | C292: =A292&"|"&B292 -> WY|Winter Peak | D292: 0.909 | E292: 0.909 | F292: 0.909 | G292: 0.909 | H292: 0.909 | I292: 0.909 | J292: 0.909 | K292: 0.909 | L292: 0.909 | M292: 0.909 | N292: 0.909 | O292: 0.909 | P292: 0.909 | Q292: 0.909 | R292: 0.909 | S292: 0.909 | T292: 0.909 | U292: 0.909 | V292: 0.909 | W292: 0.909 | X292: 0.909 | Y292: 0.909 | Z292: 0.909 | AA292: 0.909

Sheet Src_VRE
A1: Src_VRE
A2: Deployed VRE ELCCAfR grids (onshore wind, solar pv, solar thermal, offshore wind), verbatim — Robbie's P30 pinned-peak-day builder output. This workbook passes them through unchanged; it does not re-derive them.
A3: Provenance: state-eps-data-repository @ 3599b4df1a + uncommitted working-tree edits (the recalibration itself), read 2026-08-31.
A4: state | B4: tech file slug | C4: slice | D4: key state|slug|slice | E4: Hour0 | F4: Hour1 | G4: Hour2 | H4: Hour3 | I4: Hour4 | J4: Hour5 | K4: Hour6 | L4: Hour7 | M4: Hour8 | N4: Hour9 | O4: Hour10 | P4: Hour11 | Q4: Hour12 | R4: Hour13 | S4: Hour14 | T4: Hour15 | U4: Hour16 | V4: Hour17 | W4: Hour18 | X4: Hour19 | Y4: Hour20 | Z4: Hour21 | AA4: Hour22 | AB4: Hour23
A5: AL | B5: onshore-wind | C5: onshore wind | D5: Winter | E5: =A5&"|"&C5&"|"&D5 -> AL|onshore wind|Winter | F5: 1 | G5: 1 | H5: 1 | I5: 1 | J5: 1 | K5: 1 | L5: 1 | M5: 1 | N5: 1 | O5: 1 | P5: 1 | Q5: 1 | R5: 1 | S5: 1 | T5: 1 | U5: 1 | V5: 1 | W5: 1 | X5: 1 | Y5: 1 | Z5: 1 | AA5: 1 | AB5: 1 | AC5: 1
A6: AL | B6: onshore-wind | C6: onshore wind | D6: Spring | E6: =A6&"|"&C6&"|"&D6 -> AL|onshore wind|Spring | F6: 1 | G6: 1 | H6: 1 | I6: 1 | J6: 1 | K6: 1 | L6: 1 | M6: 1 | N6: 1 | O6: 1 | P6: 1 | Q6: 1 | R6: 1 | S6: 1 | T6: 1 | U6: 1 | V6: 1 | W6: 1 | X6: 1 | Y6: 1 | Z6: 1 | AA6: 1 | AB6: 1 | AC6: 1
A7: AL | B7: onshore-wind | C7: onshore wind | D7: Summer | E7: =A7&"|"&C7&"|"&D7 -> AL|onshore wind|Summer | F7: 1 | G7: 1 | H7: 1 | I7: 1 | J7: 1 | K7: 1 | L7: 1 | M7: 1 | N7: 1 | O7: 1 | P7: 1 | Q7: 1 | R7: 1 | S7: 1 | T7: 1 | U7: 1 | V7: 1 | W7: 1 | X7: 1 | Y7: 1 | Z7: 1 | AA7: 1 | AB7: 1 | AC7: 1
A8: AL | B8: onshore-wind | C8: onshore wind | D8: Fall | E8: =A8&"|"&C8&"|"&D8 -> AL|onshore wind|Fall | F8: 1 | G8: 1 | H8: 1 | I8: 1 | J8: 1 | K8: 1 | L8: 1 | M8: 1 | N8: 1 | O8: 1 | P8: 1 | Q8: 1 | R8: 1 | S8: 1 | T8: 1 | U8: 1 | V8: 1 | W8: 1 | X8: 1 | Y8: 1 | Z8: 1 | AA8: 1 | AB8: 1 | AC8: 1
A9: AL | B9: onshore-wind | C9: onshore wind | D9: Summer Peak | E9: =A9&"|"&C9&"|"&D9 -> AL|onshore wind|Summer Peak | F9: 0.9213 | G9: 0.928 | H9: 0.9529 | I9: 0.9494 | J9: 0.9344 | K9: 0.9422 | L9: 0.9618 | M9: 0.916 | N9: 0.817 | O9: 0.7732 | P9: 0.7672 | Q9: 0.7559 | R9: 0.6911 | S9: 0.7569 | T9: 0.8218 | U9: 0.8394 | V9: 0.8623 | W9: 0.8938 | X9: 0.9103 | Y9: 0.9335 | Z9: 0.929 | AA9: 0.9536 | AB9: 0.9761 | AC9: 0.9895
A10: AL | B10: onshore-wind | C10: onshore wind | D10: Winter Peak | E10: =A10&"|"&C10&"|"&D10 -> AL|onshore wind|Winter Peak | F10: 0.8839 | G10: 0.8569 | H10: 0.8389 | I10: 0.8246 | J10: 0.8097 | K10: 0.7799 | L10: 0.7956 | M10: 0.8067 | N10: 0.8546 | O10: 0.8916 | P10: 0.9459 | Q10: 0.9592 | R10: 0.972 | S10: 0.9603 | T10: 0.8889 | U10: 0.8507 | V10: 0.9267 | W10: 0.8877 | X10: 0.8751 | Y10: 0.8409 | Z10: 0.8108 | AA10: 0.8073 | AB10: 0.7985 | AC10: 0.7899
A11: AL | B11: solar-pv | C11: solar pv | D11: Winter | E11: =A11&"|"&C11&"|"&D11 -> AL|solar pv|Winter | F11: 1 | G11: 1 | H11: 1 | I11: 1 | J11: 1 | K11: 1 | L11: 1 | M11: 1 | N11: 1 | O11: 1 | P11: 1 | Q11: 1 | R11: 1 | S11: 1 | T11: 1 | U11: 1 | V11: 1 | W11: 1 | X11: 1 | Y11: 1 | Z11: 1 | AA11: 1 | AB11: 1 | AC11: 1
A12: AL | B12: solar-pv | C12: solar pv | D12: Spring | E12: =A12&"|"&C12&"|"&D12 -> AL|solar pv|Spring | F12: 1 | G12: 1 | H12: 1 | I12: 1 | J12: 1 | K12: 1 | L12: 1 | M12: 1 | N12: 1 | O12: 1 | P12: 1 | Q12: 1 | R12: 1 | S12: 1 | T12: 1 | U12: 1 | V12: 1 | W12: 1 | X12: 1 | Y12: 1 | Z12: 1 | AA12: 1 | AB12: 1 | AC12: 1
A13: AL | B13: solar-pv | C13: solar pv | D13: Summer | E13: =A13&"|"&C13&"|"&D13 -> AL|solar pv|Summer | F13: 1 | G13: 1 | H13: 1 | I13: 1 | J13: 1 | K13: 1 | L13: 1 | M13: 1 | N13: 1 | O13: 1 | P13: 1 | Q13: 1 | R13: 1 | S13: 1 | T13: 1 | U13: 1 | V13: 1 | W13: 1 | X13: 1 | Y13: 1 | Z13: 1 | AA13: 1 | AB13: 1 | AC13: 1
