Workbook

Sheet About
A1: BFoICStCT BAU Fraction of Industry Category Subject to Carbon Tax | B1: Arizona | C1: 46268
A2: State abbr (derived): | B2: =IFERROR(INDEX(Keys!$A:$A,MATCH($B$1,Keys!$B:$B,0)),"") -> AZ
A4: Sources:
A6: Notes
A7: This file controls the extent to which the industry sector carbon tax is levied on each industry, per state. It can be set between 0 (industry entirely exempt) and 1 (industry entirely covered).
A9: Default (no enacted adjustment for the active state): every category = 1, no exemption, except 'agriculture and forestry 01T03' and 'water and waste 36T39' (Keys!zero_flag), which are always 0 regardless of state.
A10: If the active state has 'Adjustments to BFoICStCT' = Y on the State Policies tab and is not the Keys!reg27_state (currently Oregon -- its Climate Protection Program is fossil-only, not industry-wide): only 'oil and gas extraction 06', 'coal mining 05', and 'energy pipelines and gas processing 352T353' = 1; every other category = 0. The zero_flag categories stay 0 in this case too. See 'State Calculations'.
A11: If the active state is the Keys!reg27_state (Colorado) and is flagged Y: manufacturing categories = 1, the same as the default, because the Reg 27 Part D baseline-and-credit market sits under GEMM -- Greenhouse Gas Emissions and Energy Management for MANUFACTURERS. The zero_flag categories stay 0. Two carve-outs follow.
A12: Colorado carve-out 1 -- permanent. The Keys!reg27_exempt_flag categories 'coal mining 05', 'oil and gas extraction 06' and 'other mining and quarrying 07T08' = 0 in EVERY year: extraction and quarrying are not manufacturing, and Colorado regulates upstream oil and gas separately ('Oil and Gas Methane Regulations' on the Industry sheet -> BPE; PERAC), so covering them here would risk double counting. This exemption applies to Colorado ONLY -- these three categories are still 1 for all other states.
A13: Colorado carve-out 2 -- year-stepped. Midstream oil and gas operators do not join the Reg 27 Part D market until Keys!reg27_expansion_year (2028), so the Keys!reg27_expansion_flag category 'energy pipelines and gas processing 352T353' = 0 through 2027 and 1 from 2028 on. This is the only category in the file whose value varies by year.

Sheet Keys
A1: state_abbr | B1: state_name | D1: category | E1: fossil_flag | F1: zero_flag | G1: reg27_expansion_flag | H1: reg27_exempt_flag | J1: reg27_state | K1: reg27_expansion_year
A2: AL | B2: Alabama | D2: agriculture and forestry 01T03 | F2: Y | J2: CO | K2: 2028
A3: AR | B3: Arkansas | D3: coal mining 05 | E3: Y | H3: Y
A4: AZ | B4: Arizona | D4: oil and gas extraction 06 | E4: Y | H4: Y
A5: CA | B5: California | D5: other mining and quarrying 07T08 | H5: Y
A6: CO | B6: Colorado | D6: food beverage and tobacco 10T12
A7: CT | B7: Connecticut | D7: textiles apparel and leather 13T15
A8: DE | B8: Delaware | D8: wood products 16
A9: FL | B9: Florida | D9: pulp paper and printing 17T18
A10: GA | B10: Georgia | D10: refined petroleum and coke 19
A11: IA | B11: Iowa | D11: chemicals 20
A12: ID | B12: Idaho | D12: rubber and plastic products 22
A13: IL | B13: Illinois | D13: glass and glass products 231
A14: IN | B14: Indiana | D14: cement and other nonmetallic minerals 239
A15: KS | B15: Kansas | D15: iron and steel 241
A16: KY | B16: Kentucky | D16: other metals 242
A17: LA | B17: Louisiana | D17: metal products except machinery and vehicles 25
... A23: MO | B23: Missouri | D23: other manufacturing 31T33
A24: MS | B24: Mississippi | D24: energy pipelines and gas processing 352T353 | E24: Y | G24: Y
A25: MT | B25: Montana | D25: water and waste 36T39 | F25: Y
A26: NC | B26: North Carolina | D26: construction 41T43
A27: ND | B27: North Dakota
A28: NE | B28: Nebraska
A29: NH | B29: New Hampshire
A30: NJ | B30: New Jersey
A31: NM | B31: New Mexico
A32: NV | B32: Nevada
A33: NY | B33: New York
A34: OH | B34: Ohio
A35: OK | B35: Oklahoma
A36: OR | B36: Oregon
A37: PA | B37: Pennsylvania
A38: RI | B38: Rhode Island
... A49: WY | B49: Wyoming

Sheet State Calculations
A1: Unit: dimensionless | B1: 2021 | C1: 2022 | D1: 2023 | E1: 2024 | F1: 2025 | G1: 2026 | H1: 2027 | I1: 2028 | J1: 2029 | K1: 2030 | L1: 2031 | M1: 2032 | N1: 2033 | O1: 2034 | P1: 2035 | Q1: 2036 | R1: 2037 | S1: 2038 | T1: 2039 | U1: 2040 | V1: 2041 | W1: 2042 | X1: 2043 | Y1: 2044 | Z1: 2045 | AA1: 2046 | AB1: 2047 | AC1: 2048 | AD1: 2049 | AE1: 2050
A2: =Keys!$D2 -> agriculture and forestry 01T03 | B2: =IF(INDEX(Keys!$F:$F,MATCH($A2,Keys!$D:$D,0))="Y",0,IF($B28=1,IF($B29=1,IF(INDEX(Keys!$H:$H,MATCH($A2,Keys!$D:$D,0))="Y",0,IF(AND(INDEX(Keys!$G:$G,MATCH($A2,Keys!$D:$D,0))="Y",B$1<Keys!$K$2),0,1)),IF(INDEX(Keys!$E:$E,MATCH($A2,Keys!$D:$D,0))="Y",1,0)),1)) -> 0 | C2: =IF(INDEX(Keys!$F:$F,MATCH($A2,Keys!$D:$D,0))="Y",0,IF($B28=1,IF($B29=1,IF(INDEX(Keys!$H:$H,MATCH($A2,Keys!$D:$D,0))="Y",0,IF(AND(INDEX(Keys!$G:$G,MATCH($A2,Keys!$D:$D,0))="Y",C$1<Keys!$K$2),0,1)),IF(INDEX(Keys!$E:$E,MATCH($A2,Keys!$D:$D,0))="Y",1,0)),1)) -> 0 | D2: =IF(INDEX(Keys!$F:$F,MATCH($A2,Keys!$D:$D,0))="Y",0,IF($B28=1,IF($B29=1,IF(INDEX(Keys!$H:$H,MATCH($A2,Keys!$D:$D,0))="Y",0,IF(AND(INDEX(Keys!$G:$G,MATCH($A2,Keys!$D:$D,0))="Y",D$1<Keys!$K$2),0,1)),IF(INDEX(Keys!$E:$E,MATCH($A2,Keys!$D:$D,0))="Y",1,0)),1)) -> 0 | E2: =IF(INDEX(Keys!$F:$F,MATCH($A2,Keys!$D:$D,0))="Y",0,IF($B28=1,IF($B29=1,IF(INDEX(Keys!$H:$H,MATCH($A2,Keys!$D:$D,0))="Y",0,IF(AND(INDEX(Keys!$G:$G,MATCH($A2,Keys!$D:$D,0))="Y",E$1<Keys!$K$2),0,1)),IF(INDEX(Keys!$E:$E,MATCH($A2,Keys!$D:$D,0))="Y",1,0)),1)) -> 0 | F2: =IF(INDEX(Keys!$F:$F,MATCH($A2,Keys!$D:$D,0))="Y",0,IF($B28=1,IF($B29=1,IF(INDEX(Keys!$H:$H,MATCH($A2,Keys!$D:$D,0))="Y",0,IF(AND(INDEX(Keys!$G:$G,MATCH($A2,Keys!$D:$D,0))="Y",F$1<Keys!$K$2),0,1)),IF(INDEX(Keys!$E:$E,MATCH($A2,Keys!$D:$D,0))="Y",1,0)),1)) -> 0 | G2: =IF(INDEX(Keys!$F:$F,MATCH($A2,Keys!$D:$D,0))="Y",0,IF($B28=1,IF($B29=1,IF(INDEX(Keys!$H:$H,MATCH($A2,Keys!$D:$D,0))="Y",0,IF(AND(INDEX(Keys!$G:$G,MATCH($A2,Keys!$D:$D,0))="Y",G$1<Keys!$K$2),0,1)),IF(INDEX(Keys!$E:$E,MATCH($A2,Keys!$D:$D,0))="Y",1,0)),1)) -> 0 | H2: =IF(INDEX(Keys!$F:$F,MATCH($A2,Keys!$D:$D,0))="Y",0,IF($B28=1,IF($B29=1,IF(INDEX(Keys!$H:$H,MATCH($A2,Keys!$D:$D,0))="Y",0,IF(AND(INDEX(Keys!$G:$G,MATCH($A2,Keys!$D:$D,0))="Y",H$1<Keys!$K$2),0,1)),IF(INDEX(Keys!$E:$E,MATCH($A2,Keys!$D:$D,0))="Y",1,0)),1)) -> 0 | I2: =IF(INDEX(Keys!$F:$F,MATCH($A2,Keys!$D:$D,0))="Y",0,IF($B28=1,IF($B29=1,IF(INDEX(Keys!$H:$H,MATCH($A2,Keys!$D:$D,0))="Y",0,IF(AND(INDEX(Keys!$G:$G,MATCH($A2,Keys!$D:$D,0))="Y",I$1<Keys!$K$2),0,1)),IF(INDEX(Keys!$E:$E,MATCH($A2,Keys!$D:$D,0))="Y",1,0)),1)) -> 0 | ... AE2: =IF(INDEX(Keys!$F:$F,MATCH($A2,Keys!$D:$D,0))="Y",0,IF($B28=1,IF($B29=1,IF(INDEX(Keys!$H:$H,MATCH($A2,Keys!$D:$D,0))="Y",0,IF(AND(INDEX(Keys!$G:$G,MATCH($A2,Keys!$D:$D,0))="Y",AE$1<Keys!$K$2),0,1)),IF(INDEX(Keys!$E:$E,MATCH($A2,Keys!$D:$D,0))="Y",1,0)),1)) -> 0
A3: =Keys!$D3 -> coal mining 05 | B3: =IF(INDEX(Keys!$F:$F,MATCH($A3,Keys!$D:$D,0))="Y",0,IF($B28=1,IF($B29=1,IF(INDEX(Keys!$H:$H,MATCH($A3,Keys!$D:$D,0))="Y",0,IF(AND(INDEX(Keys!$G:$G,MATCH($A3,Keys!$D:$D,0))="Y",B$1<Keys!$K$2),0,1)),IF(INDEX(Keys!$E:$E,MATCH($A3,Keys!$D:$D,0))="Y",1,0)),1)) -> 1 | C3: =IF(INDEX(Keys!$F:$F,MATCH($A3,Keys!$D:$D,0))="Y",0,IF($B28=1,IF($B29=1,IF(INDEX(Keys!$H:$H,MATCH($A3,Keys!$D:$D,0))="Y",0,IF(AND(INDEX(Keys!$G:$G,MATCH($A3,Keys!$D:$D,0))="Y",C$1<Keys!$K$2),0,1)),IF(INDEX(Keys!$E:$E,MATCH($A3,Keys!$D:$D,0))="Y",1,0)),1)) -> 1 | D3: =IF(INDEX(Keys!$F:$F,MATCH($A3,Keys!$D:$D,0))="Y",0,IF($B28=1,IF($B29=1,IF(INDEX(Keys!$H:$H,MATCH($A3,Keys!$D:$D,0))="Y",0,IF(AND(INDEX(Keys!$G:$G,MATCH($A3,Keys!$D:$D,0))="Y",D$1<Keys!$K$2),0,1)),IF(INDEX(Keys!$E:$E,MATCH($A3,Keys!$D:$D,0))="Y",1,0)),1)) -> 1 | E3: =IF(INDEX(Keys!$F:$F,MATCH($A3,Keys!$D:$D,0))="Y",0,IF($B28=1,IF($B29=1,IF(INDEX(Keys!$H:$H,MATCH($A3,Keys!$D:$D,0))="Y",0,IF(AND(INDEX(Keys!$G:$G,MATCH($A3,Keys!$D:$D,0))="Y",E$1<Keys!$K$2),0,1)),IF(INDEX(Keys!$E:$E,MATCH($A3,Keys!$D:$D,0))="Y",1,0)),1)) -> 1 | F3: =IF(INDEX(Keys!$F:$F,MATCH($A3,Keys!$D:$D,0))="Y",0,IF($B28=1,IF($B29=1,IF(INDEX(Keys!$H:$H,MATCH($A3,Keys!$D:$D,0))="Y",0,IF(AND(INDEX(Keys!$G:$G,MATCH($A3,Keys!$D:$D,0))="Y",F$1<Keys!$K$2),0,1)),IF(INDEX(Keys!$E:$E,MATCH($A3,Keys!$D:$D,0))="Y",1,0)),1)) -> 1 | G3: =IF(INDEX(Keys!$F:$F,MATCH($A3,Keys!$D:$D,0))="Y",0,IF($B28=1,IF($B29=1,IF(INDEX(Keys!$H:$H,MATCH($A3,Keys!$D:$D,0))="Y",0,IF(AND(INDEX(Keys!$G:$G,MATCH($A3,Keys!$D:$D,0))="Y",G$1<Keys!$K$2),0,1)),IF(INDEX(Keys!$E:$E,MATCH($A3,Keys!$D:$D,0))="Y",1,0)),1)) -> 1 | H3: =IF(INDEX(Keys!$F:$F,MATCH($A3,Keys!$D:$D,0))="Y",0,IF($B28=1,IF($B29=1,IF(INDEX(Keys!$H:$H,MATCH($A3,Keys!$D:$D,0))="Y",0,IF(AND(INDEX(Keys!$G:$G,MATCH($A3,Keys!$D:$D,0))="Y",H$1<Keys!$K$2),0,1)),IF(INDEX(Keys!$E:$E,MATCH($A3,Keys!$D:$D,0))="Y",1,0)),1)) -> 1 | I3: =IF(INDEX(Keys!$F:$F,MATCH($A3,Keys!$D:$D,0))="Y",0,IF($B28=1,IF($B29=1,IF(INDEX(Keys!$H:$H,MATCH($A3,Keys!$D:$D,0))="Y",0,IF(AND(INDEX(Keys!$G:$G,MATCH($A3,Keys!$D:$D,0))="Y",I$1<Keys!$K$2),0,1)),IF(INDEX(Keys!$E:$E,MATCH($A3,Keys!$D:$D,0))="Y",1,0)),1)) -> 1 | ... AE3: =IF(INDEX(Keys!$F:$F,MATCH($A3,Keys!$D:$D,0))="Y",0,IF($B28=1,IF($B29=1,IF(INDEX(Keys!$H:$H,MATCH($A3,Keys!$D:$D,0))="Y",0,IF(AND(INDEX(Keys!$G:$G,MATCH($A3,Keys!$D:$D,0))="Y",AE$1<Keys!$K$2),0,1)),IF(INDEX(Keys!$E:$E,MATCH($A3,Keys!$D:$D,0))="Y",1,0)),1)) -> 1
A4: =Keys!$D4 -> oil and gas extraction 06 | B4: =IF(INDEX(Keys!$F:$F,MATCH($A4,Keys!$D:$D,0))="Y",0,IF($B28=1,IF($B29=1,IF(INDEX(Keys!$H:$H,MATCH($A4,Keys!$D:$D,0))="Y",0,IF(AND(INDEX(Keys!$G:$G,MATCH($A4,Keys!$D:$D,0))="Y",B$1<Keys!$K$2),0,1)),IF(INDEX(Keys!$E:$E,MATCH($A4,Keys!$D:$D,0))="Y",1,0)),1)) -> 1 | C4: =IF(INDEX(Keys!$F:$F,MATCH($A4,Keys!$D:$D,0))="Y",0,IF($B28=1,IF($B29=1,IF(INDEX(Keys!$H:$H,MATCH($A4,Keys!$D:$D,0))="Y",0,IF(AND(INDEX(Keys!$G:$G,MATCH($A4,Keys!$D:$D,0))="Y",C$1<Keys!$K$2),0,1)),IF(INDEX(Keys!$E:$E,MATCH($A4,Keys!$D:$D,0))="Y",1,0)),1)) -> 1 | D4: =IF(INDEX(Keys!$F:$F,MATCH($A4,Keys!$D:$D,0))="Y",0,IF($B28=1,IF($B29=1,IF(INDEX(Keys!$H:$H,MATCH($A4,Keys!$D:$D,0))="Y",0,IF(AND(INDEX(Keys!$G:$G,MATCH($A4,Keys!$D:$D,0))="Y",D$1<Keys!$K$2),0,1)),IF(INDEX(Keys!$E:$E,MATCH($A4,Keys!$D:$D,0))="Y",1,0)),1)) -> 1 | E4: =IF(INDEX(Keys!$F:$F,MATCH($A4,Keys!$D:$D,0))="Y",0,IF($B28=1,IF($B29=1,IF(INDEX(Keys!$H:$H,MATCH($A4,Keys!$D:$D,0))="Y",0,IF(AND(INDEX(Keys!$G:$G,MATCH($A4,Keys!$D:$D,0))="Y",E$1<Keys!$K$2),0,1)),IF(INDEX(Keys!$E:$E,MATCH($A4,Keys!$D:$D,0))="Y",1,0)),1)) -> 1 | F4: =IF(INDEX(Keys!$F:$F,MATCH($A4,Keys!$D:$D,0))="Y",0,IF($B28=1,IF($B29=1,IF(INDEX(Keys!$H:$H,MATCH($A4,Keys!$D:$D,0))="Y",0,IF(AND(INDEX(Keys!$G:$G,MATCH($A4,Keys!$D:$D,0))="Y",F$1<Keys!$K$2),0,1)),IF(INDEX(Keys!$E:$E,MATCH($A4,Keys!$D:$D,0))="Y",1,0)),1)) -> 1 | G4: =IF(INDEX(Keys!$F:$F,MATCH($A4,Keys!$D:$D,0))="Y",0,IF($B28=1,IF($B29=1,IF(INDEX(Keys!$H:$H,MATCH($A4,Keys!$D:$D,0))="Y",0,IF(AND(INDEX(Keys!$G:$G,MATCH($A4,Keys!$D:$D,0))="Y",G$1<Keys!$K$2),0,1)),IF(INDEX(Keys!$E:$E,MATCH($A4,Keys!$D:$D,0))="Y",1,0)),1)) -> 1 | H4: =IF(INDEX(Keys!$F:$F,MATCH($A4,Keys!$D:$D,0))="Y",0,IF($B28=1,IF($B29=1,IF(INDEX(Keys!$H:$H,MATCH($A4,Keys!$D:$D,0))="Y",0,IF(AND(INDEX(Keys!$G:$G,MATCH($A4,Keys!$D:$D,0))="Y",H$1<Keys!$K$2),0,1)),IF(INDEX(Keys!$E:$E,MATCH($A4,Keys!$D:$D,0))="Y",1,0)),1)) -> 1 | I4: =IF(INDEX(Keys!$F:$F,MATCH($A4,Keys!$D:$D,0))="Y",0,IF($B28=1,IF($B29=1,IF(INDEX(Keys!$H:$H,MATCH($A4,Keys!$D:$D,0))="Y",0,IF(AND(INDEX(Keys!$G:$G,MATCH($A4,Keys!$D:$D,0))="Y",I$1<Keys!$K$2),0,1)),IF(INDEX(Keys!$E:$E,MATCH($A4,Keys!$D:$D,0))="Y",1,0)),1)) -> 1 | ... AE4: =IF(INDEX(Keys!$F:$F,MATCH($A4,Keys!$D:$D,0))="Y",0,IF($B28=1,IF($B29=1,IF(INDEX(Keys!$H:$H,MATCH($A4,Keys!$D:$D,0))="Y",0,IF(AND(INDEX(Keys!$G:$G,MATCH($A4,Keys!$D:$D,0))="Y",AE$1<Keys!$K$2),0,1)),IF(INDEX(Keys!$E:$E,MATCH($A4,Keys!$D:$D,0))="Y",1,0)),1)) -> 1
A5: =Keys!$D5 -> other mining and quarrying 07T08 | B5: =IF(INDEX(Keys!$F:$F,MATCH($A5,Keys!$D:$D,0))="Y",0,IF($B28=1,IF($B29=1,IF(INDEX(Keys!$H:$H,MATCH($A5,Keys!$D:$D,0))="Y",0,IF(AND(INDEX(Keys!$G:$G,MATCH($A5,Keys!$D:$D,0))="Y",B$1<Keys!$K$2),0,1)),IF(INDEX(Keys!$E:$E,MATCH($A5,Keys!$D:$D,0))="Y",1,0)),1)) -> 1 | C5: =IF(INDEX(Keys!$F:$F,MATCH($A5,Keys!$D:$D,0))="Y",0,IF($B28=1,IF($B29=1,IF(INDEX(Keys!$H:$H,MATCH($A5,Keys!$D:$D,0))="Y",0,IF(AND(INDEX(Keys!$G:$G,MATCH($A5,Keys!$D:$D,0))="Y",C$1<Keys!$K$2),0,1)),IF(INDEX(Keys!$E:$E,MATCH($A5,Keys!$D:$D,0))="Y",1,0)),1)) -> 1 | D5: =IF(INDEX(Keys!$F:$F,MATCH($A5,Keys!$D:$D,0))="Y",0,IF($B28=1,IF($B29=1,IF(INDEX(Keys!$H:$H,MATCH($A5,Keys!$D:$D,0))="Y",0,IF(AND(INDEX(Keys!$G:$G,MATCH($A5,Keys!$D:$D,0))="Y",D$1<Keys!$K$2),0,1)),IF(INDEX(Keys!$E:$E,MATCH($A5,Keys!$D:$D,0))="Y",1,0)),1)) -> 1 | E5: =IF(INDEX(Keys!$F:$F,MATCH($A5,Keys!$D:$D,0))="Y",0,IF($B28=1,IF($B29=1,IF(INDEX(Keys!$H:$H,MATCH($A5,Keys!$D:$D,0))="Y",0,IF(AND(INDEX(Keys!$G:$G,MATCH($A5,Keys!$D:$D,0))="Y",E$1<Keys!$K$2),0,1)),IF(INDEX(Keys!$E:$E,MATCH($A5,Keys!$D:$D,0))="Y",1,0)),1)) -> 1 | F5: =IF(INDEX(Keys!$F:$F,MATCH($A5,Keys!$D:$D,0))="Y",0,IF($B28=1,IF($B29=1,IF(INDEX(Keys!$H:$H,MATCH($A5,Keys!$D:$D,0))="Y",0,IF(AND(INDEX(Keys!$G:$G,MATCH($A5,Keys!$D:$D,0))="Y",F$1<Keys!$K$2),0,1)),IF(INDEX(Keys!$E:$E,MATCH($A5,Keys!$D:$D,0))="Y",1,0)),1)) -> 1 | G5: =IF(INDEX(Keys!$F:$F,MATCH($A5,Keys!$D:$D,0))="Y",0,IF($B28=1,IF($B29=1,IF(INDEX(Keys!$H:$H,MATCH($A5,Keys!$D:$D,0))="Y",0,IF(AND(INDEX(Keys!$G:$G,MATCH($A5,Keys!$D:$D,0))="Y",G$1<Keys!$K$2),0,1)),IF(INDEX(Keys!$E:$E,MATCH($A5,Keys!$D:$D,0))="Y",1,0)),1)) -> 1 | H5: =IF(INDEX(Keys!$F:$F,MATCH($A5,Keys!$D:$D,0))="Y",0,IF($B28=1,IF($B29=1,IF(INDEX(Keys!$H:$H,MATCH($A5,Keys!$D:$D,0))="Y",0,IF(AND(INDEX(Keys!$G:$G,MATCH($A5,Keys!$D:$D,0))="Y",H$1<Keys!$K$2),0,1)),IF(INDEX(Keys!$E:$E,MATCH($A5,Keys!$D:$D,0))="Y",1,0)),1)) -> 1 | I5: =IF(INDEX(Keys!$F:$F,MATCH($A5,Keys!$D:$D,0))="Y",0,IF($B28=1,IF($B29=1,IF(INDEX(Keys!$H:$H,MATCH($A5,Keys!$D:$D,0))="Y",0,IF(AND(INDEX(Keys!$G:$G,MATCH($A5,Keys!$D:$D,0))="Y",I$1<Keys!$K$2),0,1)),IF(INDEX(Keys!$E:$E,MATCH($A5,Keys!$D:$D,0))="Y",1,0)),1)) -> 1 | ... AE5: =IF(INDEX(Keys!$F:$F,MATCH($A5,Keys!$D:$D,0))="Y",0,IF($B28=1,IF($B29=1,IF(INDEX(Keys!$H:$H,MATCH($A5,Keys!$D:$D,0))="Y",0,IF(AND(INDEX(Keys!$G:$G,MATCH($A5,Keys!$D:$D,0))="Y",AE$1<Keys!$K$2),0,1)),IF(INDEX(Keys!$E:$E,MATCH($A5,Keys!$D:$D,0))="Y",1,0)),1)) -> 1
A6: =Keys!$D6 -> food beverage and tobacco 10T12 | B6: =IF(INDEX(Keys!$F:$F,MATCH($A6,Keys!$D:$D,0))="Y",0,IF($B28=1,IF($B29=1,IF(INDEX(Keys!$H:$H,MATCH($A6,Keys!$D:$D,0))="Y",0,IF(AND(INDEX(Keys!$G:$G,MATCH($A6,Keys!$D:$D,0))="Y",B$1<Keys!$K$2),0,1)),IF(INDEX(Keys!$E:$E,MATCH($A6,Keys!$D:$D,0))="Y",1,0)),1)) -> 1 | C6: =IF(INDEX(Keys!$F:$F,MATCH($A6,Keys!$D:$D,0))="Y",0,IF($B28=1,IF($B29=1,IF(INDEX(Keys!$H:$H,MATCH($A6,Keys!$D:$D,0))="Y",0,IF(AND(INDEX(Keys!$G:$G,MATCH($A6,Keys!$D:$D,0))="Y",C$1<Keys!$K$2),0,1)),IF(INDEX(Keys!$E:$E,MATCH($A6,Keys!$D:$D,0))="Y",1,0)),1)) -> 1 | D6: =IF(INDEX(Keys!$F:$F,MATCH($A6,Keys!$D:$D,0))="Y",0,IF($B28=1,IF($B29=1,IF(INDEX(Keys!$H:$H,MATCH($A6,Keys!$D:$D,0))="Y",0,IF(AND(INDEX(Keys!$G:$G,MATCH($A6,Keys!$D:$D,0))="Y",D$1<Keys!$K$2),0,1)),IF(INDEX(Keys!$E:$E,MATCH($A6,Keys!$D:$D,0))="Y",1,0)),1)) -> 1 | E6: =IF(INDEX(Keys!$F:$F,MATCH($A6,Keys!$D:$D,0))="Y",0,IF($B28=1,IF($B29=1,IF(INDEX(Keys!$H:$H,MATCH($A6,Keys!$D:$D,0))="Y",0,IF(AND(INDEX(Keys!$G:$G,MATCH($A6,Keys!$D:$D,0))="Y",E$1<Keys!$K$2),0,1)),IF(INDEX(Keys!$E:$E,MATCH($A6,Keys!$D:$D,0))="Y",1,0)),1)) -> 1 | F6: =IF(INDEX(Keys!$F:$F,MATCH($A6,Keys!$D:$D,0))="Y",0,IF($B28=1,IF($B29=1,IF(INDEX(Keys!$H:$H,MATCH($A6,Keys!$D:$D,0))="Y",0,IF(AND(INDEX(Keys!$G:$G,MATCH($A6,Keys!$D:$D,0))="Y",F$1<Keys!$K$2),0,1)),IF(INDEX(Keys!$E:$E,MATCH($A6,Keys!$D:$D,0))="Y",1,0)),1)) -> 1 | G6: =IF(INDEX(Keys!$F:$F,MATCH($A6,Keys!$D:$D,0))="Y",0,IF($B28=1,IF($B29=1,IF(INDEX(Keys!$H:$H,MATCH($A6,Keys!$D:$D,0))="Y",0,IF(AND(INDEX(Keys!$G:$G,MATCH($A6,Keys!$D:$D,0))="Y",G$1<Keys!$K$2),0,1)),IF(INDEX(Keys!$E:$E,MATCH($A6,Keys!$D:$D,0))="Y",1,0)),1)) -> 1 | H6: =IF(INDEX(Keys!$F:$F,MATCH($A6,Keys!$D:$D,0))="Y",0,IF($B28=1,IF($B29=1,IF(INDEX(Keys!$H:$H,MATCH($A6,Keys!$D:$D,0))="Y",0,IF(AND(INDEX(Keys!$G:$G,MATCH($A6,Keys!$D:$D,0))="Y",H$1<Keys!$K$2),0,1)),IF(INDEX(Keys!$E:$E,MATCH($A6,Keys!$D:$D,0))="Y",1,0)),1)) -> 1 | I6: =IF(INDEX(Keys!$F:$F,MATCH($A6,Keys!$D:$D,0))="Y",0,IF($B28=1,IF($B29=1,IF(INDEX(Keys!$H:$H,MATCH($A6,Keys!$D:$D,0))="Y",0,IF(AND(INDEX(Keys!$G:$G,MATCH($A6,Keys!$D:$D,0))="Y",I$1<Keys!$K$2),0,1)),IF(INDEX(Keys!$E:$E,MATCH($A6,Keys!$D:$D,0))="Y",1,0)),1)) -> 1 | ... AE6: =IF(INDEX(Keys!$F:$F,MATCH($A6,Keys!$D:$D,0))="Y",0,IF($B28=1,IF($B29=1,IF(INDEX(Keys!$H:$H,MATCH($A6,Keys!$D:$D,0))="Y",0,IF(AND(INDEX(Keys!$G:$G,MATCH($A6,Keys!$D:$D,0))="Y",AE$1<Keys!$K$2),0,1)),IF(INDEX(Keys!$E:$E,MATCH($A6,Keys!$D:$D,0))="Y",1,0)),1)) -> 1
A7: =Keys!$D7 -> textiles apparel and leather 13T15 | B7: =IF(INDEX(Keys!$F:$F,MATCH($A7,Keys!$D:$D,0))="Y",0,IF($B28=1,IF($B29=1,IF(INDEX(Keys!$H:$H,MATCH($A7,Keys!$D:$D,0))="Y",0,IF(AND(INDEX(Keys!$G:$G,MATCH($A7,Keys!$D:$D,0))="Y",B$1<Keys!$K$2),0,1)),IF(INDEX(Keys!$E:$E,MATCH($A7,Keys!$D:$D,0))="Y",1,0)),1)) -> 1 | C7: =IF(INDEX(Keys!$F:$F,MATCH($A7,Keys!$D:$D,0))="Y",0,IF($B28=1,IF($B29=1,IF(INDEX(Keys!$H:$H,MATCH($A7,Keys!$D:$D,0))="Y",0,IF(AND(INDEX(Keys!$G:$G,MATCH($A7,Keys!$D:$D,0))="Y",C$1<Keys!$K$2),0,1)),IF(INDEX(Keys!$E:$E,MATCH($A7,Keys!$D:$D,0))="Y",1,0)),1)) -> 1 | D7: =IF(INDEX(Keys!$F:$F,MATCH($A7,Keys!$D:$D,0))="Y",0,IF($B28=1,IF($B29=1,IF(INDEX(Keys!$H:$H,MATCH($A7,Keys!$D:$D,0))="Y",0,IF(AND(INDEX(Keys!$G:$G,MATCH($A7,Keys!$D:$D,0))="Y",D$1<Keys!$K$2),0,1)),IF(INDEX(Keys!$E:$E,MATCH($A7,Keys!$D:$D,0))="Y",1,0)),1)) -> 1 | E7: =IF(INDEX(Keys!$F:$F,MATCH($A7,Keys!$D:$D,0))="Y",0,IF($B28=1,IF($B29=1,IF(INDEX(Keys!$H:$H,MATCH($A7,Keys!$D:$D,0))="Y",0,IF(AND(INDEX(Keys!$G:$G,MATCH($A7,Keys!$D:$D,0))="Y",E$1<Keys!$K$2),0,1)),IF(INDEX(Keys!$E:$E,MATCH($A7,Keys!$D:$D,0))="Y",1,0)),1)) -> 1 | F7: =IF(INDEX(Keys!$F:$F,MATCH($A7,Keys!$D:$D,0))="Y",0,IF($B28=1,IF($B29=1,IF(INDEX(Keys!$H:$H,MATCH($A7,Keys!$D:$D,0))="Y",0,IF(AND(INDEX(Keys!$G:$G,MATCH($A7,Keys!$D:$D,0))="Y",F$1<Keys!$K$2),0,1)),IF(INDEX(Keys!$E:$E,MATCH($A7,Keys!$D:$D,0))="Y",1,0)),1)) -> 1 | G7: =IF(INDEX(Keys!$F:$F,MATCH($A7,Keys!$D:$D,0))="Y",0,IF($B28=1,IF($B29=1,IF(INDEX(Keys!$H:$H,MATCH($A7,Keys!$D:$D,0))="Y",0,IF(AND(INDEX(Keys!$G:$G,MATCH($A7,Keys!$D:$D,0))="Y",G$1<Keys!$K$2),0,1)),IF(INDEX(Keys!$E:$E,MATCH($A7,Keys!$D:$D,0))="Y",1,0)),1)) -> 1 | H7: =IF(INDEX(Keys!$F:$F,MATCH($A7,Keys!$D:$D,0))="Y",0,IF($B28=1,IF($B29=1,IF(INDEX(Keys!$H:$H,MATCH($A7,Keys!$D:$D,0))="Y",0,IF(AND(INDEX(Keys!$G:$G,MATCH($A7,Keys!$D:$D,0))="Y",H$1<Keys!$K$2),0,1)),IF(INDEX(Keys!$E:$E,MATCH($A7,Keys!$D:$D,0))="Y",1,0)),1)) -> 1 | I7: =IF(INDEX(Keys!$F:$F,MATCH($A7,Keys!$D:$D,0))="Y",0,IF($B28=1,IF($B29=1,IF(INDEX(Keys!$H:$H,MATCH($A7,Keys!$D:$D,0))="Y",0,IF(AND(INDEX(Keys!$G:$G,MATCH($A7,Keys!$D:$D,0))="Y",I$1<Keys!$K$2),0,1)),IF(INDEX(Keys!$E:$E,MATCH($A7,Keys!$D:$D,0))="Y",1,0)),1)) -> 1 | ... AE7: =IF(INDEX(Keys!$F:$F,MATCH($A7,Keys!$D:$D,0))="Y",0,IF($B28=1,IF($B29=1,IF(INDEX(Keys!$H:$H,MATCH($A7,Keys!$D:$D,0))="Y",0,IF(AND(INDEX(Keys!$G:$G,MATCH($A7,Keys!$D:$D,0))="Y",AE$1<Keys!$K$2),0,1)),IF(INDEX(Keys!$E:$E,MATCH($A7,Keys!$D:$D,0))="Y",1,0)),1)) -> 1
A8: =Keys!$D8 -> wood products 16 | B8: =IF(INDEX(Keys!$F:$F,MATCH($A8,Keys!$D:$D,0))="Y",0,IF($B28=1,IF($B29=1,IF(INDEX(Keys!$H:$H,MATCH($A8,Keys!$D:$D,0))="Y",0,IF(AND(INDEX(Keys!$G:$G,MATCH($A8,Keys!$D:$D,0))="Y",B$1<Keys!$K$2),0,1)),IF(INDEX(Keys!$E:$E,MATCH($A8,Keys!$D:$D,0))="Y",1,0)),1)) -> 1 | C8: =IF(INDEX(Keys!$F:$F,MATCH($A8,Keys!$D:$D,0))="Y",0,IF($B28=1,IF($B29=1,IF(INDEX(Keys!$H:$H,MATCH($A8,Keys!$D:$D,0))="Y",0,IF(AND(INDEX(Keys!$G:$G,MATCH($A8,Keys!$D:$D,0))="Y",C$1<Keys!$K$2),0,1)),IF(INDEX(Keys!$E:$E,MATCH($A8,Keys!$D:$D,0))="Y",1,0)),1)) -> 1 | D8: =IF(INDEX(Keys!$F:$F,MATCH($A8,Keys!$D:$D,0))="Y",0,IF($B28=1,IF($B29=1,IF(INDEX(Keys!$H:$H,MATCH($A8,Keys!$D:$D,0))="Y",0,IF(AND(INDEX(Keys!$G:$G,MATCH($A8,Keys!$D:$D,0))="Y",D$1<Keys!$K$2),0,1)),IF(INDEX(Keys!$E:$E,MATCH($A8,Keys!$D:$D,0))="Y",1,0)),1)) -> 1 | E8: =IF(INDEX(Keys!$F:$F,MATCH($A8,Keys!$D:$D,0))="Y",0,IF($B28=1,IF($B29=1,IF(INDEX(Keys!$H:$H,MATCH($A8,Keys!$D:$D,0))="Y",0,IF(AND(INDEX(Keys!$G:$G,MATCH($A8,Keys!$D:$D,0))="Y",E$1<Keys!$K$2),0,1)),IF(INDEX(Keys!$E:$E,MATCH($A8,Keys!$D:$D,0))="Y",1,0)),1)) -> 1 | F8: =IF(INDEX(Keys!$F:$F,MATCH($A8,Keys!$D:$D,0))="Y",0,IF($B28=1,IF($B29=1,IF(INDEX(Keys!$H:$H,MATCH($A8,Keys!$D:$D,0))="Y",0,IF(AND(INDEX(Keys!$G:$G,MATCH($A8,Keys!$D:$D,0))="Y",F$1<Keys!$K$2),0,1)),IF(INDEX(Keys!$E:$E,MATCH($A8,Keys!$D:$D,0))="Y",1,0)),1)) -> 1 | G8: =IF(INDEX(Keys!$F:$F,MATCH($A8,Keys!$D:$D,0))="Y",0,IF($B28=1,IF($B29=1,IF(INDEX(Keys!$H:$H,MATCH($A8,Keys!$D:$D,0))="Y",0,IF(AND(INDEX(Keys!$G:$G,MATCH($A8,Keys!$D:$D,0))="Y",G$1<Keys!$K$2),0,1)),IF(INDEX(Keys!$E:$E,MATCH($A8,Keys!$D:$D,0))="Y",1,0)),1)) -> 1 | H8: =IF(INDEX(Keys!$F:$F,MATCH($A8,Keys!$D:$D,0))="Y",0,IF($B28=1,IF($B29=1,IF(INDEX(Keys!$H:$H,MATCH($A8,Keys!$D:$D,0))="Y",0,IF(AND(INDEX(Keys!$G:$G,MATCH($A8,Keys!$D:$D,0))="Y",H$1<Keys!$K$2),0,1)),IF(INDEX(Keys!$E:$E,MATCH($A8,Keys!$D:$D,0))="Y",1,0)),1)) -> 1 | I8: =IF(INDEX(Keys!$F:$F,MATCH($A8,Keys!$D:$D,0))="Y",0,IF($B28=1,IF($B29=1,IF(INDEX(Keys!$H:$H,MATCH($A8,Keys!$D:$D,0))="Y",0,IF(AND(INDEX(Keys!$G:$G,MATCH($A8,Keys!$D:$D,0))="Y",I$1<Keys!$K$2),0,1)),IF(INDEX(Keys!$E:$E,MATCH($A8,Keys!$D:$D,0))="Y",1,0)),1)) -> 1 | ... AE8: =IF(INDEX(Keys!$F:$F,MATCH($A8,Keys!$D:$D,0))="Y",0,IF($B28=1,IF($B29=1,IF(INDEX(Keys!$H:$H,MATCH($A8,Keys!$D:$D,0))="Y",0,IF(AND(INDEX(Keys!$G:$G,MATCH($A8,Keys!$D:$D,0))="Y",AE$1<Keys!$K$2),0,1)),IF(INDEX(Keys!$E:$E,MATCH($A8,Keys!$D:$D,0))="Y",1,0)),1)) -> 1
A9: =Keys!$D9 -> pulp paper and printing 17T18 | B9: =IF(INDEX(Keys!$F:$F,MATCH($A9,Keys!$D:$D,0))="Y",0,IF($B28=1,IF($B29=1,IF(INDEX(Keys!$H:$H,MATCH($A9,Keys!$D:$D,0))="Y",0,IF(AND(INDEX(Keys!$G:$G,MATCH($A9,Keys!$D:$D,0))="Y",B$1<Keys!$K$2),0,1)),IF(INDEX(Keys!$E:$E,MATCH($A9,Keys!$D:$D,0))="Y",1,0)),1)) -> 1 | C9: =IF(INDEX(Keys!$F:$F,MATCH($A9,Keys!$D:$D,0))="Y",0,IF($B28=1,IF($B29=1,IF(INDEX(Keys!$H:$H,MATCH($A9,Keys!$D:$D,0))="Y",0,IF(AND(INDEX(Keys!$G:$G,MATCH($A9,Keys!$D:$D,0))="Y",C$1<Keys!$K$2),0,1)),IF(INDEX(Keys!$E:$E,MATCH($A9,Keys!$D:$D,0))="Y",1,0)),1)) -> 1 | D9: =IF(INDEX(Keys!$F:$F,MATCH($A9,Keys!$D:$D,0))="Y",0,IF($B28=1,IF($B29=1,IF(INDEX(Keys!$H:$H,MATCH($A9,Keys!$D:$D,0))="Y",0,IF(AND(INDEX(Keys!$G:$G,MATCH($A9,Keys!$D:$D,0))="Y",D$1<Keys!$K$2),0,1)),IF(INDEX(Keys!$E:$E,MATCH($A9,Keys!$D:$D,0))="Y",1,0)),1)) -> 1 | E9: =IF(INDEX(Keys!$F:$F,MATCH($A9,Keys!$D:$D,0))="Y",0,IF($B28=1,IF($B29=1,IF(INDEX(Keys!$H:$H,MATCH($A9,Keys!$D:$D,0))="Y",0,IF(AND(INDEX(Keys!$G:$G,MATCH($A9,Keys!$D:$D,0))="Y",E$1<Keys!$K$2),0,1)),IF(INDEX(Keys!$E:$E,MATCH($A9,Keys!$D:$D,0))="Y",1,0)),1)) -> 1 | F9: =IF(INDEX(Keys!$F:$F,MATCH($A9,Keys!$D:$D,0))="Y",0,IF($B28=1,IF($B29=1,IF(INDEX(Keys!$H:$H,MATCH($A9,Keys!$D:$D,0))="Y",0,IF(AND(INDEX(Keys!$G:$G,MATCH($A9,Keys!$D:$D,0))="Y",F$1<Keys!$K$2),0,1)),IF(INDEX(Keys!$E:$E,MATCH($A9,Keys!$D:$D,0))="Y",1,0)),1)) -> 1 | G9: =IF(INDEX(Keys!$F:$F,MATCH($A9,Keys!$D:$D,0))="Y",0,IF($B28=1,IF($B29=1,IF(INDEX(Keys!$H:$H,MATCH($A9,Keys!$D:$D,0))="Y",0,IF(AND(INDEX(Keys!$G:$G,MATCH($A9,Keys!$D:$D,0))="Y",G$1<Keys!$K$2),0,1)),IF(INDEX(Keys!$E:$E,MATCH($A9,Keys!$D:$D,0))="Y",1,0)),1)) -> 1 | H9: =IF(INDEX(Keys!$F:$F,MATCH($A9,Keys!$D:$D,0))="Y",0,IF($B28=1,IF($B29=1,IF(INDEX(Keys!$H:$H,MATCH($A9,Keys!$D:$D,0))="Y",0,IF(AND(INDEX(Keys!$G:$G,MATCH($A9,Keys!$D:$D,0))="Y",H$1<Keys!$K$2),0,1)),IF(INDEX(Keys!$E:$E,MATCH($A9,Keys!$D:$D,0))="Y",1,0)),1)) -> 1 | I9: =IF(INDEX(Keys!$F:$F,MATCH($A9,Keys!$D:$D,0))="Y",0,IF($B28=1,IF($B29=1,IF(INDEX(Keys!$H:$H,MATCH($A9,Keys!$D:$D,0))="Y",0,IF(AND(INDEX(Keys!$G:$G,MATCH($A9,Keys!$D:$D,0))="Y",I$1<Keys!$K$2),0,1)),IF(INDEX(Keys!$E:$E,MATCH($A9,Keys!$D:$D,0))="Y",1,0)),1)) -> 1 | ... AE9: =IF(INDEX(Keys!$F:$F,MATCH($A9,Keys!$D:$D,0))="Y",0,IF($B28=1,IF($B29=1,IF(INDEX(Keys!$H:$H,MATCH($A9,Keys!$D:$D,0))="Y",0,IF(AND(INDEX(Keys!$G:$G,MATCH($A9,Keys!$D:$D,0))="Y",AE$1<Keys!$K$2),0,1)),IF(INDEX(Keys!$E:$E,MATCH($A9,Keys!$D:$D,0))="Y",1,0)),1)) -> 1
A10: =Keys!$D10 -> refined petroleum and coke 19 | B10: =IF(INDEX(Keys!$F:$F,MATCH($A10,Keys!$D:$D,0))="Y",0,IF($B28=1,IF($B29=1,IF(INDEX(Keys!$H:$H,MATCH($A10,Keys!$D:$D,0))="Y",0,IF(AND(INDEX(Keys!$G:$G,MATCH($A10,Keys!$D:$D,0))="Y",B$1<Keys!$K$2),0,1)),IF(INDEX(Keys!$E:$E,MATCH($A10,Keys!$D:$D,0))="Y",1,0)),1)) -> 1 | C10: =IF(INDEX(Keys!$F:$F,MATCH($A10,Keys!$D:$D,0))="Y",0,IF($B28=1,IF($B29=1,IF(INDEX(Keys!$H:$H,MATCH($A10,Keys!$D:$D,0))="Y",0,IF(AND(INDEX(Keys!$G:$G,MATCH($A10,Keys!$D:$D,0))="Y",C$1<Keys!$K$2),0,1)),IF(INDEX(Keys!$E:$E,MATCH($A10,Keys!$D:$D,0))="Y",1,0)),1)) -> 1 | D10: =IF(INDEX(Keys!$F:$F,MATCH($A10,Keys!$D:$D,0))="Y",0,IF($B28=1,IF($B29=1,IF(INDEX(Keys!$H:$H,MATCH($A10,Keys!$D:$D,0))="Y",0,IF(AND(INDEX(Keys!$G:$G,MATCH($A10,Keys!$D:$D,0))="Y",D$1<Keys!$K$2),0,1)),IF(INDEX(Keys!$E:$E,MATCH($A10,Keys!$D:$D,0))="Y",1,0)),1)) -> 1 | E10: =IF(INDEX(Keys!$F:$F,MATCH($A10,Keys!$D:$D,0))="Y",0,IF($B28=1,IF($B29=1,IF(INDEX(Keys!$H:$H,MATCH($A10,Keys!$D:$D,0))="Y",0,IF(AND(INDEX(Keys!$G:$G,MATCH($A10,Keys!$D:$D,0))="Y",E$1<Keys!$K$2),0,1)),IF(INDEX(Keys!$E:$E,MATCH($A10,Keys!$D:$D,0))="Y",1,0)),1)) -> 1 | F10: =IF(INDEX(Keys!$F:$F,MATCH($A10,Keys!$D:$D,0))="Y",0,IF($B28=1,IF($B29=1,IF(INDEX(Keys!$H:$H,MATCH($A10,Keys!$D:$D,0))="Y",0,IF(AND(INDEX(Keys!$G:$G,MATCH($A10,Keys!$D:$D,0))="Y",F$1<Keys!$K$2),0,1)),IF(INDEX(Keys!$E:$E,MATCH($A10,Keys!$D:$D,0))="Y",1,0)),1)) -> 1 | G10: =IF(INDEX(Keys!$F:$F,MATCH($A10,Keys!$D:$D,0))="Y",0,IF($B28=1,IF($B29=1,IF(INDEX(Keys!$H:$H,MATCH($A10,Keys!$D:$D,0))="Y",0,IF(AND(INDEX(Keys!$G:$G,MATCH($A10,Keys!$D:$D,0))="Y",G$1<Keys!$K$2),0,1)),IF(INDEX(Keys!$E:$E,MATCH($A10,Keys!$D:$D,0))="Y",1,0)),1)) -> 1 | H10: =IF(INDEX(Keys!$F:$F,MATCH($A10,Keys!$D:$D,0))="Y",0,IF($B28=1,IF($B29=1,IF(INDEX(Keys!$H:$H,MATCH($A10,Keys!$D:$D,0))="Y",0,IF(AND(INDEX(Keys!$G:$G,MATCH($A10,Keys!$D:$D,0))="Y",H$1<Keys!$K$2),0,1)),IF(INDEX(Keys!$E:$E,MATCH($A10,Keys!$D:$D,0))="Y",1,0)),1)) -> 1 | I10: =IF(INDEX(Keys!$F:$F,MATCH($A10,Keys!$D:$D,0))="Y",0,IF($B28=1,IF($B29=1,IF(INDEX(Keys!$H:$H,MATCH($A10,Keys!$D:$D,0))="Y",0,IF(AND(INDEX(Keys!$G:$G,MATCH($A10,Keys!$D:$D,0))="Y",I$1<Keys!$K$2),0,1)),IF(INDEX(Keys!$E:$E,MATCH($A10,Keys!$D:$D,0))="Y",1,0)),1)) -> 1 | ... AE10: =IF(INDEX(Keys!$F:$F,MATCH($A10,Keys!$D:$D,0))="Y",0,IF($B28=1,IF($B29=1,IF(INDEX(Keys!$H:$H,MATCH($A10,Keys!$D:$D,0))="Y",0,IF(AND(INDEX(Keys!$G:$G,MATCH($A10,Keys!$D:$D,0))="Y",AE$1<Keys!$K$2),0,1)),IF(INDEX(Keys!$E:$E,MATCH($A10,Keys!$D:$D,0))="Y",1,0)),1)) -> 1
A11: =Keys!$D11 -> chemicals 20 | B11: =IF(INDEX(Keys!$F:$F,MATCH($A11,Keys!$D:$D,0))="Y",0,IF($B28=1,IF($B29=1,IF(INDEX(Keys!$H:$H,MATCH($A11,Keys!$D:$D,0))="Y",0,IF(AND(INDEX(Keys!$G:$G,MATCH($A11,Keys!$D:$D,0))="Y",B$1<Keys!$K$2),0,1)),IF(INDEX(Keys!$E:$E,MATCH($A11,Keys!$D:$D,0))="Y",1,0)),1)) -> 1 | C11: =IF(INDEX(Keys!$F:$F,MATCH($A11,Keys!$D:$D,0))="Y",0,IF($B28=1,IF($B29=1,IF(INDEX(Keys!$H:$H,MATCH($A11,Keys!$D:$D,0))="Y",0,IF(AND(INDEX(Keys!$G:$G,MATCH($A11,Keys!$D:$D,0))="Y",C$1<Keys!$K$2),0,1)),IF(INDEX(Keys!$E:$E,MATCH($A11,Keys!$D:$D,0))="Y",1,0)),1)) -> 1 | D11: =IF(INDEX(Keys!$F:$F,MATCH($A11,Keys!$D:$D,0))="Y",0,IF($B28=1,IF($B29=1,IF(INDEX(Keys!$H:$H,MATCH($A11,Keys!$D:$D,0))="Y",0,IF(AND(INDEX(Keys!$G:$G,MATCH($A11,Keys!$D:$D,0))="Y",D$1<Keys!$K$2),0,1)),IF(INDEX(Keys!$E:$E,MATCH($A11,Keys!$D:$D,0))="Y",1,0)),1)) -> 1 | E11: =IF(INDEX(Keys!$F:$F,MATCH($A11,Keys!$D:$D,0))="Y",0,IF($B28=1,IF($B29=1,IF(INDEX(Keys!$H:$H,MATCH($A11,Keys!$D:$D,0))="Y",0,IF(AND(INDEX(Keys!$G:$G,MATCH($A11,Keys!$D:$D,0))="Y",E$1<Keys!$K$2),0,1)),IF(INDEX(Keys!$E:$E,MATCH($A11,Keys!$D:$D,0))="Y",1,0)),1)) -> 1 | F11: =IF(INDEX(Keys!$F:$F,MATCH($A11,Keys!$D:$D,0))="Y",0,IF($B28=1,IF($B29=1,IF(INDEX(Keys!$H:$H,MATCH($A11,Keys!$D:$D,0))="Y",0,IF(AND(INDEX(Keys!$G:$G,MATCH($A11,Keys!$D:$D,0))="Y",F$1<Keys!$K$2),0,1)),IF(INDEX(Keys!$E:$E,MATCH($A11,Keys!$D:$D,0))="Y",1,0)),1)) -> 1 | G11: =IF(INDEX(Keys!$F:$F,MATCH($A11,Keys!$D:$D,0))="Y",0,IF($B28=1,IF($B29=1,IF(INDEX(Keys!$H:$H,MATCH($A11,Keys!$D:$D,0))="Y",0,IF(AND(INDEX(Keys!$G:$G,MATCH($A11,Keys!$D:$D,0))="Y",G$1<Keys!$K$2),0,1)),IF(INDEX(Keys!$E:$E,MATCH($A11,Keys!$D:$D,0))="Y",1,0)),1)) -> 1 | H11: =IF(INDEX(Keys!$F:$F,MATCH($A11,Keys!$D:$D,0))="Y",0,IF($B28=1,IF($B29=1,IF(INDEX(Keys!$H:$H,MATCH($A11,Keys!$D:$D,0))="Y",0,IF(AND(INDEX(Keys!$G:$G,MATCH($A11,Keys!$D:$D,0))="Y",H$1<Keys!$K$2),0,1)),IF(INDEX(Keys!$E:$E,MATCH($A11,Keys!$D:$D,0))="Y",1,0)),1)) -> 1 | I11: =IF(INDEX(Keys!$F:$F,MATCH($A11,Keys!$D:$D,0))="Y",0,IF($B28=1,IF($B29=1,IF(INDEX(Keys!$H:$H,MATCH($A11,Keys!$D:$D,0))="Y",0,IF(AND(INDEX(Keys!$G:$G,MATCH($A11,Keys!$D:$D,0))="Y",I$1<Keys!$K$2),0,1)),IF(INDEX(Keys!$E:$E,MATCH($A11,Keys!$D:$D,0))="Y",1,0)),1)) -> 1 | ... AE11: =IF(INDEX(Keys!$F:$F,MATCH($A11,Keys!$D:$D,0))="Y",0,IF($B28=1,IF($B29=1,IF(INDEX(Keys!$H:$H,MATCH($A11,Keys!$D:$D,0))="Y",0,IF(AND(INDEX(Keys!$G:$G,MATCH($A11,Keys!$D:$D,0))="Y",AE$1<Keys!$K$2),0,1)),IF(INDEX(Keys!$E:$E,MATCH($A11,Keys!$D:$D,0))="Y",1,0)),1)) -> 1
A12: =Keys!$D12 -> rubber and plastic products 22 | B12: =IF(INDEX(Keys!$F:$F,MATCH($A12,Keys!$D:$D,0))="Y",0,IF($B28=1,IF($B29=1,IF(INDEX(Keys!$H:$H,MATCH($A12,Keys!$D:$D,0))="Y",0,IF(AND(INDEX(Keys!$G:$G,MATCH($A12,Keys!$D:$D,0))="Y",B$1<Keys!$K$2),0,1)),IF(INDEX(Keys!$E:$E,MATCH($A12,Keys!$D:$D,0))="Y",1,0)),1)) -> 1 | C12: =IF(INDEX(Keys!$F:$F,MATCH($A12,Keys!$D:$D,0))="Y",0,IF($B28=1,IF($B29=1,IF(INDEX(Keys!$H:$H,MATCH($A12,Keys!$D:$D,0))="Y",0,IF(AND(INDEX(Keys!$G:$G,MATCH($A12,Keys!$D:$D,0))="Y",C$1<Keys!$K$2),0,1)),IF(INDEX(Keys!$E:$E,MATCH($A12,Keys!$D:$D,0))="Y",1,0)),1)) -> 1 | D12: =IF(INDEX(Keys!$F:$F,MATCH($A12,Keys!$D:$D,0))="Y",0,IF($B28=1,IF($B29=1,IF(INDEX(Keys!$H:$H,MATCH($A12,Keys!$D:$D,0))="Y",0,IF(AND(INDEX(Keys!$G:$G,MATCH($A12,Keys!$D:$D,0))="Y",D$1<Keys!$K$2),0,1)),IF(INDEX(Keys!$E:$E,MATCH($A12,Keys!$D:$D,0))="Y",1,0)),1)) -> 1 | E12: =IF(INDEX(Keys!$F:$F,MATCH($A12,Keys!$D:$D,0))="Y",0,IF($B28=1,IF($B29=1,IF(INDEX(Keys!$H:$H,MATCH($A12,Keys!$D:$D,0))="Y",0,IF(AND(INDEX(Keys!$G:$G,MATCH($A12,Keys!$D:$D,0))="Y",E$1<Keys!$K$2),0,1)),IF(INDEX(Keys!$E:$E,MATCH($A12,Keys!$D:$D,0))="Y",1,0)),1)) -> 1 | F12: =IF(INDEX(Keys!$F:$F,MATCH($A12,Keys!$D:$D,0))="Y",0,IF($B28=1,IF($B29=1,IF(INDEX(Keys!$H:$H,MATCH($A12,Keys!$D:$D,0))="Y",0,IF(AND(INDEX(Keys!$G:$G,MATCH($A12,Keys!$D:$D,0))="Y",F$1<Keys!$K$2),0,1)),IF(INDEX(Keys!$E:$E,MATCH($A12,Keys!$D:$D,0))="Y",1,0)),1)) -> 1 | G12: =IF(INDEX(Keys!$F:$F,MATCH($A12,Keys!$D:$D,0))="Y",0,IF($B28=1,IF($B29=1,IF(INDEX(Keys!$H:$H,MATCH($A12,Keys!$D:$D,0))="Y",0,IF(AND(INDEX(Keys!$G:$G,MATCH($A12,Keys!$D:$D,0))="Y",G$1<Keys!$K$2),0,1)),IF(INDEX(Keys!$E:$E,MATCH($A12,Keys!$D:$D,0))="Y",1,0)),1)) -> 1 | H12: =IF(INDEX(Keys!$F:$F,MATCH($A12,Keys!$D:$D,0))="Y",0,IF($B28=1,IF($B29=1,IF(INDEX(Keys!$H:$H,MATCH($A12,Keys!$D:$D,0))="Y",0,IF(AND(INDEX(Keys!$G:$G,MATCH($A12,Keys!$D:$D,0))="Y",H$1<Keys!$K$2),0,1)),IF(INDEX(Keys!$E:$E,MATCH($A12,Keys!$D:$D,0))="Y",1,0)),1)) -> 1 | I12: =IF(INDEX(Keys!$F:$F,MATCH($A12,Keys!$D:$D,0))="Y",0,IF($B28=1,IF($B29=1,IF(INDEX(Keys!$H:$H,MATCH($A12,Keys!$D:$D,0))="Y",0,IF(AND(INDEX(Keys!$G:$G,MATCH($A12,Keys!$D:$D,0))="Y",I$1<Keys!$K$2),0,1)),IF(INDEX(Keys!$E:$E,MATCH($A12,Keys!$D:$D,0))="Y",1,0)),1)) -> 1 | ... AE12: =IF(INDEX(Keys!$F:$F,MATCH($A12,Keys!$D:$D,0))="Y",0,IF($B28=1,IF($B29=1,IF(INDEX(Keys!$H:$H,MATCH($A12,Keys!$D:$D,0))="Y",0,IF(AND(INDEX(Keys!$G:$G,MATCH($A12,Keys!$D:$D,0))="Y",AE$1<Keys!$K$2),0,1)),IF(INDEX(Keys!$E:$E,MATCH($A12,Keys!$D:$D,0))="Y",1,0)),1)) -> 1
A13: =Keys!$D13 -> glass and glass products 231 | B13: =IF(INDEX(Keys!$F:$F,MATCH($A13,Keys!$D:$D,0))="Y",0,IF($B28=1,IF($B29=1,IF(INDEX(Keys!$H:$H,MATCH($A13,Keys!$D:$D,0))="Y",0,IF(AND(INDEX(Keys!$G:$G,MATCH($A13,Keys!$D:$D,0))="Y",B$1<Keys!$K$2),0,1)),IF(INDEX(Keys!$E:$E,MATCH($A13,Keys!$D:$D,0))="Y",1,0)),1)) -> 1 | C13: =IF(INDEX(Keys!$F:$F,MATCH($A13,Keys!$D:$D,0))="Y",0,IF($B28=1,IF($B29=1,IF(INDEX(Keys!$H:$H,MATCH($A13,Keys!$D:$D,0))="Y",0,IF(AND(INDEX(Keys!$G:$G,MATCH($A13,Keys!$D:$D,0))="Y",C$1<Keys!$K$2),0,1)),IF(INDEX(Keys!$E:$E,MATCH($A13,Keys!$D:$D,0))="Y",1,0)),1)) -> 1 | D13: =IF(INDEX(Keys!$F:$F,MATCH($A13,Keys!$D:$D,0))="Y",0,IF($B28=1,IF($B29=1,IF(INDEX(Keys!$H:$H,MATCH($A13,Keys!$D:$D,0))="Y",0,IF(AND(INDEX(Keys!$G:$G,MATCH($A13,Keys!$D:$D,0))="Y",D$1<Keys!$K$2),0,1)),IF(INDEX(Keys!$E:$E,MATCH($A13,Keys!$D:$D,0))="Y",1,0)),1)) -> 1 | E13: =IF(INDEX(Keys!$F:$F,MATCH($A13,Keys!$D:$D,0))="Y",0,IF($B28=1,IF($B29=1,IF(INDEX(Keys!$H:$H,MATCH($A13,Keys!$D:$D,0))="Y",0,IF(AND(INDEX(Keys!$G:$G,MATCH($A13,Keys!$D:$D,0))="Y",E$1<Keys!$K$2),0,1)),IF(INDEX(Keys!$E:$E,MATCH($A13,Keys!$D:$D,0))="Y",1,0)),1)) -> 1 | F13: =IF(INDEX(Keys!$F:$F,MATCH($A13,Keys!$D:$D,0))="Y",0,IF($B28=1,IF($B29=1,IF(INDEX(Keys!$H:$H,MATCH($A13,Keys!$D:$D,0))="Y",0,IF(AND(INDEX(Keys!$G:$G,MATCH($A13,Keys!$D:$D,0))="Y",F$1<Keys!$K$2),0,1)),IF(INDEX(Keys!$E:$E,MATCH($A13,Keys!$D:$D,0))="Y",1,0)),1)) -> 1 | G13: =IF(INDEX(Keys!$F:$F,MATCH($A13,Keys!$D:$D,0))="Y",0,IF($B28=1,IF($B29=1,IF(INDEX(Keys!$H:$H,MATCH($A13,Keys!$D:$D,0))="Y",0,IF(AND(INDEX(Keys!$G:$G,MATCH($A13,Keys!$D:$D,0))="Y",G$1<Keys!$K$2),0,1)),IF(INDEX(Keys!$E:$E,MATCH($A13,Keys!$D:$D,0))="Y",1,0)),1)) -> 1 | H13: =IF(INDEX(Keys!$F:$F,MATCH($A13,Keys!$D:$D,0))="Y",0,IF($B28=1,IF($B29=1,IF(INDEX(Keys!$H:$H,MATCH($A13,Keys!$D:$D,0))="Y",0,IF(AND(INDEX(Keys!$G:$G,MATCH($A13,Keys!$D:$D,0))="Y",H$1<Keys!$K$2),0,1)),IF(INDEX(Keys!$E:$E,MATCH($A13,Keys!$D:$D,0))="Y",1,0)),1)) -> 1 | I13: =IF(INDEX(Keys!$F:$F,MATCH($A13,Keys!$D:$D,0))="Y",0,IF($B28=1,IF($B29=1,IF(INDEX(Keys!$H:$H,MATCH($A13,Keys!$D:$D,0))="Y",0,IF(AND(INDEX(Keys!$G:$G,MATCH($A13,Keys!$D:$D,0))="Y",I$1<Keys!$K$2),0,1)),IF(INDEX(Keys!$E:$E,MATCH($A13,Keys!$D:$D,0))="Y",1,0)),1)) -> 1 | ... AE13: =IF(INDEX(Keys!$F:$F,MATCH($A13,Keys!$D:$D,0))="Y",0,IF($B28=1,IF($B29=1,IF(INDEX(Keys!$H:$H,MATCH($A13,Keys!$D:$D,0))="Y",0,IF(AND(INDEX(Keys!$G:$G,MATCH($A13,Keys!$D:$D,0))="Y",AE$1<Keys!$K$2),0,1)),IF(INDEX(Keys!$E:$E,MATCH($A13,Keys!$D:$D,0))="Y",1,0)),1)) -> 1
A14: =Keys!$D14 -> cement and other nonmetallic minerals 239 | B14: =IF(INDEX(Keys!$F:$F,MATCH($A14,Keys!$D:$D,0))="Y",0,IF($B28=1,IF($B29=1,IF(INDEX(Keys!$H:$H,MATCH($A14,Keys!$D:$D,0))="Y",0,IF(AND(INDEX(Keys!$G:$G,MATCH($A14,Keys!$D:$D,0))="Y",B$1<Keys!$K$2),0,1)),IF(INDEX(Keys!$E:$E,MATCH($A14,Keys!$D:$D,0))="Y",1,0)),1)) -> 1 | C14: =IF(INDEX(Keys!$F:$F,MATCH($A14,Keys!$D:$D,0))="Y",0,IF($B28=1,IF($B29=1,IF(INDEX(Keys!$H:$H,MATCH($A14,Keys!$D:$D,0))="Y",0,IF(AND(INDEX(Keys!$G:$G,MATCH($A14,Keys!$D:$D,0))="Y",C$1<Keys!$K$2),0,1)),IF(INDEX(Keys!$E:$E,MATCH($A14,Keys!$D:$D,0))="Y",1,0)),1)) -> 1 | D14: =IF(INDEX(Keys!$F:$F,MATCH($A14,Keys!$D:$D,0))="Y",0,IF($B28=1,IF($B29=1,IF(INDEX(Keys!$H:$H,MATCH($A14,Keys!$D:$D,0))="Y",0,IF(AND(INDEX(Keys!$G:$G,MATCH($A14,Keys!$D:$D,0))="Y",D$1<Keys!$K$2),0,1)),IF(INDEX(Keys!$E:$E,MATCH($A14,Keys!$D:$D,0))="Y",1,0)),1)) -> 1 | E14: =IF(INDEX(Keys!$F:$F,MATCH($A14,Keys!$D:$D,0))="Y",0,IF($B28=1,IF($B29=1,IF(INDEX(Keys!$H:$H,MATCH($A14,Keys!$D:$D,0))="Y",0,IF(AND(INDEX(Keys!$G:$G,MATCH($A14,Keys!$D:$D,0))="Y",E$1<Keys!$K$2),0,1)),IF(INDEX(Keys!$E:$E,MATCH($A14,Keys!$D:$D,0))="Y",1,0)),1)) -> 1 | F14: =IF(INDEX(Keys!$F:$F,MATCH($A14,Keys!$D:$D,0))="Y",0,IF($B28=1,IF($B29=1,IF(INDEX(Keys!$H:$H,MATCH($A14,Keys!$D:$D,0))="Y",0,IF(AND(INDEX(Keys!$G:$G,MATCH($A14,Keys!$D:$D,0))="Y",F$1<Keys!$K$2),0,1)),IF(INDEX(Keys!$E:$E,MATCH($A14,Keys!$D:$D,0))="Y",1,0)),1)) -> 1 | G14: =IF(INDEX(Keys!$F:$F,MATCH($A14,Keys!$D:$D,0))="Y",0,IF($B28=1,IF($B29=1,IF(INDEX(Keys!$H:$H,MATCH($A14,Keys!$D:$D,0))="Y",0,IF(AND(INDEX(Keys!$G:$G,MATCH($A14,Keys!$D:$D,0))="Y",G$1<Keys!$K$2),0,1)),IF(INDEX(Keys!$E:$E,MATCH($A14,Keys!$D:$D,0))="Y",1,0)),1)) -> 1 | H14: =IF(INDEX(Keys!$F:$F,MATCH($A14,Keys!$D:$D,0))="Y",0,IF($B28=1,IF($B29=1,IF(INDEX(Keys!$H:$H,MATCH($A14,Keys!$D:$D,0))="Y",0,IF(AND(INDEX(Keys!$G:$G,MATCH($A14,Keys!$D:$D,0))="Y",H$1<Keys!$K$2),0,1)),IF(INDEX(Keys!$E:$E,MATCH($A14,Keys!$D:$D,0))="Y",1,0)),1)) -> 1 | I14: =IF(INDEX(Keys!$F:$F,MATCH($A14,Keys!$D:$D,0))="Y",0,IF($B28=1,IF($B29=1,IF(INDEX(Keys!$H:$H,MATCH($A14,Keys!$D:$D,0))="Y",0,IF(AND(INDEX(Keys!$G:$G,MATCH($A14,Keys!$D:$D,0))="Y",I$1<Keys!$K$2),0,1)),IF(INDEX(Keys!$E:$E,MATCH($A14,Keys!$D:$D,0))="Y",1,0)),1)) -> 1 | ... AE14: =IF(INDEX(Keys!$F:$F,MATCH($A14,Keys!$D:$D,0))="Y",0,IF($B28=1,IF($B29=1,IF(INDEX(Keys!$H:$H,MATCH($A14,Keys!$D:$D,0))="Y",0,IF(AND(INDEX(Keys!$G:$G,MATCH($A14,Keys!$D:$D,0))="Y",AE$1<Keys!$K$2),0,1)),IF(INDEX(Keys!$E:$E,MATCH($A14,Keys!$D:$D,0))="Y",1,0)),1)) -> 1
A15: =Keys!$D15 -> iron and steel 241 | B15: =IF(INDEX(Keys!$F:$F,MATCH($A15,Keys!$D:$D,0))="Y",0,IF($B28=1,IF($B29=1,IF(INDEX(Keys!$H:$H,MATCH($A15,Keys!$D:$D,0))="Y",0,IF(AND(INDEX(Keys!$G:$G,MATCH($A15,Keys!$D:$D,0))="Y",B$1<Keys!$K$2),0,1)),IF(INDEX(Keys!$E:$E,MATCH($A15,Keys!$D:$D,0))="Y",1,0)),1)) -> 1 | C15: =IF(INDEX(Keys!$F:$F,MATCH($A15,Keys!$D:$D,0))="Y",0,IF($B28=1,IF($B29=1,IF(INDEX(Keys!$H:$H,MATCH($A15,Keys!$D:$D,0))="Y",0,IF(AND(INDEX(Keys!$G:$G,MATCH($A15,Keys!$D:$D,0))="Y",C$1<Keys!$K$2),0,1)),IF(INDEX(Keys!$E:$E,MATCH($A15,Keys!$D:$D,0))="Y",1,0)),1)) -> 1 | D15: =IF(INDEX(Keys!$F:$F,MATCH($A15,Keys!$D:$D,0))="Y",0,IF($B28=1,IF($B29=1,IF(INDEX(Keys!$H:$H,MATCH($A15,Keys!$D:$D,0))="Y",0,IF(AND(INDEX(Keys!$G:$G,MATCH($A15,Keys!$D:$D,0))="Y",D$1<Keys!$K$2),0,1)),IF(INDEX(Keys!$E:$E,MATCH($A15,Keys!$D:$D,0))="Y",1,0)),1)) -> 1 | E15: =IF(INDEX(Keys!$F:$F,MATCH($A15,Keys!$D:$D,0))="Y",0,IF($B28=1,IF($B29=1,IF(INDEX(Keys!$H:$H,MATCH($A15,Keys!$D:$D,0))="Y",0,IF(AND(INDEX(Keys!$G:$G,MATCH($A15,Keys!$D:$D,0))="Y",E$1<Keys!$K$2),0,1)),IF(INDEX(Keys!$E:$E,MATCH($A15,Keys!$D:$D,0))="Y",1,0)),1)) -> 1 | F15: =IF(INDEX(Keys!$F:$F,MATCH($A15,Keys!$D:$D,0))="Y",0,IF($B28=1,IF($B29=1,IF(INDEX(Keys!$H:$H,MATCH($A15,Keys!$D:$D,0))="Y",0,IF(AND(INDEX(Keys!$G:$G,MATCH($A15,Keys!$D:$D,0))="Y",F$1<Keys!$K$2),0,1)),IF(INDEX(Keys!$E:$E,MATCH($A15,Keys!$D:$D,0))="Y",1,0)),1)) -> 1 | G15: =IF(INDEX(Keys!$F:$F,MATCH($A15,Keys!$D:$D,0))="Y",0,IF($B28=1,IF($B29=1,IF(INDEX(Keys!$H:$H,MATCH($A15,Keys!$D:$D,0))="Y",0,IF(AND(INDEX(Keys!$G:$G,MATCH($A15,Keys!$D:$D,0))="Y",G$1<Keys!$K$2),0,1)),IF(INDEX(Keys!$E:$E,MATCH($A15,Keys!$D:$D,0))="Y",1,0)),1)) -> 1 | H15: =IF(INDEX(Keys!$F:$F,MATCH($A15,Keys!$D:$D,0))="Y",0,IF($B28=1,IF($B29=1,IF(INDEX(Keys!$H:$H,MATCH($A15,Keys!$D:$D,0))="Y",0,IF(AND(INDEX(Keys!$G:$G,MATCH($A15,Keys!$D:$D,0))="Y",H$1<Keys!$K$2),0,1)),IF(INDEX(Keys!$E:$E,MATCH($A15,Keys!$D:$D,0))="Y",1,0)),1)) -> 1 | I15: =IF(INDEX(Keys!$F:$F,MATCH($A15,Keys!$D:$D,0))="Y",0,IF($B28=1,IF($B29=1,IF(INDEX(Keys!$H:$H,MATCH($A15,Keys!$D:$D,0))="Y",0,IF(AND(INDEX(Keys!$G:$G,MATCH($A15,Keys!$D:$D,0))="Y",I$1<Keys!$K$2),0,1)),IF(INDEX(Keys!$E:$E,MATCH($A15,Keys!$D:$D,0))="Y",1,0)),1)) -> 1 | ... AE15: =IF(INDEX(Keys!$F:$F,MATCH($A15,Keys!$D:$D,0))="Y",0,IF($B28=1,IF($B29=1,IF(INDEX(Keys!$H:$H,MATCH($A15,Keys!$D:$D,0))="Y",0,IF(AND(INDEX(Keys!$G:$G,MATCH($A15,Keys!$D:$D,0))="Y",AE$1<Keys!$K$2),0,1)),IF(INDEX(Keys!$E:$E,MATCH($A15,Keys!$D:$D,0))="Y",1,0)),1)) -> 1
A16: =Keys!$D16 -> other metals 242 | B16: =IF(INDEX(Keys!$F:$F,MATCH($A16,Keys!$D:$D,0))="Y",0,IF($B28=1,IF($B29=1,IF(INDEX(Keys!$H:$H,MATCH($A16,Keys!$D:$D,0))="Y",0,IF(AND(INDEX(Keys!$G:$G,MATCH($A16,Keys!$D:$D,0))="Y",B$1<Keys!$K$2),0,1)),IF(INDEX(Keys!$E:$E,MATCH($A16,Keys!$D:$D,0))="Y",1,0)),1)) -> 1 | C16: =IF(INDEX(Keys!$F:$F,MATCH($A16,Keys!$D:$D,0))="Y",0,IF($B28=1,IF($B29=1,IF(INDEX(Keys!$H:$H,MATCH($A16,Keys!$D:$D,0))="Y",0,IF(AND(INDEX(Keys!$G:$G,MATCH($A16,Keys!$D:$D,0))="Y",C$1<Keys!$K$2),0,1)),IF(INDEX(Keys!$E:$E,MATCH($A16,Keys!$D:$D,0))="Y",1,0)),1)) -> 1 | D16: =IF(INDEX(Keys!$F:$F,MATCH($A16,Keys!$D:$D,0))="Y",0,IF($B28=1,IF($B29=1,IF(INDEX(Keys!$H:$H,MATCH($A16,Keys!$D:$D,0))="Y",0,IF(AND(INDEX(Keys!$G:$G,MATCH($A16,Keys!$D:$D,0))="Y",D$1<Keys!$K$2),0,1)),IF(INDEX(Keys!$E:$E,MATCH($A16,Keys!$D:$D,0))="Y",1,0)),1)) -> 1 | E16: =IF(INDEX(Keys!$F:$F,MATCH($A16,Keys!$D:$D,0))="Y",0,IF($B28=1,IF($B29=1,IF(INDEX(Keys!$H:$H,MATCH($A16,Keys!$D:$D,0))="Y",0,IF(AND(INDEX(Keys!$G:$G,MATCH($A16,Keys!$D:$D,0))="Y",E$1<Keys!$K$2),0,1)),IF(INDEX(Keys!$E:$E,MATCH($A16,Keys!$D:$D,0))="Y",1,0)),1)) -> 1 | F16: =IF(INDEX(Keys!$F:$F,MATCH($A16,Keys!$D:$D,0))="Y",0,IF($B28=1,IF($B29=1,IF(INDEX(Keys!$H:$H,MATCH($A16,Keys!$D:$D,0))="Y",0,IF(AND(INDEX(Keys!$G:$G,MATCH($A16,Keys!$D:$D,0))="Y",F$1<Keys!$K$2),0,1)),IF(INDEX(Keys!$E:$E,MATCH($A16,Keys!$D:$D,0))="Y",1,0)),1)) -> 1 | G16: =IF(INDEX(Keys!$F:$F,MATCH($A16,Keys!$D:$D,0))="Y",0,IF($B28=1,IF($B29=1,IF(INDEX(Keys!$H:$H,MATCH($A16,Keys!$D:$D,0))="Y",0,IF(AND(INDEX(Keys!$G:$G,MATCH($A16,Keys!$D:$D,0))="Y",G$1<Keys!$K$2),0,1)),IF(INDEX(Keys!$E:$E,MATCH($A16,Keys!$D:$D,0))="Y",1,0)),1)) -> 1 | H16: =IF(INDEX(Keys!$F:$F,MATCH($A16,Keys!$D:$D,0))="Y",0,IF($B28=1,IF($B29=1,IF(INDEX(Keys!$H:$H,MATCH($A16,Keys!$D:$D,0))="Y",0,IF(AND(INDEX(Keys!$G:$G,MATCH($A16,Keys!$D:$D,0))="Y",H$1<Keys!$K$2),0,1)),IF(INDEX(Keys!$E:$E,MATCH($A16,Keys!$D:$D,0))="Y",1,0)),1)) -> 1 | I16: =IF(INDEX(Keys!$F:$F,MATCH($A16,Keys!$D:$D,0))="Y",0,IF($B28=1,IF($B29=1,IF(INDEX(Keys!$H:$H,MATCH($A16,Keys!$D:$D,0))="Y",0,IF(AND(INDEX(Keys!$G:$G,MATCH($A16,Keys!$D:$D,0))="Y",I$1<Keys!$K$2),0,1)),IF(INDEX(Keys!$E:$E,MATCH($A16,Keys!$D:$D,0))="Y",1,0)),1)) -> 1 | ... AE16: =IF(INDEX(Keys!$F:$F,MATCH($A16,Keys!$D:$D,0))="Y",0,IF($B28=1,IF($B29=1,IF(INDEX(Keys!$H:$H,MATCH($A16,Keys!$D:$D,0))="Y",0,IF(AND(INDEX(Keys!$G:$G,MATCH($A16,Keys!$D:$D,0))="Y",AE$1<Keys!$K$2),0,1)),IF(INDEX(Keys!$E:$E,MATCH($A16,Keys!$D:$D,0))="Y",1,0)),1)) -> 1
A17: =Keys!$D17 -> metal products except machinery and vehicles 25 | B17: =IF(INDEX(Keys!$F:$F,MATCH($A17,Keys!$D:$D,0))="Y",0,IF($B28=1,IF($B29=1,IF(INDEX(Keys!$H:$H,MATCH($A17,Keys!$D:$D,0))="Y",0,IF(AND(INDEX(Keys!$G:$G,MATCH($A17,Keys!$D:$D,0))="Y",B$1<Keys!$K$2),0,1)),IF(INDEX(Keys!$E:$E,MATCH($A17,Keys!$D:$D,0))="Y",1,0)),1)) -> 1 | C17: =IF(INDEX(Keys!$F:$F,MATCH($A17,Keys!$D:$D,0))="Y",0,IF($B28=1,IF($B29=1,IF(INDEX(Keys!$H:$H,MATCH($A17,Keys!$D:$D,0))="Y",0,IF(AND(INDEX(Keys!$G:$G,MATCH($A17,Keys!$D:$D,0))="Y",C$1<Keys!$K$2),0,1)),IF(INDEX(Keys!$E:$E,MATCH($A17,Keys!$D:$D,0))="Y",1,0)),1)) -> 1 | D17: =IF(INDEX(Keys!$F:$F,MATCH($A17,Keys!$D:$D,0))="Y",0,IF($B28=1,IF($B29=1,IF(INDEX(Keys!$H:$H,MATCH($A17,Keys!$D:$D,0))="Y",0,IF(AND(INDEX(Keys!$G:$G,MATCH($A17,Keys!$D:$D,0))="Y",D$1<Keys!$K$2),0,1)),IF(INDEX(Keys!$E:$E,MATCH($A17,Keys!$D:$D,0))="Y",1,0)),1)) -> 1 | E17: =IF(INDEX(Keys!$F:$F,MATCH($A17,Keys!$D:$D,0))="Y",0,IF($B28=1,IF($B29=1,IF(INDEX(Keys!$H:$H,MATCH($A17,Keys!$D:$D,0))="Y",0,IF(AND(INDEX(Keys!$G:$G,MATCH($A17,Keys!$D:$D,0))="Y",E$1<Keys!$K$2),0,1)),IF(INDEX(Keys!$E:$E,MATCH($A17,Keys!$D:$D,0))="Y",1,0)),1)) -> 1 | F17: =IF(INDEX(Keys!$F:$F,MATCH($A17,Keys!$D:$D,0))="Y",0,IF($B28=1,IF($B29=1,IF(INDEX(Keys!$H:$H,MATCH($A17,Keys!$D:$D,0))="Y",0,IF(AND(INDEX(Keys!$G:$G,MATCH($A17,Keys!$D:$D,0))="Y",F$1<Keys!$K$2),0,1)),IF(INDEX(Keys!$E:$E,MATCH($A17,Keys!$D:$D,0))="Y",1,0)),1)) -> 1 | G17: =IF(INDEX(Keys!$F:$F,MATCH($A17,Keys!$D:$D,0))="Y",0,IF($B28=1,IF($B29=1,IF(INDEX(Keys!$H:$H,MATCH($A17,Keys!$D:$D,0))="Y",0,IF(AND(INDEX(Keys!$G:$G,MATCH($A17,Keys!$D:$D,0))="Y",G$1<Keys!$K$2),0,1)),IF(INDEX(Keys!$E:$E,MATCH($A17,Keys!$D:$D,0))="Y",1,0)),1)) -> 1 | H17: =IF(INDEX(Keys!$F:$F,MATCH($A17,Keys!$D:$D,0))="Y",0,IF($B28=1,IF($B29=1,IF(INDEX(Keys!$H:$H,MATCH($A17,Keys!$D:$D,0))="Y",0,IF(AND(INDEX(Keys!$G:$G,MATCH($A17,Keys!$D:$D,0))="Y",H$1<Keys!$K$2),0,1)),IF(INDEX(Keys!$E:$E,MATCH($A17,Keys!$D:$D,0))="Y",1,0)),1)) -> 1 | I17: =IF(INDEX(Keys!$F:$F,MATCH($A17,Keys!$D:$D,0))="Y",0,IF($B28=1,IF($B29=1,IF(INDEX(Keys!$H:$H,MATCH($A17,Keys!$D:$D,0))="Y",0,IF(AND(INDEX(Keys!$G:$G,MATCH($A17,Keys!$D:$D,0))="Y",I$1<Keys!$K$2),0,1)),IF(INDEX(Keys!$E:$E,MATCH($A17,Keys!$D:$D,0))="Y",1,0)),1)) -> 1 | ... AE17: =IF(INDEX(Keys!$F:$F,MATCH($A17,Keys!$D:$D,0))="Y",0,IF($B28=1,IF($B29=1,IF(INDEX(Keys!$H:$H,MATCH($A17,Keys!$D:$D,0))="Y",0,IF(AND(INDEX(Keys!$G:$G,MATCH($A17,Keys!$D:$D,0))="Y",AE$1<Keys!$K$2),0,1)),IF(INDEX(Keys!$E:$E,MATCH($A17,Keys!$D:$D,0))="Y",1,0)),1)) -> 1
A18: =Keys!$D18 -> computers and electronics 26 | B18: =IF(INDEX(Keys!$F:$F,MATCH($A18,Keys!$D:$D,0))="Y",0,IF($B28=1,IF($B29=1,IF(INDEX(Keys!$H:$H,MATCH($A18,Keys!$D:$D,0))="Y",0,IF(AND(INDEX(Keys!$G:$G,MATCH($A18,Keys!$D:$D,0))="Y",B$1<Keys!$K$2),0,1)),IF(INDEX(Keys!$E:$E,MATCH($A18,Keys!$D:$D,0))="Y",1,0)),1)) -> 1 | C18: =IF(INDEX(Keys!$F:$F,MATCH($A18,Keys!$D:$D,0))="Y",0,IF($B28=1,IF($B29=1,IF(INDEX(Keys!$H:$H,MATCH($A18,Keys!$D:$D,0))="Y",0,IF(AND(INDEX(Keys!$G:$G,MATCH($A18,Keys!$D:$D,0))="Y",C$1<Keys!$K$2),0,1)),IF(INDEX(Keys!$E:$E,MATCH($A18,Keys!$D:$D,0))="Y",1,0)),1)) -> 1 | D18: =IF(INDEX(Keys!$F:$F,MATCH($A18,Keys!$D:$D,0))="Y",0,IF($B28=1,IF($B29=1,IF(INDEX(Keys!$H:$H,MATCH($A18,Keys!$D:$D,0))="Y",0,IF(AND(INDEX(Keys!$G:$G,MATCH($A18,Keys!$D:$D,0))="Y",D$1<Keys!$K$2),0,1)),IF(INDEX(Keys!$E:$E,MATCH($A18,Keys!$D:$D,0))="Y",1,0)),1)) -> 1 | E18: =IF(INDEX(Keys!$F:$F,MATCH($A18,Keys!$D:$D,0))="Y",0,IF($B28=1,IF($B29=1,IF(INDEX(Keys!$H:$H,MATCH($A18,Keys!$D:$D,0))="Y",0,IF(AND(INDEX(Keys!$G:$G,MATCH($A18,Keys!$D:$D,0))="Y",E$1<Keys!$K$2),0,1)),IF(INDEX(Keys!$E:$E,MATCH($A18,Keys!$D:$D,0))="Y",1,0)),1)) -> 1 | F18: =IF(INDEX(Keys!$F:$F,MATCH($A18,Keys!$D:$D,0))="Y",0,IF($B28=1,IF($B29=1,IF(INDEX(Keys!$H:$H,MATCH($A18,Keys!$D:$D,0))="Y",0,IF(AND(INDEX(Keys!$G:$G,MATCH($A18,Keys!$D:$D,0))="Y",F$1<Keys!$K$2),0,1)),IF(INDEX(Keys!$E:$E,MATCH($A18,Keys!$D:$D,0))="Y",1,0)),1)) -> 1 | G18: =IF(INDEX(Keys!$F:$F,MATCH($A18,Keys!$D:$D,0))="Y",0,IF($B28=1,IF($B29=1,IF(INDEX(Keys!$H:$H,MATCH($A18,Keys!$D:$D,0))="Y",0,IF(AND(INDEX(Keys!$G:$G,MATCH($A18,Keys!$D:$D,0))="Y",G$1<Keys!$K$2),0,1)),IF(INDEX(Keys!$E:$E,MATCH($A18,Keys!$D:$D,0))="Y",1,0)),1)) -> 1 | H18: =IF(INDEX(Keys!$F:$F,MATCH($A18,Keys!$D:$D,0))="Y",0,IF($B28=1,IF($B29=1,IF(INDEX(Keys!$H:$H,MATCH($A18,Keys!$D:$D,0))="Y",0,IF(AND(INDEX(Keys!$G:$G,MATCH($A18,Keys!$D:$D,0))="Y",H$1<Keys!$K$2),0,1)),IF(INDEX(Keys!$E:$E,MATCH($A18,Keys!$D:$D,0))="Y",1,0)),1)) -> 1 | I18: =IF(INDEX(Keys!$F:$F,MATCH($A18,Keys!$D:$D,0))="Y",0,IF($B28=1,IF($B29=1,IF(INDEX(Keys!$H:$H,MATCH($A18,Keys!$D:$D,0))="Y",0,IF(AND(INDEX(Keys!$G:$G,MATCH($A18,Keys!$D:$D,0))="Y",I$1<Keys!$K$2),0,1)),IF(INDEX(Keys!$E:$E,MATCH($A18,Keys!$D:$D,0))="Y",1,0)),1)) -> 1 | ... AE18: =IF(INDEX(Keys!$F:$F,MATCH($A18,Keys!$D:$D,0))="Y",0,IF($B28=1,IF($B29=1,IF(INDEX(Keys!$H:$H,MATCH($A18,Keys!$D:$D,0))="Y",0,IF(AND(INDEX(Keys!$G:$G,MATCH($A18,Keys!$D:$D,0))="Y",AE$1<Keys!$K$2),0,1)),IF(INDEX(Keys!$E:$E,MATCH($A18,Keys!$D:$D,0))="Y",1,0)),1)) -> 1
A19: =Keys!$D19 -> appliances and electrical equipment 27 | B19: =IF(INDEX(Keys!$F:$F,MATCH($A19,Keys!$D:$D,0))="Y",0,IF($B28=1,IF($B29=1,IF(INDEX(Keys!$H:$H,MATCH($A19,Keys!$D:$D,0))="Y",0,IF(AND(INDEX(Keys!$G:$G,MATCH($A19,Keys!$D:$D,0))="Y",B$1<Keys!$K$2),0,1)),IF(INDEX(Keys!$E:$E,MATCH($A19,Keys!$D:$D,0))="Y",1,0)),1)) -> 1 | C19: =IF(INDEX(Keys!$F:$F,MATCH($A19,Keys!$D:$D,0))="Y",0,IF($B28=1,IF($B29=1,IF(INDEX(Keys!$H:$H,MATCH($A19,Keys!$D:$D,0))="Y",0,IF(AND(INDEX(Keys!$G:$G,MATCH($A19,Keys!$D:$D,0))="Y",C$1<Keys!$K$2),0,1)),IF(INDEX(Keys!$E:$E,MATCH($A19,Keys!$D:$D,0))="Y",1,0)),1)) -> 1 | D19: =IF(INDEX(Keys!$F:$F,MATCH($A19,Keys!$D:$D,0))="Y",0,IF($B28=1,IF($B29=1,IF(INDEX(Keys!$H:$H,MATCH($A19,Keys!$D:$D,0))="Y",0,IF(AND(INDEX(Keys!$G:$G,MATCH($A19,Keys!$D:$D,0))="Y",D$1<Keys!$K$2),0,1)),IF(INDEX(Keys!$E:$E,MATCH($A19,Keys!$D:$D,0))="Y",1,0)),1)) -> 1 | E19: =IF(INDEX(Keys!$F:$F,MATCH($A19,Keys!$D:$D,0))="Y",0,IF($B28=1,IF($B29=1,IF(INDEX(Keys!$H:$H,MATCH($A19,Keys!$D:$D,0))="Y",0,IF(AND(INDEX(Keys!$G:$G,MATCH($A19,Keys!$D:$D,0))="Y",E$1<Keys!$K$2),0,1)),IF(INDEX(Keys!$E:$E,MATCH($A19,Keys!$D:$D,0))="Y",1,0)),1)) -> 1 | F19: =IF(INDEX(Keys!$F:$F,MATCH($A19,Keys!$D:$D,0))="Y",0,IF($B28=1,IF($B29=1,IF(INDEX(Keys!$H:$H,MATCH($A19,Keys!$D:$D,0))="Y",0,IF(AND(INDEX(Keys!$G:$G,MATCH($A19,Keys!$D:$D,0))="Y",F$1<Keys!$K$2),0,1)),IF(INDEX(Keys!$E:$E,MATCH($A19,Keys!$D:$D,0))="Y",1,0)),1)) -> 1 | G19: =IF(INDEX(Keys!$F:$F,MATCH($A19,Keys!$D:$D,0))="Y",0,IF($B28=1,IF($B29=1,IF(INDEX(Keys!$H:$H,MATCH($A19,Keys!$D:$D,0))="Y",0,IF(AND(INDEX(Keys!$G:$G,MATCH($A19,Keys!$D:$D,0))="Y",G$1<Keys!$K$2),0,1)),IF(INDEX(Keys!$E:$E,MATCH($A19,Keys!$D:$D,0))="Y",1,0)),1)) -> 1 | H19: =IF(INDEX(Keys!$F:$F,MATCH($A19,Keys!$D:$D,0))="Y",0,IF($B28=1,IF($B29=1,IF(INDEX(Keys!$H:$H,MATCH($A19,Keys!$D:$D,0))="Y",0,IF(AND(INDEX(Keys!$G:$G,MATCH($A19,Keys!$D:$D,0))="Y",H$1<Keys!$K$2),0,1)),IF(INDEX(Keys!$E:$E,MATCH($A19,Keys!$D:$D,0))="Y",1,0)),1)) -> 1 | I19: =IF(INDEX(Keys!$F:$F,MATCH($A19,Keys!$D:$D,0))="Y",0,IF($B28=1,IF($B29=1,IF(INDEX(Keys!$H:$H,MATCH($A19,Keys!$D:$D,0))="Y",0,IF(AND(INDEX(Keys!$G:$G,MATCH($A19,Keys!$D:$D,0))="Y",I$1<Keys!$K$2),0,1)),IF(INDEX(Keys!$E:$E,MATCH($A19,Keys!$D:$D,0))="Y",1,0)),1)) -> 1 | ... AE19: =IF(INDEX(Keys!$F:$F,MATCH($A19,Keys!$D:$D,0))="Y",0,IF($B28=1,IF($B29=1,IF(INDEX(Keys!$H:$H,MATCH($A19,Keys!$D:$D,0))="Y",0,IF(AND(INDEX(Keys!$G:$G,MATCH($A19,Keys!$D:$D,0))="Y",AE$1<Keys!$K$2),0,1)),IF(INDEX(Keys!$E:$E,MATCH($A19,Keys!$D:$D,0))="Y",1,0)),1)) -> 1
A20: =Keys!$D20 -> other machinery 28 | B20: =IF(INDEX(Keys!$F:$F,MATCH($A20,Keys!$D:$D,0))="Y",0,IF($B28=1,IF($B29=1,IF(INDEX(Keys!$H:$H,MATCH($A20,Keys!$D:$D,0))="Y",0,IF(AND(INDEX(Keys!$G:$G,MATCH($A20,Keys!$D:$D,0))="Y",B$1<Keys!$K$2),0,1)),IF(INDEX(Keys!$E:$E,MATCH($A20,Keys!$D:$D,0))="Y",1,0)),1)) -> 1 | C20: =IF(INDEX(Keys!$F:$F,MATCH($A20,Keys!$D:$D,0))="Y",0,IF($B28=1,IF($B29=1,IF(INDEX(Keys!$H:$H,MATCH($A20,Keys!$D:$D,0))="Y",0,IF(AND(INDEX(Keys!$G:$G,MATCH($A20,Keys!$D:$D,0))="Y",C$1<Keys!$K$2),0,1)),IF(INDEX(Keys!$E:$E,MATCH($A20,Keys!$D:$D,0))="Y",1,0)),1)) -> 1 | D20: =IF(INDEX(Keys!$F:$F,MATCH($A20,Keys!$D:$D,0))="Y",0,IF($B28=1,IF($B29=1,IF(INDEX(Keys!$H:$H,MATCH($A20,Keys!$D:$D,0))="Y",0,IF(AND(INDEX(Keys!$G:$G,MATCH($A20,Keys!$D:$D,0))="Y",D$1<Keys!$K$2),0,1)),IF(INDEX(Keys!$E:$E,MATCH($A20,Keys!$D:$D,0))="Y",1,0)),1)) -> 1 | E20: =IF(INDEX(Keys!$F:$F,MATCH($A20,Keys!$D:$D,0))="Y",0,IF($B28=1,IF($B29=1,IF(INDEX(Keys!$H:$H,MATCH($A20,Keys!$D:$D,0))="Y",0,IF(AND(INDEX(Keys!$G:$G,MATCH($A20,Keys!$D:$D,0))="Y",E$1<Keys!$K$2),0,1)),IF(INDEX(Keys!$E:$E,MATCH($A20,Keys!$D:$D,0))="Y",1,0)),1)) -> 1 | F20: =IF(INDEX(Keys!$F:$F,MATCH($A20,Keys!$D:$D,0))="Y",0,IF($B28=1,IF($B29=1,IF(INDEX(Keys!$H:$H,MATCH($A20,Keys!$D:$D,0))="Y",0,IF(AND(INDEX(Keys!$G:$G,MATCH($A20,Keys!$D:$D,0))="Y",F$1<Keys!$K$2),0,1)),IF(INDEX(Keys!$E:$E,MATCH($A20,Keys!$D:$D,0))="Y",1,0)),1)) -> 1 | G20: =IF(INDEX(Keys!$F:$F,MATCH($A20,Keys!$D:$D,0))="Y",0,IF($B28=1,IF($B29=1,IF(INDEX(Keys!$H:$H,MATCH($A20,Keys!$D:$D,0))="Y",0,IF(AND(INDEX(Keys!$G:$G,MATCH($A20,Keys!$D:$D,0))="Y",G$1<Keys!$K$2),0,1)),IF(INDEX(Keys!$E:$E,MATCH($A20,Keys!$D:$D,0))="Y",1,0)),1)) -> 1 | H20: =IF(INDEX(Keys!$F:$F,MATCH($A20,Keys!$D:$D,0))="Y",0,IF($B28=1,IF($B29=1,IF(INDEX(Keys!$H:$H,MATCH($A20,Keys!$D:$D,0))="Y",0,IF(AND(INDEX(Keys!$G:$G,MATCH($A20,Keys!$D:$D,0))="Y",H$1<Keys!$K$2),0,1)),IF(INDEX(Keys!$E:$E,MATCH($A20,Keys!$D:$D,0))="Y",1,0)),1)) -> 1 | I20: =IF(INDEX(Keys!$F:$F,MATCH($A20,Keys!$D:$D,0))="Y",0,IF($B28=1,IF($B29=1,IF(INDEX(Keys!$H:$H,MATCH($A20,Keys!$D:$D,0))="Y",0,IF(AND(INDEX(Keys!$G:$G,MATCH($A20,Keys!$D:$D,0))="Y",I$1<Keys!$K$2),0,1)),IF(INDEX(Keys!$E:$E,MATCH($A20,Keys!$D:$D,0))="Y",1,0)),1)) -> 1 | ... AE20: =IF(INDEX(Keys!$F:$F,MATCH($A20,Keys!$D:$D,0))="Y",0,IF($B28=1,IF($B29=1,IF(INDEX(Keys!$H:$H,MATCH($A20,Keys!$D:$D,0))="Y",0,IF(AND(INDEX(Keys!$G:$G,MATCH($A20,Keys!$D:$D,0))="Y",AE$1<Keys!$K$2),0,1)),IF(INDEX(Keys!$E:$E,MATCH($A20,Keys!$D:$D,0))="Y",1,0)),1)) -> 1
A21: =Keys!$D21 -> road vehicles 29 | B21: =IF(INDEX(Keys!$F:$F,MATCH($A21,Keys!$D:$D,0))="Y",0,IF($B28=1,IF($B29=1,IF(INDEX(Keys!$H:$H,MATCH($A21,Keys!$D:$D,0))="Y",0,IF(AND(INDEX(Keys!$G:$G,MATCH($A21,Keys!$D:$D,0))="Y",B$1<Keys!$K$2),0,1)),IF(INDEX(Keys!$E:$E,MATCH($A21,Keys!$D:$D,0))="Y",1,0)),1)) -> 1 | C21: =IF(INDEX(Keys!$F:$F,MATCH($A21,Keys!$D:$D,0))="Y",0,IF($B28=1,IF($B29=1,IF(INDEX(Keys!$H:$H,MATCH($A21,Keys!$D:$D,0))="Y",0,IF(AND(INDEX(Keys!$G:$G,MATCH($A21,Keys!$D:$D,0))="Y",C$1<Keys!$K$2),0,1)),IF(INDEX(Keys!$E:$E,MATCH($A21,Keys!$D:$D,0))="Y",1,0)),1)) -> 1 | D21: =IF(INDEX(Keys!$F:$F,MATCH($A21,Keys!$D:$D,0))="Y",0,IF($B28=1,IF($B29=1,IF(INDEX(Keys!$H:$H,MATCH($A21,Keys!$D:$D,0))="Y",0,IF(AND(INDEX(Keys!$G:$G,MATCH($A21,Keys!$D:$D,0))="Y",D$1<Keys!$K$2),0,1)),IF(INDEX(Keys!$E:$E,MATCH($A21,Keys!$D:$D,0))="Y",1,0)),1)) -> 1 | E21: =IF(INDEX(Keys!$F:$F,MATCH($A21,Keys!$D:$D,0))="Y",0,IF($B28=1,IF($B29=1,IF(INDEX(Keys!$H:$H,MATCH($A21,Keys!$D:$D,0))="Y",0,IF(AND(INDEX(Keys!$G:$G,MATCH($A21,Keys!$D:$D,0))="Y",E$1<Keys!$K$2),0,1)),IF(INDEX(Keys!$E:$E,MATCH($A21,Keys!$D:$D,0))="Y",1,0)),1)) -> 1 | F21: =IF(INDEX(Keys!$F:$F,MATCH($A21,Keys!$D:$D,0))="Y",0,IF($B28=1,IF($B29=1,IF(INDEX(Keys!$H:$H,MATCH($A21,Keys!$D:$D,0))="Y",0,IF(AND(INDEX(Keys!$G:$G,MATCH($A21,Keys!$D:$D,0))="Y",F$1<Keys!$K$2),0,1)),IF(INDEX(Keys!$E:$E,MATCH($A21,Keys!$D:$D,0))="Y",1,0)),1)) -> 1 | G21: =IF(INDEX(Keys!$F:$F,MATCH($A21,Keys!$D:$D,0))="Y",0,IF($B28=1,IF($B29=1,IF(INDEX(Keys!$H:$H,MATCH($A21,Keys!$D:$D,0))="Y",0,IF(AND(INDEX(Keys!$G:$G,MATCH($A21,Keys!$D:$D,0))="Y",G$1<Keys!$K$2),0,1)),IF(INDEX(Keys!$E:$E,MATCH($A21,Keys!$D:$D,0))="Y",1,0)),1)) -> 1 | H21: =IF(INDEX(Keys!$F:$F,MATCH($A21,Keys!$D:$D,0))="Y",0,IF($B28=1,IF($B29=1,IF(INDEX(Keys!$H:$H,MATCH($A21,Keys!$D:$D,0))="Y",0,IF(AND(INDEX(Keys!$G:$G,MATCH($A21,Keys!$D:$D,0))="Y",H$1<Keys!$K$2),0,1)),IF(INDEX(Keys!$E:$E,MATCH($A21,Keys!$D:$D,0))="Y",1,0)),1)) -> 1 | I21: =IF(INDEX(Keys!$F:$F,MATCH($A21,Keys!$D:$D,0))="Y",0,IF($B28=1,IF($B29=1,IF(INDEX(Keys!$H:$H,MATCH($A21,Keys!$D:$D,0))="Y",0,IF(AND(INDEX(Keys!$G:$G,MATCH($A21,Keys!$D:$D,0))="Y",I$1<Keys!$K$2),0,1)),IF(INDEX(Keys!$E:$E,MATCH($A21,Keys!$D:$D,0))="Y",1,0)),1)) -> 1 | ... AE21: =IF(INDEX(Keys!$F:$F,MATCH($A21,Keys!$D:$D,0))="Y",0,IF($B28=1,IF($B29=1,IF(INDEX(Keys!$H:$H,MATCH($A21,Keys!$D:$D,0))="Y",0,IF(AND(INDEX(Keys!$G:$G,MATCH($A21,Keys!$D:$D,0))="Y",AE$1<Keys!$K$2),0,1)),IF(INDEX(Keys!$E:$E,MATCH($A21,Keys!$D:$D,0))="Y",1,0)),1)) -> 1
A22: =Keys!$D22 -> nonroad vehicles 30 | B22: =IF(INDEX(Keys!$F:$F,MATCH($A22,Keys!$D:$D,0))="Y",0,IF($B28=1,IF($B29=1,IF(INDEX(Keys!$H:$H,MATCH($A22,Keys!$D:$D,0))="Y",0,IF(AND(INDEX(Keys!$G:$G,MATCH($A22,Keys!$D:$D,0))="Y",B$1<Keys!$K$2),0,1)),IF(INDEX(Keys!$E:$E,MATCH($A22,Keys!$D:$D,0))="Y",1,0)),1)) -> 1 | C22: =IF(INDEX(Keys!$F:$F,MATCH($A22,Keys!$D:$D,0))="Y",0,IF($B28=1,IF($B29=1,IF(INDEX(Keys!$H:$H,MATCH($A22,Keys!$D:$D,0))="Y",0,IF(AND(INDEX(Keys!$G:$G,MATCH($A22,Keys!$D:$D,0))="Y",C$1<Keys!$K$2),0,1)),IF(INDEX(Keys!$E:$E,MATCH($A22,Keys!$D:$D,0))="Y",1,0)),1)) -> 1 | D22: =IF(INDEX(Keys!$F:$F,MATCH($A22,Keys!$D:$D,0))="Y",0,IF($B28=1,IF($B29=1,IF(INDEX(Keys!$H:$H,MATCH($A22,Keys!$D:$D,0))="Y",0,IF(AND(INDEX(Keys!$G:$G,MATCH($A22,Keys!$D:$D,0))="Y",D$1<Keys!$K$2),0,1)),IF(INDEX(Keys!$E:$E,MATCH($A22,Keys!$D:$D,0))="Y",1,0)),1)) -> 1 | E22: =IF(INDEX(Keys!$F:$F,MATCH($A22,Keys!$D:$D,0))="Y",0,IF($B28=1,IF($B29=1,IF(INDEX(Keys!$H:$H,MATCH($A22,Keys!$D:$D,0))="Y",0,IF(AND(INDEX(Keys!$G:$G,MATCH($A22,Keys!$D:$D,0))="Y",E$1<Keys!$K$2),0,1)),IF(INDEX(Keys!$E:$E,MATCH($A22,Keys!$D:$D,0))="Y",1,0)),1)) -> 1 | F22: =IF(INDEX(Keys!$F:$F,MATCH($A22,Keys!$D:$D,0))="Y",0,IF($B28=1,IF($B29=1,IF(INDEX(Keys!$H:$H,MATCH($A22,Keys!$D:$D,0))="Y",0,IF(AND(INDEX(Keys!$G:$G,MATCH($A22,Keys!$D:$D,0))="Y",F$1<Keys!$K$2),0,1)),IF(INDEX(Keys!$E:$E,MATCH($A22,Keys!$D:$D,0))="Y",1,0)),1)) -> 1 | G22: =IF(INDEX(Keys!$F:$F,MATCH($A22,Keys!$D:$D,0))="Y",0,IF($B28=1,IF($B29=1,IF(INDEX(Keys!$H:$H,MATCH($A22,Keys!$D:$D,0))="Y",0,IF(AND(INDEX(Keys!$G:$G,MATCH($A22,Keys!$D:$D,0))="Y",G$1<Keys!$K$2),0,1)),IF(INDEX(Keys!$E:$E,MATCH($A22,Keys!$D:$D,0))="Y",1,0)),1)) -> 1 | H22: =IF(INDEX(Keys!$F:$F,MATCH($A22,Keys!$D:$D,0))="Y",0,IF($B28=1,IF($B29=1,IF(INDEX(Keys!$H:$H,MATCH($A22,Keys!$D:$D,0))="Y",0,IF(AND(INDEX(Keys!$G:$G,MATCH($A22,Keys!$D:$D,0))="Y",H$1<Keys!$K$2),0,1)),IF(INDEX(Keys!$E:$E,MATCH($A22,Keys!$D:$D,0))="Y",1,0)),1)) -> 1 | I22: =IF(INDEX(Keys!$F:$F,MATCH($A22,Keys!$D:$D,0))="Y",0,IF($B28=1,IF($B29=1,IF(INDEX(Keys!$H:$H,MATCH($A22,Keys!$D:$D,0))="Y",0,IF(AND(INDEX(Keys!$G:$G,MATCH($A22,Keys!$D:$D,0))="Y",I$1<Keys!$K$2),0,1)),IF(INDEX(Keys!$E:$E,MATCH($A22,Keys!$D:$D,0))="Y",1,0)),1)) -> 1 | ... AE22: =IF(INDEX(Keys!$F:$F,MATCH($A22,Keys!$D:$D,0))="Y",0,IF($B28=1,IF($B29=1,IF(INDEX(Keys!$H:$H,MATCH($A22,Keys!$D:$D,0))="Y",0,IF(AND(INDEX(Keys!$G:$G,MATCH($A22,Keys!$D:$D,0))="Y",AE$1<Keys!$K$2),0,1)),IF(INDEX(Keys!$E:$E,MATCH($A22,Keys!$D:$D,0))="Y",1,0)),1)) -> 1
A23: =Keys!$D23 -> other manufacturing 31T33 | B23: =IF(INDEX(Keys!$F:$F,MATCH($A23,Keys!$D:$D,0))="Y",0,IF($B28=1,IF($B29=1,IF(INDEX(Keys!$H:$H,MATCH($A23,Keys!$D:$D,0))="Y",0,IF(AND(INDEX(Keys!$G:$G,MATCH($A23,Keys!$D:$D,0))="Y",B$1<Keys!$K$2),0,1)),IF(INDEX(Keys!$E:$E,MATCH($A23,Keys!$D:$D,0))="Y",1,0)),1)) -> 1 | C23: =IF(INDEX(Keys!$F:$F,MATCH($A23,Keys!$D:$D,0))="Y",0,IF($B28=1,IF($B29=1,IF(INDEX(Keys!$H:$H,MATCH($A23,Keys!$D:$D,0))="Y",0,IF(AND(INDEX(Keys!$G:$G,MATCH($A23,Keys!$D:$D,0))="Y",C$1<Keys!$K$2),0,1)),IF(INDEX(Keys!$E:$E,MATCH($A23,Keys!$D:$D,0))="Y",1,0)),1)) -> 1 | D23: =IF(INDEX(Keys!$F:$F,MATCH($A23,Keys!$D:$D,0))="Y",0,IF($B28=1,IF($B29=1,IF(INDEX(Keys!$H:$H,MATCH($A23,Keys!$D:$D,0))="Y",0,IF(AND(INDEX(Keys!$G:$G,MATCH($A23,Keys!$D:$D,0))="Y",D$1<Keys!$K$2),0,1)),IF(INDEX(Keys!$E:$E,MATCH($A23,Keys!$D:$D,0))="Y",1,0)),1)) -> 1 | E23: =IF(INDEX(Keys!$F:$F,MATCH($A23,Keys!$D:$D,0))="Y",0,IF($B28=1,IF($B29=1,IF(INDEX(Keys!$H:$H,MATCH($A23,Keys!$D:$D,0))="Y",0,IF(AND(INDEX(Keys!$G:$G,MATCH($A23,Keys!$D:$D,0))="Y",E$1<Keys!$K$2),0,1)),IF(INDEX(Keys!$E:$E,MATCH($A23,Keys!$D:$D,0))="Y",1,0)),1)) -> 1 | F23: =IF(INDEX(Keys!$F:$F,MATCH($A23,Keys!$D:$D,0))="Y",0,IF($B28=1,IF($B29=1,IF(INDEX(Keys!$H:$H,MATCH($A23,Keys!$D:$D,0))="Y",0,IF(AND(INDEX(Keys!$G:$G,MATCH($A23,Keys!$D:$D,0))="Y",F$1<Keys!$K$2),0,1)),IF(INDEX(Keys!$E:$E,MATCH($A23,Keys!$D:$D,0))="Y",1,0)),1)) -> 1 | G23: =IF(INDEX(Keys!$F:$F,MATCH($A23,Keys!$D:$D,0))="Y",0,IF($B28=1,IF($B29=1,IF(INDEX(Keys!$H:$H,MATCH($A23,Keys!$D:$D,0))="Y",0,IF(AND(INDEX(Keys!$G:$G,MATCH($A23,Keys!$D:$D,0))="Y",G$1<Keys!$K$2),0,1)),IF(INDEX(Keys!$E:$E,MATCH($A23,Keys!$D:$D,0))="Y",1,0)),1)) -> 1 | H23: =IF(INDEX(Keys!$F:$F,MATCH($A23,Keys!$D:$D,0))="Y",0,IF($B28=1,IF($B29=1,IF(INDEX(Keys!$H:$H,MATCH($A23,Keys!$D:$D,0))="Y",0,IF(AND(INDEX(Keys!$G:$G,MATCH($A23,Keys!$D:$D,0))="Y",H$1<Keys!$K$2),0,1)),IF(INDEX(Keys!$E:$E,MATCH($A23,Keys!$D:$D,0))="Y",1,0)),1)) -> 1 | I23: =IF(INDEX(Keys!$F:$F,MATCH($A23,Keys!$D:$D,0))="Y",0,IF($B28=1,IF($B29=1,IF(INDEX(Keys!$H:$H,MATCH($A23,Keys!$D:$D,0))="Y",0,IF(AND(INDEX(Keys!$G:$G,MATCH($A23,Keys!$D:$D,0))="Y",I$1<Keys!$K$2),0,1)),IF(INDEX(Keys!$E:$E,MATCH($A23,Keys!$D:$D,0))="Y",1,0)),1)) -> 1 | ... AE23: =IF(INDEX(Keys!$F:$F,MATCH($A23,Keys!$D:$D,0))="Y",0,IF($B28=1,IF($B29=1,IF(INDEX(Keys!$H:$H,MATCH($A23,Keys!$D:$D,0))="Y",0,IF(AND(INDEX(Keys!$G:$G,MATCH($A23,Keys!$D:$D,0))="Y",AE$1<Keys!$K$2),0,1)),IF(INDEX(Keys!$E:$E,MATCH($A23,Keys!$D:$D,0))="Y",1,0)),1)) -> 1
